Workbook
Name DepartmentNum: '.c12_inputs.hr'!$E$4

Sheet registry
A2: Year | E2: 45657 | F2: 46022 | G2: 46112 | H2: 46203 | I2: 46022 | J2: 46112 | K2: 46203 | L2: 46295 | M2: 46387 | N2: 46477 | O2: 46568 | P2: 46660 | Q2: 46752
E3: actual | I3: i/o
R4: src_page
A6: [not sourced from c12]
A7: [not sourced from c12]
A8: [not sourced from c12]
A11: [not sourced from c12]
A12: [not sourced from c12]
A13: [not sourced from c12]
A14: [not sourced from c12]
A15: [not sourced from c12]
A16: [not sourced from c12]
A17: [not sourced from c12]
A18: [not sourced from c12]
A19: [not sourced from c12]
... A44: [not sourced from c12]
A47: Total LGH HM Fees | E47: =+'c12_hm'!E60 -> 0 | F47: =+'c12_hm'!F60 -> 447597 | G47: =+'c12_hm'!G60 -> 310715.79 | H47: =+'c12_hm'!H60 -> 0 | I47: =+'c12_hm'!I60 -> 447597 | J47: =+'c12_hm'!J60 -> 310715.79 | K47: =+'c12_hm'!K60 -> 902637.29 | L47: =+'c12_hm'!L60 -> 948110.97 | ... Q47: =+'c12_hm'!Q60 -> 1223469.7 | R47: c12_hm
A48: c12 Participation | E48: =+'c12_hm'!E70 -> 0 | F48: =+'c12_hm'!F70 -> 447597 | G48: =+'c12_hm'!G70 -> 63035.789 | H48: =+'c12_hm'!H70 -> 0 | I48: =+'c12_hm'!I70 -> 447597 | J48: =+'c12_hm'!J70 -> 63035.789 | K48: =+'c12_hm'!K70 -> 398173.65 | L48: =+'c12_hm'!L70 -> 400447.34 | ... Q48: =+'c12_hm'!Q70 -> 255971.76 | R48: c12_hm
A50: [not sourced from c12]
A51: [not sourced from c12]
A52: [not sourced from c12]
A56: Total LGH D&s Fees | E56: ='c12_d&s'!E60 -> 0 | F56: ='c12_d&s'!F60 -> 911235.5 | G56: ='c12_d&s'!G60 -> 1735259.1 | H56: ='c12_d&s'!H60 -> 0 | I56: ='c12_d&s'!I60 -> 911235.5 | J56: ='c12_d&s'!J60 -> 1829009.1 | K56: ='c12_d&s'!K60 -> 2567569.8 | L56: ='c12_d&s'!L60 -> 2299388.8 | ... Q56: ='c12_d&s'!Q60 -> 4550380.3 | R56: c12_d&s
A57: c12 D&s Participation | E57: ='c12_d&s'!E70 -> 0 | F57: ='c12_d&s'!F70 -> 455617.75 | G57: ='c12_d&s'!G70 -> 806580.95 | H57: ='c12_d&s'!H70 -> 0 | I57: ='c12_d&s'!I70 -> 455617.75 | J57: ='c12_d&s'!J70 -> 839393.45 | K57: ='c12_d&s'!K70 -> 1048217.6 | L57: ='c12_d&s'!L70 -> 968127.09 | ... Q57: ='c12_d&s'!Q70 -> 1555733.1 | R57: c12_d&s
A59: total c12 participation | E59: ='c12_oc'!E10 -> 2452451 | F59: ='c12_oc'!F10 -> 903214.75 | G59: ='c12_oc'!G10 -> 886331.48 | H59: ='c12_oc'!H10 -> 0 | I59: ='c12_oc'!I10 -> 903214.75 | J59: ='c12_oc'!J10 -> 919143.98 | K59: ='c12_oc'!K10 -> 1463106 | L59: ='c12_oc'!L10 -> 1390973.4 | ... Q59: ='c12_oc'!Q10 -> 1838752 | R59: c12_oc
A60: total lgh revenue | E60: ='c12_oc'!E87 -> 0 | F60: ='c12_oc'!F87 -> 1358832.5 | G60: ='c12_oc'!G87 -> 2200269.7 | H60: ='c12_oc'!H87 -> 0 | I60: ='c12_oc'!I87 -> 1358832.5 | J60: ='c12_oc'!J87 -> 2294019.7 | K60: ='c12_oc'!K87 -> 3624501.8 | L60: ='c12_oc'!L87 -> 3515478.7 | ... Q60: ='c12_oc'!Q87 -> 6134792.1 | R60: c12_oc
A61: art leases | E61: ='c12_sk'!E7 -> 0 | F61: ='c12_sk'!F7 -> 0 | G61: ='c12_sk'!G7 -> 0 | H61: ='c12_sk'!H7 -> 0 | I61: ='c12_sk'!I7 -> 0 | J61: ='c12_sk'!J7 -> 50000 | K61: ='c12_sk'!K7 -> 50000 | L61: ='c12_sk'!L7 -> 50000 | ... Q61: ='c12_sk'!Q7 -> 50000 | R61: c12_sk
A63: [not sourced from c12]
A64: [not sourced from c12]
A67: [not sourced from c12]
A68: [not sourced from c12]
A69: [not sourced from c12]
A72: [not sourced from c12]
A73: [not sourced from c12]
A74: [not sourced from c12]
A78: [not sourced from c12]
A79: [not sourced from c12]
A80: [not sourced from c12]
A83: [not sourced from c12]
A84: guarantee payments | E84: ='c12_sk'!E8 -> 0 | F84: ='c12_sk'!F8 -> -250000 | G84: ='c12_sk'!G8 -> -250000 | H84: ='c12_sk'!H8 -> 0 | I84: ='c12_sk'!I8 -> -250000 | J84: ='c12_sk'!J8 -> -250000 | K84: ='c12_sk'!K8 -> -250000 | L84: ='c12_sk'!L8 -> -250000 | ... Q84: ='c12_sk'!Q8 -> -250000 | R84: c12_sk
A87: [not sourced from c12]
...

Sheet c12_inputs
A2: Year
A3: Period
B4: i/o | C4: field_name | D4: index
A5: cost inflation | B5: i | C5: cost_inflation_rate_actual | E5: 0.03
A7: Charge Back Percentage | B7: i | C7: chargeback_pct_actual | E7: 0.05
A8: participation% | B8: i | C8: participation_pct_actual | E8: 0.35
A11: actual thru | B11: i | C11: actuals_thru | E11: 46112
A12: projections from | B12: i | C12: projections_from | E12: 46203
A13: projections to | B13: i | C13: projections_to | E13: 46752

Sheet c12_oc
A2: Year | E2: 45657 | F2: 46022 | G2: 46112 | H2: 46203 | I2: 46022 | J2: 46112 | K2: 46203 | L2: 46295 | M2: 46387 | N2: 46477 | O2: 46568 | P2: 46660 | Q2: 46752
E3: actual | I3: i/o
B4: i/o | C4: field_name | D4: index
A5: C12 Participation Revenue (not c/b reimb)
A6: HM Fees | F6: 447597 | G6: 63035.789 | I6: 447597 | J6: ='c12_hm'!J70 -> 63035.789 | K6: ='c12_hm'!K70 -> 398173.65 | L6: ='c12_hm'!L70 -> 400447.34 | M6: ='c12_hm'!M70 -> 662529.63 | N6: ='c12_hm'!N70 -> 255971.76 | O6: ='c12_hm'!O70 -> 255971.76 | P6: ='c12_hm'!P70 -> 255971.76 | Q6: ='c12_hm'!Q70 -> 255971.76
A7: BI&F Fees | F7: 0 | G7: 16714.737 | I7: 0 | J7: ='c12_bi&F'!J70 -> 16714.737 | K7: ='c12_bi&F'!K70 -> 16714.737 | L7: ='c12_bi&F'!L70 -> 22398.947 | M7: ='c12_bi&F'!M70 -> 27047.105 | N7: ='c12_bi&F'!N70 -> 27047.105 | O7: ='c12_bi&F'!O70 -> 27047.105 | P7: ='c12_bi&F'!P70 -> 27047.105 | Q7: ='c12_bi&F'!Q70 -> 27047.105
A8: DS Fees | F8: 455617.75 | G8: 806580.95 | I8: 455617.75 | J8: ='c12_d&s'!J70 -> 839393.45 | K8: ='c12_d&s'!K70 -> 1048217.6 | L8: ='c12_d&s'!L70 -> 968127.09 | M8: ='c12_d&s'!M70 -> 2241733.1 | N8: ='c12_d&s'!N70 -> 1555733.1 | O8: ='c12_d&s'!O70 -> 1555733.1 | P8: ='c12_d&s'!P70 -> 1555733.1 | Q8: ='c12_d&s'!Q70 -> 1555733.1
A10: total participation revenue | B10: o | C10: total_participation_revenue_actual | E10: 2452451 | F10: 903214.75 | G10: 886331.48 | I10: 903214.75 | J10: =SUM(J6:J9) -> 919143.98 | K10: =SUM(K6:K9) -> 1463106 | L10: =SUM(L6:L9) -> 1390973.4 | M10: =SUM(M6:M9) -> 2931309.9 | N10: =SUM(N6:N9) -> 1838752 | O10: =SUM(O6:O9) -> 1838752 | P10: =SUM(P6:P9) -> 1838752 | Q10: =SUM(Q6:Q9) -> 1838752
A12: Infrastructure | B12: i | C12: nonrecur_exp | D12: infrastructure
A13: Professional services | B13: i | C13: nonrecur_exp | D13: professional_services | K13: 100000 | L13: 100000
A14: Hiring Costs | B14: i | C14: nonrecur_exp | D14: hiring_costs | K14: 100000
A15: signing bonuses | B15: i | C15: nonrecur_exp | D15: signing_bonus
A16: Restructuring | B16: i | C16: nonrecur_exp | D16: restructuring | G16: 0 | J16: 0 | K16: 0 | L16: 0 | M16: 0 | N16: 0 | O16: 0 | P16: 0 | Q16: 0
A17: housing | B17: i | C17: nonrecur_exp | D17: housing | G17: 0 | J17: 0 | K17: 0 | L17: 0 | M17: 0 | N17: 0 | O17: 0 | P17: 0 | Q17: 0
A18: Total | B18: c | C18: total_nonrecur_exp | F18: 0 | G18: 0 | I18: 0 | J18: =SUM(J12:J17) -> 0 | K18: =SUM(K12:K17) -> 200000 | L18: =SUM(L12:L17) -> 100000 | M18: =SUM(M12:M17) -> 0 | N18: =SUM(N12:N17) -> 0 | O18: =SUM(O12:O17) -> 0 | P18: =SUM(P12:P17) -> 0 | Q18: =SUM(Q12:Q17) -> 0
A20: Reimbursable Operating Expenses (inc holtel) | F20: 2917273 | G20: 4057849.9 | I20: 2917273 | J20: =-J39 -> 4057849.9 | K20: =-K39 -> 4457407 | L20: =-L39 -> 2834607 | M20: =-M39 -> 4930793.2 | N20: =-N39 -> 4930793.2 | O20: =-O39 -> 4930793.2 | P20: =-P39 -> 4930793.2 | Q20: =-Q39 -> 4930793.2
A22: revenue from lgh | F22: 3820487.8 | G22: 4944181.3 | I22: 3820487.8 | J22: =J20+J10 -> 4976993.8 | K22: =K20+K10 -> 5920513 | L22: =L20+L10 -> 4225580.4 | M22: =M20+M10 -> 7862103.1 | N22: =N20+N10 -> 6769545.2 | O22: =O20+O10 -> 6769545.2 | P22: =P20+P10 -> 6769545.2 | Q22: =Q20+Q10 -> 6769545.2
A24: compensation
A25: Hotel Management | F25: -770825 | G25: -391680 | I25: -770825 | J25: =-('c12_hm'!J78+'c12_hm'!J79) -> -391680 | K25: =-('c12_hm'!K78+'c12_hm'!K79) -> -391680 | L25: =-('c12_hm'!L78+'c12_hm'!L79) -> -434880 | M25: =-('c12_hm'!M78+'c12_hm'!M79) -> -949185 | N25: =-('c12_hm'!N78+'c12_hm'!N79) -> -949185 | O25: =-('c12_hm'!O78+'c12_hm'!O79) -> -949185 | P25: =-('c12_hm'!P78+'c12_hm'!P79) -> -949185 | Q25: =-('c12_hm'!Q78+'c12_hm'!Q79) -> -949185
A26: Business Infrastructure & Finance | F26: -602497.5 | G26: -296640 | I26: -602497.5 | J26: =-('c12_bi&F'!J78+'c12_bi&F'!J79) -> -296640 | K26: =-('c12_bi&F'!K78+'c12_bi&F'!K79) -> -477677.14 | L26: =-('c12_bi&F'!L78+'c12_bi&F'!L79) -> -672077.14 | M26: =-('c12_bi&F'!M78+'c12_bi&F'!M79) -> -1173394.6 | N26: =-('c12_bi&F'!N78+'c12_bi&F'!N79) -> -1173394.6 | O26: =-('c12_bi&F'!O78+'c12_bi&F'!O79) -> -1173394.6 | P26: =-('c12_bi&F'!P78+'c12_bi&F'!P79) -> -1173394.6 | Q26: =-('c12_bi&F'!Q78+'c12_bi&F'!Q79) -> -1173394.6
A27: Development & Structuring | F27: -1652177.5 | G27: -560160 | I27: -1652177.5 | J27: =-('c12_d&s'!J78+'c12_d&s'!J79) -> -560160 | K27: =-('c12_d&s'!K78+'c12_d&s'!K79) -> -520560 | L27: =-('c12_d&s'!L78+'c12_d&s'!L79) -> -560160 | M27: =-('c12_d&s'!M78+'c12_d&s'!M79) -> -1221223.8 | N27: =-('c12_d&s'!N78+'c12_d&s'!N79) -> -1221223.8 | O27: =-('c12_d&s'!O78+'c12_d&s'!O79) -> -1221223.8 | P27: =-('c12_d&s'!P78+'c12_d&s'!P79) -> -1221223.8 | Q27: =-('c12_d&s'!Q78+'c12_d&s'!Q79) -> -1221223.8
A28: C12 headoffice | F28: -472542.86 | G28: -805022.86 | I28: -472542.86 | J28: =-(J78-J81) -> -805022.86 | K28: =-(K78-K81) -> -383142.86 | L28: =-(L78-L81) -> -383142.86 | M28: =-(M78-M81) -> -902642.86 | N28: =-(N78-N81) -> -902642.86 | O28: =-(O78-O81) -> -902642.86 | P28: =-(P78-P81) -> -902642.86 | Q28: =-(Q78-Q81) -> -902642.86
A29: Head office expenses
A30: office costs (rent & reoccuring) | B30: i | C30: ho_exp | D30: office_costs | F30: -47485 | G30: -135000 | I30: -47485 | J30: =-540000/4 -> -135000 | K30: =-540000/4 -> -135000 | L30: =-540000/4 -> -135000 | M30: =-540000/4 -> -135000 | N30: -135000 | O30: -135000 | P30: -135000 | Q30: -135000
A31: Departmental OOP paid via sk | F31: -249431 | G31: -174347 | I31: -249431 | J31: ='c12_sk'!J6 -> -174347 | K31: ='c12_sk'!K6 -> -174347 | L31: ='c12_sk'!L6 -> -174347 | M31: ='c12_sk'!M6 -> -174347 | N31: ='c12_sk'!N6 -> -174347 | O31: ='c12_sk'!O6 -> -174347 | P31: ='c12_sk'!P6 -> -174347 | Q31: ='c12_sk'!Q6 -> -174347
A32: Departmental OOP not paid via sk | B32: i | C32: ho_exp | D32: oop_notsk | G32: -75000 | J32: -75000 | K32: -75000 | L32: -75000 | M32: -75000 | N32: -75000 | O32: -75000 | P32: -75000 | Q32: -75000
A33: Non-recurring Items paid by LGH | B33: i | C33: ho_exp | D33: nonrecur_lgh | F33: 0 | G33: 0 | I33: 0 | J33: =-J18 -> 0 | K33: =-K18 -> -200000 | L33: =-L18 -> -100000 | M33: =-M18 -> 0 | N33: 0 | O33: 0 | P33: 0 | Q33: 0
A34: C12 Accounts Payable | B34: i | C34: ho_exp | D34: accounts_payable | F34: -599728 | G34: -1620000 | I34: -599728 | J34: -1620000 | K34: -2100000 | L34: -300000 | M34: -300000 | N34: -300000 | O34: -300000 | P34: -300000 | Q34: -300000
A35: inflation multiplier | B35: i | C35: inflation_multiplier | F35: 1 | G35: 1 | I35: 1 | J35: 1 | K35: 1 | L35: 1 | M35: 1 | N35: 1 | O35: 1 | P35: 1 | Q35: 1
A36: Inflation | B36: c | C36: inflation | F36: 0 | G36: 0 | I36: 0 | J36: =(J35-1)*SUM(J25:J34) -> 0 | K36: =(K35-1)*SUM(K25:K34) -> 0 | L36: =(L35-1)*SUM(L25:L34) -> 0 | M36: =(M35-1)*SUM(M25:M34) -> 0 | N36: =(N35-1)*SUM(N25:N34) -> 0 | O36: =(O35-1)*SUM(O25:O34) -> 0 | P36: =(P35-1)*SUM(P25:P34) -> 0 | Q36: =(Q35-1)*SUM(Q25:Q34) -> 0
A37: Compensation - total | B37: o | C37: compensation_total | E37: -3970569 | F37: -1645629 | G37: -2053502.9 | I37: -1645629 | J37: =IF(AND((G37<>""),(J$2<46204)),(G37),SUM(J25:J28)) -> -2053502.9 | K37: =IF(AND((H37<>""),(K$2<46204)),(H37),SUM(K25:K28)) -> -1773060 | L37: =IF(AND((I37<>""),(L$2<46204)),(I37),SUM(L25:L28)) -> -2050260 | M37: =IF(AND((J37<>""),(M$2<46204)),(J37),SUM(M25:M28)) -> -4246446.2 | N37: =IF(AND((K37<>""),(N$2<46204)),(K37),SUM(N25:N28)) -> -4246446.2 | O37: =IF(AND((L37<>""),(O$2<46204)),(L37),SUM(O25:O28)) -> -4246446.2 | P37: =IF(AND((M37<>""),(P$2<46204)),(M37),SUM(P25:P28)) -> -4246446.2 | Q37: =IF(AND((N37<>""),(Q$2<46204)),(N37),SUM(Q25:Q28)) -> -4246446.2
A38: Direct compensation not via trinet | B38: i | C38: compensation_direct | F38: -375000 | G38: 0 | I38: -375000 | J38: =IF(AND((G38<>""),(J$2<46204)),(G38),0) -> 0 | K38: =IF(AND((H38<>""),(K$2<46204)),(H38),0) -> 0 | L38: =IF(AND((I38<>""),(L$2<46204)),(I38),0) -> 0 | M38: =IF(AND((J38<>""),(M$2<46204)),(J38),0) -> 0 | N38: 0 | O38: 0 | P38: 0 | Q38: 0
A39: Total c12 Expenses paid by LGH | B39: o | C39: total_c12_exp_lgh_actual | E39: -5450569 | F39: -2917273 | G39: -4057849.9 | I39: -2917273 | J39: =SUM(J30:J34,J36,J37:J38) -> -4057849.9 | K39: =SUM(K30:K34,K36,K37:K38) -> -4457407 | L39: =SUM(L30:L34,L36,L37:L38) -> -2834607 | M39: =SUM(M30:M34,M36,M37:M38) -> -4930793.2 | N39: =SUM(N30:N34,N36,N37:N38) -> -4930793.2 | O39: =SUM(O30:O34,O36,O37:O38) -> -4930793.2 | P39: =SUM(P30:P34,P36,P37:P38) -> -4930793.2 | Q39: =SUM(Q30:Q34,Q36,Q37:Q38) -> -4930793.2
A41: C12 H/O compensation not paid by lgh | F41: -42318.571 | G41: -58237.714 | I41: -42318.571 | J41: =-J81 -> -58237.714 | K41: =-K81 -> -58237.714 | L41: =-L81 -> -58237.714 | M41: =-M81 -> -79017.714 | N41: =-N81 -> -79017.714 | O41: =-O81 -> -79017.714 | P41: =-P81 -> -79017.714 | Q41: =-Q81 -> -79017.714
A42: Roots donation by c12 | B42: i | C42: roots_donation | M42: -200000 | N42: -200000 | O42: -200000 | P42: -200000 | Q42: -200000
A43: Total c12 Expenses Not paid by lgh | B43: c | C43: total_c12_exp_not_lgh | F43: -42318.571 | G43: -58237.714 | I43: -42318.571 | J43: =SUM(J41:J42) -> -58237.714 | K43: =SUM(K41:K42) -> -58237.714 | L43: =SUM(L41:L42) -> -58237.714 | M43: =SUM(M41:M42) -> -279017.71 | N43: =SUM(N41:N42) -> -279017.71 | O43: =SUM(O41:O42) -> -279017.71 | P43: =SUM(P41:P42) -> -279017.71 | Q43: =SUM(Q41:Q42) -> -279017.71
A45: total costs | B45: c | C45: total_c12_costs | F45: -2959591.6 | G45: -4116087.6 | I45: -2959591.6 | J45: =J43+J39 -> -4116087.6 | K45: =K43+K39 -> -4515644.7 | L45: =L43+L39 -> -2892844.7 | M45: =M43+M39 -> -5209811 | N45: =N43+N39 -> -5209811 | O45: =O43+O39 -> -5209811 | P45: =P43+P39 -> -5209811 | Q45: =Q43+Q39 -> -5209811
A47: Total C12 Profit | B47: o | C47: total_c12_profit_actual | E47: 3119951 | F47: 860896.18 | G47: 828093.76 | I47: 860896.18 | J47: =J22+J45 -> 860906.26 | K47: =K22+K45 -> 1404868.3 | L47: =L22+L45 -> 1332735.7 | M47: =M22+M45 -> 2652292.1 | N47: =N22+N45 -> 1559734.3 | O47: =O22+O45 -> 1559734.3 | P47: =P22+P45 -> 1559734.3 | Q47: =Q22+Q45 -> 1559734.3
A48: c12 profit margin | B48: c | C48: c12_profit_margin | F48: 0.22533672 | G48: 0.16748855 | I48: 0.22533672 | J48: =J47/J22 -> 0.17297716 | K48: =K47/K22 -> 0.23728827 | L48: =L47/L22 -> 0.31539707 | M48: =M47/M22 -> 0.33735148 | N48: =N47/N22 -> 0.23040459 | O48: =O47/O22 -> 0.23040459 | P48: =P47/P22 -> 0.23040459 | Q48: =Q47/Q22 -> 0.23040459
A51: Bank transfers (actual or danielle)
...

Sheet c12_sk
A2: Year | E2: 45657 | F2: 46022 | G2: 46112 | H2: 46203 | I2: 46022 | J2: 46112 | K2: 46203 | L2: 46295 | M2: 46387 | N2: 46477 | O2: 46568 | P2: 46660 | Q2: 46752
E3: actual | I3: i/o
B4: i/o | C4: field_name | D4: index
A5: Bank transfers | B5: i | C5: bank_transfers | D5: sk | F5: -1925382 | G5: -1925382 | I5: -1925382 | J5: -1375000 | K5: -1375000 | L5: -1375000 | M5: -1375000 | N5: -1375000 | O5: -1375000 | P5: -1375000 | Q5: -1375000
A6: Departmental OOP paid via sk | B6: i | C6: ho_exp | D6: oop_sk | F6: -112553 | G6: -186705 | I6: -249431 | J6: -174347 | K6: -174347 | L6: -174347 | M6: -174347 | N6: -174347 | O6: -174347 | P6: -174347 | Q6: -174347
A7: art lease payments to sk | B7: i | C7: lease_payments | D7: sk | E7: 0 | F7: 0 | G7: 0 | I7: 0 | J7: 50000 | K7: 50000 | L7: 50000 | M7: 50000 | N7: 50000 | O7: 50000 | P7: 50000 | Q7: 50000
A8: guarantee fees to sk | B8: i | C8: guarantee_fees | D8: sk | E8: 0 | F8: -250000 | G8: -250000 | I8: -250000 | J8: -250000 | K8: -250000 | L8: -250000 | M8: -250000 | N8: -250000 | O8: -250000 | P8: -250000 | Q8: -250000
A9: cuda buy back | B9: i | C9: cuda_buyback | D9: sk | G9: -1200000
A10: c12 to sk (jp dist) | B10: i | C10: jp_payment | D10: sk

Sheet c12_bs
A2: Year | E2: 45657 | F2: 46022 | G2: 46112 | H2: 46203 | I2: 46022 | J2: 46112 | K2: 46203 | L2: 46295 | M2: 46387 | N2: 46477 | O2: 46568 | P2: 46660 | Q2: 46752
E3: actual | I3: i/o
B4: i/o | C4: field_name | D4: index
A5: assets
A6: cash open | I6: 9950 | J6: =I11 -> 9950 | K6: =J11 -> 9950 | L6: =K11 -> 9950 | M6: =L11 -> 9950 | N6: =M11 -> 9950 | O6: =N11 -> 9950 | P6: =O11 -> 9950 | Q6: =P11 -> 9950
A7: c12 profit | I7: ='c12_oc'!I47 -> 860896.18 | J7: ='c12_oc'!J47 -> 860906.26 | K7: ='c12_oc'!K47 -> 1404868.3 | L7: ='c12_oc'!L47 -> 1332735.7 | M7: ='c12_oc'!M47 -> 2652292.1 | N7: ='c12_oc'!N47 -> 1559734.3 | O7: ='c12_oc'!O47 -> 1559734.3 | P7: ='c12_oc'!P47 -> 1559734.3 | Q7: ='c12_oc'!Q47 -> 1559734.3
A8: borrow from c12 loc | I8: =-'c12_oc'!I60 -> 190054.82 | J8: =-'c12_oc'!J60 -> -335253.26 | K8: =-'c12_oc'!K60 -> -879215.26 | L8: =-'c12_oc'!L60 -> -807082.66 | M8: =-'c12_oc'!M60 -> -2126639.1 | N8: =-'c12_oc'!N60 -> -1034081.3 | O8: =-'c12_oc'!O60 -> -1034081.3 | P8: =-'c12_oc'!P60 -> -1034081.3 | Q8: =-'c12_oc'!Q60 -> -1034081.3
A9: LGH to sk (from danielle) | I9: ='c12_oc'!I59 -> -1050951 | J9: ='c12_oc'!J59 -> -525653 | K9: ='c12_oc'!K59 -> -525653 | L9: ='c12_oc'!L59 -> -525653 | M9: ='c12_oc'!M59 -> -525653 | N9: ='c12_oc'!N59 -> -525653 | O9: ='c12_oc'!O59 -> -525653 | P9: ='c12_oc'!P59 -> -525653 | Q9: ='c12_oc'!Q59 -> -525653
A11: cash close | I11: =SUM(I6:I9) -> 9950 | J11: =SUM(J6:J9) -> 9950 | K11: =SUM(K6:K9) -> 9950 | L11: =SUM(L6:L9) -> 9950 | M11: =SUM(M6:M9) -> 9950 | N11: =SUM(N6:N9) -> 9950 | O11: =SUM(O6:O9) -> 9950 | P11: =SUM(P6:P9) -> 9950 | Q11: =SUM(Q6:Q9) -> 9950
A12: participation accrual | I12: =-'c12_oc'!I74 -> -2964570.5 | J12: =-'c12_oc'!J74 -> -2970159.3 | K12: =-'c12_oc'!K74 -> -2465036.1 | L12: =-'c12_oc'!L74 -> -2022503.4 | M12: =-'c12_oc'!M74 -> -1664945.5 | N12: =-'c12_oc'!N74 -> -2399945.5 | O12: =-'c12_oc'!O74 -> -3134945.5 | P12: =-'c12_oc'!P74 -> -3869945.5 | Q12: =-'c12_oc'!Q74 -> -4604945.5
A13: total assets | I13: =SUM(I11:I12) -> -2954620.5 | J13: =SUM(J11:J12) -> -2960209.3 | K13: =SUM(K11:K12) -> -2455086.1 | L13: =SUM(L11:L12) -> -2012553.4 | M13: =SUM(M11:M12) -> -1654995.5 | N13: =SUM(N11:N12) -> -2389995.5 | O13: =SUM(O11:O12) -> -3124995.5 | P13: =SUM(P11:P12) -> -3859995.5 | Q13: =SUM(Q11:Q12) -> -4594995.5
A15: liabilities
A16: c12loc | I16: ='c12_oc'!I62 -> -1924884.3 | J16: ='c12_oc'!J62 -> -48632.013 | K16: ='c12_oc'!K62 -> 0 | L16: ='c12_oc'!L62 -> 0 | M16: ='c12_oc'!M62 -> 0 | N16: ='c12_oc'!N62 -> 0 | O16: ='c12_oc'!O62 -> 0 | P16: ='c12_oc'!P62 -> 0 | Q16: ='c12_oc'!Q62 -> 0
A18: NAV | I18: =I16+I13 -> -4879504.8 | J18: =J16+J13 -> -3008841.3 | K18: =K16+K13 -> -2455086.1 | L18: =L16+L13 -> -2012553.4 | M18: =M16+M13 -> -1654995.5 | N18: =N16+N13 -> -2389995.5 | O18: =O16+O13 -> -3124995.5 | P18: =P16+P13 -> -3859995.5 | Q18: =Q16+Q13 -> -4594995.5

Sheet c12_hm
A2: Year | E2: 45657 | F2: 46022 | G2: 46112 | H2: 46203 | I2: 46022 | J2: 46112 | K2: 46203 | L2: 46295 | M2: 46387 | N2: 46477 | O2: 46568 | P2: 46660 | Q2: 46752
E3: actual | I3: i/o
B4: i/o | C4: field_name | D4: index
A5: LGH Fee Revenue | C5: lgh_fee_revenue_section
A6: Bermuda PB Mgt | B6: i | C6: mgmt_fee | D6: pb | E6: 535096.5 | F6: 174125 | G6: 186369 | I6: 174125 | J6: =745476/4 -> 186369 | K6: =745476/4 -> 186369 | L6: =745476/4 -> 186369 | M6: =745476/4 -> 186369 | N6: 186369 | O6: 186369 | P6: 186369 | Q6: 186369
A7: Bermuda PB Inc | B7: i | C7: incentive_fee | D7: pb | E7: 535096.5 | F7: 176042 | G7: 181323.26 | I7: 176042 | J7: =+I7*1.03 -> 181323.26 | K7: =+J7 -> 181323.26 | L7: =+K7 -> 181323.26 | M7: =+L7 -> 181323.26 | N7: 181323.26 | O7: 181323.26 | P7: 181323.26 | Q7: 181323.26
A8: Austin Mgt | B8: i | C8: mgmt_fee | D8: austin | E8: 569458 | F8: 161030 | G8: 208682.75 | I8: 161030 | J8: =834731/4 -> 208682.75 | K8: =834731/4 -> 208682.75 | L8: =834731/4 -> 208682.75 | M8: =834731/4 -> 208682.75 | N8: 208682.75 | O8: 208682.75 | P8: 208682.75 | Q8: 208682.75
A9: Austin Inc | B9: i | C9: incentive_fee | D9: austin | F9: 70827.75 | G9: 72952.583 | I9: 70827.75 | J9: =+I9*1.03 -> 72952.583 | K9: =+J9 -> 72952.583 | L9: =+K9 -> 72952.583 | M9: =+L9 -> 72952.583 | N9: 72952.583 | O9: 72952.583 | P9: 72952.583 | Q9: 72952.583
A10: Turks Mgt | B10: i | C10: mgmt_fee | D10: turks | F10: 0 | G10: 0 | I10: 0 | J10: 0 | K10: 0 | L10: 0 | M10: 0 | N10: 0 | O10: 0 | P10: 0 | Q10: 0
A11: Turks Inc | B11: i | C11: incentive_fee | D11: turks
A12: Frithholme | B12: i | C12: mgmt_fee | D12: fritholme | F12: 0 | G12: 0 | I12: 0 | J12: 0 | K12: 0 | L12: 0 | M12: 0 | N12: 0 | O12: 0 | P12: 0 | Q12: 0
A13: Elbow | B13: i | C13: mgmt_fee | D13: elbow | F13: 0 | G13: 0 | I13: 0 | J13: 0
A14: [LSAT] | B14: i | C14: mgmt_fee | D14: lsat | M14: 0 | N14: 0 | O14: 0 | P14: 0 | Q14: 0
A15: [blank]
A16: [blank]
A17: [blank]
A18: [blank]
A19: [blank]
A20: [blank]
A21: [blank]
A22: [blank]
A23: [blank]
A24: [L4] | B24: i | C24: mgmt_fee | D24: l4
A25: Total LGH Fees Earned | B25: c | C25: total_fees_earned | F25: 582024.75 | G25: 649327.59 | I25: 582024.75 | J25: =SUM(J6:J24) -> 649327.59 | K25: =SUM(K6:K24) -> 649327.59 | L25: =SUM(L6:L24) -> 649327.59 | M25: =SUM(M6:M24) -> 649327.59 | N25: =SUM(N6:N24) -> 649327.59 | O25: =SUM(O6:O24) -> 649327.59 | P25: =SUM(P6:P24) -> 649327.59 | Q25: =SUM(Q6:Q24) -> 649327.59
A27: Deferred Period Fee | B27: i | C27: deferred_fee | F27: -182177.75 | G27: -649327.59 | I27: -182177.75 | J27: =-J25 -> -649327.59 | K27: =-K7-K9 -> -254275.84 | L27: =-L7-L9 -> -254275.84 | M27: =-M7-M9-M14 -> -254275.84
A28: Paid Fee Accruals | B28: i | C28: paid_fee_accruals | G28: 50000 | J28: 50000 | K28: 246869.75 | L28: 246869.75 | M28: 1246869.8
A29: Cumm. Balance Accrued Fee | B29: c | C29: cumm_accrued_fee | F29: -394661 | G29: -993988.59 | I29: -394661 | J29: =+J27+I29+J28 -> -993988.59 | K29: =+K27+J29+K28 -> -1001394.7 | L29: =+L27+K29+L28 -> -1008800.8 | M29: =+M27+L29+M28 -> -16206.87 | N29: =+N27+M29+N28 -> -16206.87 | O29: =+O27+N29+O28 -> -16206.87 | P29: =+P27+O29+P28 -> -16206.87 | Q29: =+Q27+P29+Q28 -> -16206.87
A31: Paid Current Fees | B31: c | C31: paid_current_fees | F31: 399847 | G31: 0 | I31: 399847 | J31: =+J25+J27 -> 0 | K31: =+K25+K27 -> 395051.75 | L31: =+L25+L27 -> 395051.75 | M31: =+M25+M27 -> 395051.75 | N31: =+N25+N27 -> 649327.59 | O31: =+O25+O27 -> 649327.59 | P31: =+P25+P27 -> 649327.59 | Q31: =+Q25+Q27 -> 649327.59
A32: Total Fees Paid | B32: c | C32: total_fees_paid | F32: 399847 | G32: 50000 | I32: 399847 | J32: =+J28+J31 -> 50000 | K32: =+K28+K31 -> 641921.5 | L32: =+L28+L31 -> 641921.5 | M32: =+M28+M31 -> 1641921.5 | N32: =+N28+N31 -> 649327.59 | O32: =+O28+O31 -> 649327.59 | P32: =+P28+P31 -> 649327.59 | Q32: =+Q28+Q31 -> 649327.59
A34: LGH Service Revenue
A35: Bermuda PB | B35: i | C35: hm_service_fee | D35: pb | F35: 47750 | G35: 0 | I35: 47750 | J35: 0 | K35: 0 | L35: 0 | M35: 0 | N35: 0 | O35: 0 | P35: 0 | Q35: 0
A36: Austin | B36: i | C36: hm_service_fee | D36: austin | F36: 42250 | G36: 0 | I36: 42250 | J36: 0 | K36: 0 | L36: 0 | M36: 0 | N36: 0 | O36: 0 | P36: 0 | Q36: 0
A37: Turks | B37: i | C37: hm_service_fee | D37: turks | F37: 0 | G37: 0 | I37: 0 | J37: 0 | K37: 0 | L37: 0 | M37: 0 | N37: 0 | O37: 0 | P37: 0 | Q37: 0
A38: Elbow | B38: i | C38: hm_service_fee | D38: elbow | F38: 0 | G38: 0 | I38: 0 | J38: 0 | K38: 0 | L38: 0 | M38: 0 | N38: 0 | O38: 0 | P38: 0 | Q38: 0
A39: [blank]
A40: [blank]
A41: [blank]
A42: [blank]
A43: [blank]
A44: [blank]
...

Sheet c12_d&s
A2: Year | E2: 45657 | F2: 46022 | G2: 46112 | H2: 46203 | I2: 46022 | J2: 46112 | K2: 46203 | L2: 46295 | M2: 46387 | N2: 46477 | O2: 46568 | P2: 46660 | Q2: 46752
E3: actual | I3: i/o
B4: i/o | C4: field_name | D4: index
A5: LGH Fee Revenue
A6: Pink Beach Design Fee | B6: i | C6: design_fee | D6: pb | F6: 0 | G6: 0 | I6: 0 | J6: 0 | K6: 0 | L6: 0 | M6: 0 | N6: 0 | O6: 0 | P6: 0 | Q6: 0
A7: Pink Beach Development Fee | B7: i | C7: development_fee | D7: pb | F7: 0 | G7: 0 | I7: 0 | J7: 0 | K7: 0 | L7: 0 | M7: 0 | N7: 0 | O7: 0 | P7: 0 | Q7: 0
A8: Pink Beach Structuring Fee | B8: i | C8: structuring_fee | D8: pb | K8: 0 | M8: 0 | N8: 0 | O8: 0 | P8: 0 | Q8: 0
A9: Austin Design Fee | B9: i | C9: design_fee | D9: austin | F9: 0 | G9: 0 | I9: 0 | J9: 0 | K9: 0 | L9: 0 | M9: 0 | N9: 0 | O9: 0 | P9: 0 | Q9: 0
A10: Austin Development Fee | B10: i | C10: development_fee | D10: austin | F10: 0 | G10: 0 | I10: 0 | J10: 0 | K10: 0 | L10: 0 | M10: 0 | N10: 0 | O10: 0 | P10: 0 | Q10: 0
A11: Turks Design Fee | B11: i | C11: design_fee | D11: turks | F11: 50000 | G11: 0 | I11: 50000 | J11: 0 | K11: 0 | L11: 0 | M11: 0 | N11: 0 | O11: 0 | P11: 0 | Q11: 0
A12: Turks Development Fee | B12: i | C12: development_fee | D12: turks | E12: 812800 | F12: 340000 | G12: 549375 | I12: 340000 | J12: =2930000/16*3 -> 549375 | K12: =2930000/16*3 -> 549375 | L12: =2930000/16*3 -> 549375 | M12: =2930000/16*3 -> 549375 | N12: 549375 | O12: 549375 | P12: 549375 | Q12: 549375
A13: Turks Structuring Fee | B13: i | C13: structuring_fee | D13: turks | F13: 250000 | G13: 0 | I13: 250000 | J13: 0 | K13: 0 | L13: 0 | M13: 0 | N13: 0 | O13: 0 | P13: 0 | Q13: 0
A14: Elbow Design Fee | B14: i | C14: design_fee | D14: elbow | F14: 375000 | G14: 487500 | I14: 375000 | J14: =(4500000*0.6-SUM($I$14:$I$14))/4 -> 581250 | K14: =(4500000*0.6-SUM($I$14:$I$14))/4 -> 581250 | L14: =(4500000*0.6-SUM($I$14:$I$14))/4 -> 581250 | M14: =(4500000*0.6-SUM($I$14:$I$14))/4 -> 581250 | N14: 581250 | O14: 581250 | P14: 581250 | Q14: 581250
A15: Elbow Development Fee | B15: i | C15: development_fee | D15: elbow | F15: 500000 | G15: 433333.33 | I15: 500000 | J15: =5200000/3/4 -> 433333.33 | K15: =5200000/3/4 -> 433333.33 | L15: =5200000/3/4 -> 433333.33 | M15: =5200000/3/4 -> 433333.33 | N15: 433333.33 | O15: 433333.33 | P15: 433333.33 | Q15: 433333.33
A16: Elbow Structuring Fee | B16: i | C16: structuring_fee | D16: elbow | F16: 0 | G16: 0 | I16: 0 | J16: 0 | K16: 0 | L16: 0 | M16: 0 | N16: 0 | O16: 0 | P16: 0 | Q16: 0
A17: Elbow Construction Fee | B17: i | C17: construction_fee | D17: elbow | G17: 0 | J17: 0 | K17: 0 | L17: 0 | M17: 0 | N17: 0 | O17: 0 | P17: 0 | Q17: 0
A18: Elbow Acquisition Fee | B18: i | C18: acquisition_fee | D18: elbow
A19: [blank] | F19: 0 | G19: 0 | I19: 0 | J19: 0 | K19: 0 | L19: 0 | M19: 0 | N19: 0 | O19: 0 | P19: 0 | Q19: 0
A20: Frith Acq Fee | B20: i | C20: acquisition_fee | D20: fritholme | F20: 0 | G20: 0 | I20: 0 | J20: 0 | K20: 0 | L20: 0 | M20: 0 | N20: 0 | O20: 0 | P20: 0 | Q20: 0
A21: [blank] | F21: 0 | G21: 0 | I21: 0 | J21: 0 | K21: 0 | L21: 0 | M21: 0 | N21: 0 | O21: 0 | P21: 0 | Q21: 0
A22: Frith Disposition fee | B22: i | C22: disposition_fee | D22: fritholme | F22: 0 | G22: 0 | I22: 0 | J22: 0 | K22: 0 | L22: 0 | M22: 2500000 | N22: 2500000 | O22: 2500000 | P22: 2500000 | Q22: 2500000
A23: SAT | B23: i | C23: development_fee | D23: lsat | M23: =500000+1600000 -> 2100000 | N23: 2100000 | O23: 2100000 | P23: 2100000 | Q23: 2100000
A24: [L4] | B24: i | C24: development_fee | D24: l4 | L24: 0 | M24: 0 | N24: 0 | O24: 0 | P24: 0 | Q24: 0
A25: Total LGH Fees Earned | B25: c | C25: total_fees_earned | F25: 1515000 | G25: 1470208.3 | I25: 1515000 | J25: =SUM(J6:J24) -> 1563958.3 | K25: =SUM(K6:K24) -> 1563958.3 | L25: =SUM(L6:L24) -> 1563958.3 | M25: =SUM(M6:M24) -> 6163958.3 | N25: =SUM(N6:N24) -> 6163958.3 | O25: =SUM(O6:O24) -> 6163958.3 | P25: =SUM(P6:P24) -> 6163958.3 | Q25: =SUM(Q6:Q24) -> 6163958.3
A27: Deferred Period Fee | B27: i | C27: deferred_fee | F27: -745000 | G27: -1470208 | I27: -745000 | J27: -1470208 | K27: =-1000000+310000 -> -690000 | L27: -1000000 | M27: -2100000 | N27: -2100000 | O27: -2100000 | P27: -2100000 | Q27: -2100000
A28: Paid Fee Accruals | B28: i | C28: paid_fee_accruals | G28: 1508647.3 | J28: 1508647.3 | K28: 1177500 | L28: 1177500 | M28: 1177500
A29: Cumm. Balance Accrued Fee | B29: c | C29: cumm_accrued_fee | F29: -4710000 | G29: -4671560.7 | I29: -4710000 | J29: =+J27+I29+J28 -> -4671560.7 | K29: =+K27+J29+K28 -> -4184060.7 | L29: =+L27+K29+L28 -> -4006560.7 | M29: =+M27+L29+M28 -> -4929060.7 | N29: =+N27+M29+N28 -> -7029060.7 | O29: =+O27+N29+O28 -> -9129060.7 | P29: =+P27+O29+P28 -> -11229061 | Q29: =+Q27+P29+Q28 -> -13329061
A31: Paid Current Fees | B31: c | C31: paid_current_fees | F31: 770000 | G31: 0.33333333 | I31: 770000 | J31: =+J25+J27 -> 93750.333 | K31: =+K25+K27 -> 873958.33 | L31: =+L25+L27 -> 563958.33 | M31: =+M25+M27 -> 4063958.3 | N31: =+N25+N27 -> 4063958.3 | O31: =+O25+O27 -> 4063958.3 | P31: =+P25+P27 -> 4063958.3 | Q31: =+Q25+Q27 -> 4063958.3
A32: Total Fees Paid | B32: c | C32: total_fees_paid | F32: 770000 | G32: 1508647.7 | I32: 770000 | J32: =+J28+J31 -> 1602397.7 | K32: =+K28+K31 -> 2051458.3 | L32: =+L28+L31 -> 1741458.3 | M32: =+M28+M31 -> 5241458.3 | N32: =+N28+N31 -> 4063958.3 | O32: =+O28+O31 -> 4063958.3 | P32: =+P28+P31 -> 4063958.3 | Q32: =+Q28+Q31 -> 4063958.3
A34: LGH Service Revenue
A35: PB Design Services | B35: i | C35: design_service_fee | D35: pb | F35: 22110.5 | G35: 45000 | I35: 22110.5 | J35: =180000/4 -> 45000 | K35: =180000/4 -> 45000 | L35: =180000/4 -> 45000 | M35: =180000/4 -> 45000 | N35: 45000 | O35: 45000 | P35: 45000 | Q35: 45000
A36: Austin Design Services | B36: i | C36: design_service_fee | D36: austin | E36: 667500 | F36: 22954.75 | G36: 60000 | I36: 22954.75 | J36: =240000/4 -> 60000 | K36: =240000/4 -> 60000 | L36: =240000/4 -> 60000 | M36: =240000/4 -> 60000 | N36: 60000 | O36: 60000 | P36: 60000 | Q36: 60000
A37: Turks Design Services | B37: i | C37: design_service_fee | D37: turks | F37: 0 | G37: 50000 | I37: 0 | J37: =200000/4 -> 50000 | K37: =400000/4 -> 100000 | L37: =200000/4 -> 50000 | M37: =200000/4 -> 50000 | N37: 50000 | O37: 50000 | P37: 50000 | Q37: 50000
A38: Elbow Design Services | B38: i | C38: design_service_fee | D38: elbow | F38: 0 | G38: 0 | I38: 0 | J38: 0 | K38: =180000/4 -> 45000 | L38: =180000/4 -> 45000 | M38: =+L38 -> 45000 | N38: 45000 | O38: 45000 | P38: 45000 | Q38: 45000
A39: Elbow AM | B39: i | C39: am_fee | D39: elbow | F39: 0 | G39: 0 | I39: 0 | J39: 0 | K39: 0 | L39: 0 | M39: 0 | N39: 0 | O39: 0 | P39: 0 | Q39: 0
A40: Frith Design Services | B40: i | C40: design_service_fee | D40: fritholme | F40: 0 | G40: 27000 | I40: 0 | J40: =108000/4 -> 27000 | K40: =+J40 -> 27000 | L40: =+K40 -> 27000 | M40: =+L40 -> 27000 | N40: 27000 | O40: 27000 | P40: 27000 | Q40: 27000
A41: Frith AM | B41: i | C41: am_fee | D41: fritholme | F41: 12500 | G41: 12500 | I41: 12500 | J41: 12500 | K41: 12500 | L41: 12500
A42: Bermuda PB AM | B42: i | C42: am_fee | D42: pb | F42: 57077.25 | G42: 72879 | I42: 57077.25 | J42: 72879 | K42: 72879 | L42: 72879 | M42: 72879 | N42: 72879 | O42: 72879 | P42: 72879 | Q42: 72879
A43: AustinAM | B43: i | C43: am_fee | D43: austin | F43: 49547.75 | G43: 63543 | I43: 49547.75 | J43: 63543 | K43: 63543 | L43: 63543 | M43: 63543 | N43: 63543 | O43: 63543 | P43: 63543 | Q43: 63543
A44: [blank]
...

Sheet c12_bi&F
A2: Year | E2: 45657 | F2: 46022 | G2: 46112 | H2: 46203 | I2: 46022 | J2: 46112 | K2: 46203 | L2: 46295 | M2: 46387 | N2: 46477 | O2: 46568 | P2: 46660 | Q2: 46752
E3: actual | I3: i/o
B4: i/o | C4: field_name | D4: index
A5: LGH Fee Revenue | C5: lgh_fee_revenue_section
A6: [blank]
A7: [blank]
A8: [blank]
A9: [blank]
A10: [blank]
A11: [blank]
A12: [blank]
A13: [blank]
A14: [blank]
A15: [blank]
A16: [blank]
A17: [blank]
... A21: [blank]
A22: [blank] | F22: 0 | G22: 0 | I22: 0 | J22: 0 | K22: 0 | L22: 0 | M22: 0 | N22: 0 | O22: 0 | P22: 0 | Q22: 0
A23: [blank] | F23: 0 | G23: 0 | I23: 0 | J23: 0 | K23: 0 | L23: 0 | M23: 0 | N23: 0 | O23: 0 | P23: 0 | Q23: 0
A24: [blank] | F24: 0 | G24: 0 | I24: 0 | J24: 0 | K24: 0 | L24: 0 | M24: 0 | N24: 0 | O24: 0 | P24: 0 | Q24: 0
A25: Total LGH Fees Earned | B25: c | C25: total_fees_earned | F25: 0 | G25: 0 | I25: 0 | J25: =SUM(J22:J24) -> 0 | K25: =SUM(K22:K24) -> 0 | L25: =SUM(L22:L24) -> 0 | M25: =SUM(M22:M24) -> 0 | N25: =SUM(N22:N24) -> 0 | O25: =SUM(O22:O24) -> 0 | P25: =SUM(P22:P24) -> 0 | Q25: =SUM(Q22:Q24) -> 0
A27: Deferred Period Fee | B27: i | C27: deferred_fee | F27: 0 | G27: 0 | I27: 0 | J27: 0 | K27: 0 | L27: 0 | M27: 0 | N27: 0 | O27: 0 | P27: 0 | Q27: 0
A28: Paid Fee Accruals | B28: i | C28: paid_fee_accruals | F28: 0 | G28: 0 | I28: 0 | J28: 0 | K28: 0 | L28: 0 | M28: 0 | N28: 0 | O28: 0 | P28: 0 | Q28: 0
A29: Cumm. Balance Accrued Fee | B29: c | C29: cumm_accrued_fee | F29: 0 | G29: 0 | I29: 0 | J29: =+J27+I29+J28 -> 0 | K29: =+K27+J29+K28 -> 0 | L29: =+L27+K29+L28 -> 0 | M29: =+M27+L29+M28 -> 0 | N29: =+N27+M29+N28 -> 0 | O29: =+O27+N29+O28 -> 0 | P29: =+P27+O29+P28 -> 0 | Q29: =+Q27+P29+Q28 -> 0
A31: Paid Current Fees | B31: c | C31: paid_current_fees | F31: 0 | G31: 0 | I31: 0 | J31: =+J25+J27 -> 0 | K31: =+K25+K27 -> 0 | L31: =+L25+L27 -> 0 | M31: =+M25+M27 -> 0 | N31: =+N25+N27 -> 0 | O31: =+O25+O27 -> 0 | P31: =+P25+P27 -> 0 | Q31: =+Q25+Q27 -> 0
A32: Total Fees Paid | B32: c | C32: total_fees_paid | F32: 0 | G32: 0 | I32: 0 | J32: =+J28+J31 -> 0 | K32: =+K28+K31 -> 0 | L32: =+L28+L31 -> 0 | M32: =+M28+M31 -> 0 | N32: =+N28+N31 -> 0 | O32: =+O28+O31 -> 0 | P32: =+P28+P31 -> 0 | Q32: =+Q28+Q31 -> 0
A34: LGH Service Revenue | C34: lgh_service_revenue_section
A35: Bermuda PB | B35: i | C35: accting_fee | D35: pb | F35: 0 | G35: 15000 | I35: 0 | J35: =60000/4 -> 15000 | K35: =60000/4 -> 15000 | L35: =60000/4 -> 15000 | M35: =60000/4 -> 15000 | N35: 15000 | O35: 15000 | P35: 15000 | Q35: 15000
A36: 7f | B36: i | C36: accting_fee | D36: austin | F36: 0 | G36: 15000 | I36: 0 | J36: =60000/4 -> 15000 | K36: =60000/4 -> 15000 | L36: =60000/4 -> 15000 | M36: =60000/4 -> 15000 | N36: 15000 | O36: 15000 | P36: 15000 | Q36: 15000
A37: Turks | B37: i | C37: accting_fee | D37: turks | F37: 0 | G37: 0 | I37: 0 | J37: 0 | K37: 0 | L37: 0 | M37: 0 | N37: 0 | O37: 0 | P37: 0 | Q37: 0
A38: Elbow | B38: i | C38: accting_fee | D38: elbow | F38: 0 | G38: 0 | I38: 0 | J38: 0 | K38: 0 | L38: 0 | M38: 0 | N38: 0 | O38: 0 | P38: 0 | Q38: 0
A39: Frith | B39: i | C39: accting_fee | D39: fritholme | F39: 0 | G39: 0 | I39: 0 | J39: 0 | K39: =+J39 -> 0 | L39: =+K39 -> 0 | M39: =+L39 -> 0 | N39: 0 | O39: 0 | P39: 0 | Q39: 0
A40: [blank]
A41: [blank]
A42: [blank]
A43: [blank]
A44: [blank]
A45: [LSAT] | B45: i | C45: accting_fee | D45: lsat
A46: Total LGH Bi&F Service Revenue | B46: c | C46: total_service_revenue | F46: 0 | G46: 30000 | I46: 0 | J46: =SUM(J35:J45) -> 30000 | K46: =SUM(K35:K45) -> 30000 | L46: =SUM(L35:L45) -> 30000 | M46: =SUM(M35:M45) -> 30000 | N46: =SUM(N35:N45) -> 30000 | O46: =SUM(O35:O45) -> 30000 | P46: =SUM(P35:P45) -> 30000 | Q46: =SUM(Q35:Q45) -> 30000
A48: Deferred Period Fee | B48: i | C48: deferred_service_fee
...

Sheet .c12_inputs.hr
B4: i/o | C4: field_name | D4: index
A5: ocBenefits | B5: i | C5: benefits_rate | D5: oc | E5: 0.021714286 | F5: adjusted down to assume sk doesn’t pay
A6: ocBonus Tax | B6: i | C6: bonus_tax_rate_actual | D6: oc | E6: 0.039
A8: hmBenefits | B8: i | C8: benefits_rate_actual | D8: hm | E8: 0.152
A9: hmBonus Tax | B9: i | C9: bonus_tax_rate_actual | D9: hm | E9: 0.039
A11: bfBenefits | B11: i | C11: benefits_rate_actual | D11: bif | E11: 0.152
A12: bfBonus Tax | B12: i | C12: bonus_tax_rate_actual | D12: bif | E12: 0.039
A15: dsBenefits | B15: i | C15: benefits_rate_actual | D15: ds | E15: 0.152
A16: dsBonus Tax | B16: i | C16: bonus_tax_rate_actual | D16: ds | E16: 0.039

Sheet .c12_oc_hr
A2: Year | E2: 45657 | F2: 46022 | G2: 46112 | H2: 46203 | I2: 46022 | J2: 46112 | K2: 46203 | L2: 46295 | M2: 46387 | N2: 46477 | O2: 46568 | P2: 46660 | Q2: 46752
E3: actual | I3: i/o
B4: i/o | C4: field_name | D4: index
A5: Base
A6: Managing Member (SK) | B6: i | C6: base_salary | D6: sk | F6: 375000 | G6: 375000 | I6: 375000 | J6: 375000 | K6: 375000 | L6: 375000 | M6: 375000 | N6: 375000 | O6: 375000 | P6: 375000 | Q6: 375000
A7: Philanropy senior exec (LM) (100%roots) | B7: i | C7: base_salary | D7: lm | F7: 0 | G7: 0 | I7: 0 | J7: 0 | K7: 0 | L7: 0 | M7: 0 | N7: 0 | O7: 0 | P7: 0 | Q7: 0
A8: Bookkeeper (DD) | B8: i | C8: base_salary | D8: dd | F8: 0 | G8: 25750 | I8: 0 | J8: 25750 | K8: 25750 | L8: 25750 | M8: 25750 | N8: 25750 | O8: 25750 | P8: 25750 | Q8: 25750
A9: Personal Assistant (CD) | B9: i | C9: base_salary | D9: cd | F9: 31250 | G9: 31250 | I9: 31250 | J9: 31250 | K9: 31250 | L9: 31250 | M9: 31250 | N9: 31250 | O9: 31250 | P9: 31250 | Q9: 31250
A10: philanthropy assist (100%roots) | B10: i | C10: base_salary | D10: philanthropy | F10: 0 | G10: 0 | I10: 0 | J10: 0 | K10: 0 | L10: 0 | M10: 0 | N10: 0 | O10: 0 | P10: 0 | Q10: 0
A11: TM (gone) | B11: i | C11: base_salary | D11: tm | F11: 87500 | G11: 87500 | I11: 87500 | J11: 87500 | K11: 0 | L11: 0 | M11: 0 | N11: 0 | O11: 0 | P11: 0 | Q11: 0
A12: Total | F12: 493750 | G12: 519500 | I12: 493750 | J12: =SUM(J6:J11) -> 519500 | K12: =SUM(K6:K11) -> 432000 | L12: =SUM(L6:L11) -> 432000 | M12: =SUM(M6:M11) -> 432000 | N12: =SUM(N6:N11) -> 432000 | O12: =SUM(O6:O11) -> 432000 | P12: =SUM(P6:P11) -> 432000 | Q12: =SUM(Q6:Q11) -> 432000
A13: Bonus
A14: =+A6 -> Managing Member (SK) | B14: i | C14: bonus | D14: sk | F14: 0 | G14: 0 | I14: 0 | J14: 0 | K14: 0 | L14: 0 | M14: 0 | N14: 0 | O14: 0 | P14: 0 | Q14: 0
A15: =+A7 -> Philanropy senior exec (LM) (100%roots) | B15: i | C15: bonus | D15: lm | F15: 0 | G15: 0 | I15: 0 | J15: 0 | K15: 0 | L15: 0 | M15: 0 | N15: 0 | O15: 0 | P15: 0 | Q15: 0
A16: =+A8 -> Bookkeeper (DD) | B16: i | C16: bonus | D16: dd | F16: 10000 | G16: 0 | I16: 10000 | J16: 0 | K16: 0 | L16: 0 | M16: 5000 | N16: 5000 | O16: 5000 | P16: 5000 | Q16: 5000
A17: =+A9 -> Personal Assistant (CD) | B17: i | C17: bonus | D17: cd | F17: 0 | G17: 0 | I17: 0 | J17: 0 | K17: 0 | L17: 0 | M17: 15000 | N17: 15000 | O17: 15000 | P17: 15000 | Q17: 15000
A18: =+A10 -> philanthropy assist (100%roots) | B18: i | C18: bonus | D18: philanthropy | F18: 0 | G18: 0 | I18: 0 | J18: 0 | K18: 0 | L18: 0 | M18: 0 | N18: 0 | O18: 0 | P18: 0 | Q18: 0
A19: =+A11 -> TM (gone) | B19: i | C19: bonus | D19: tm | F19: 0 | G19: 320000 | I19: 0 | J19: 320000 | K19: 0 | L19: 0 | M19: 500000 | N19: 500000 | O19: 500000 | P19: 500000 | Q19: 500000
A20: Total | F20: 10000 | G20: 320000 | I20: 10000 | J20: =SUM(J14:J19) -> 320000 | K20: =SUM(K14:K19) -> 0 | L20: =SUM(L14:L19) -> 0 | M20: =SUM(M14:M19) -> 520000 | N20: =SUM(N14:N19) -> 520000 | O20: =SUM(O14:O19) -> 520000 | P20: =SUM(P14:P19) -> 520000 | Q20: =SUM(Q14:Q19) -> 520000
A22: Total
A23: =+A6 -> Managing Member (SK) | B23: c | C23: total_salary | D23: sk | F23: 383142.86 | G23: 383142.86 | I23: 383142.86 | J23: =J6*(1+'.c12_inputs.hr'!$E$5)+(J14*(1+'.c12_inputs.hr'!$E$6)) -> 383142.86 | K23: =K6*(1+'.c12_inputs.hr'!$E$5)+(K14*(1+'.c12_inputs.hr'!$E$6)) -> 383142.86 | L23: =L6*(1+'.c12_inputs.hr'!$E$5)+(L14*(1+'.c12_inputs.hr'!$E$6)) -> 383142.86 | M23: =M6*(1+'.c12_inputs.hr'!$E$5)+(M14*(1+'.c12_inputs.hr'!$E$6)) -> 383142.86 | N23: =N6*(1+'.c12_inputs.hr'!$E$5)+(N14*(1+'.c12_inputs.hr'!$E$6)) -> 383142.86 | O23: =O6*(1+'.c12_inputs.hr'!$E$5)+(O14*(1+'.c12_inputs.hr'!$E$6)) -> 383142.86 | P23: =P6*(1+'.c12_inputs.hr'!$E$5)+(P14*(1+'.c12_inputs.hr'!$E$6)) -> 383142.86 | Q23: =Q6*(1+'.c12_inputs.hr'!$E$5)+(Q14*(1+'.c12_inputs.hr'!$E$6)) -> 383142.86
A24: =+A7 -> Philanropy senior exec (LM) (100%roots) | B24: c | C24: total_salary | D24: lm | F24: 0 | G24: 0 | I24: 0 | J24: =J7*(1+'.c12_inputs.hr'!$E$5)+(J15*(1+'.c12_inputs.hr'!$E$6)) -> 0 | K24: =K7*(1+'.c12_inputs.hr'!$E$5)+(K15*(1+'.c12_inputs.hr'!$E$6)) -> 0 | L24: =L7*(1+'.c12_inputs.hr'!$E$5)+(L15*(1+'.c12_inputs.hr'!$E$6)) -> 0 | M24: =M7*(1+'.c12_inputs.hr'!$E$5)+(M15*(1+'.c12_inputs.hr'!$E$6)) -> 0 | N24: =N7*(1+'.c12_inputs.hr'!$E$5)+(N15*(1+'.c12_inputs.hr'!$E$6)) -> 0 | O24: =O7*(1+'.c12_inputs.hr'!$E$5)+(O15*(1+'.c12_inputs.hr'!$E$6)) -> 0 | P24: =P7*(1+'.c12_inputs.hr'!$E$5)+(P15*(1+'.c12_inputs.hr'!$E$6)) -> 0 | Q24: =Q7*(1+'.c12_inputs.hr'!$E$5)+(Q15*(1+'.c12_inputs.hr'!$E$6)) -> 0
A25: =+A8 -> Bookkeeper (DD) | B25: c | C25: total_salary | D25: dd | F25: 10390 | G25: 26309.143 | I25: 10390 | J25: =J8*(1+'.c12_inputs.hr'!$E$5)+(J16*(1+'.c12_inputs.hr'!$E$6)) -> 26309.143 | K25: =K8*(1+'.c12_inputs.hr'!$E$5)+(K16*(1+'.c12_inputs.hr'!$E$6)) -> 26309.143 | L25: =L8*(1+'.c12_inputs.hr'!$E$5)+(L16*(1+'.c12_inputs.hr'!$E$6)) -> 26309.143 | M25: =M8*(1+'.c12_inputs.hr'!$E$5)+(M16*(1+'.c12_inputs.hr'!$E$6)) -> 31504.143 | N25: =N8*(1+'.c12_inputs.hr'!$E$5)+(N16*(1+'.c12_inputs.hr'!$E$6)) -> 31504.143 | O25: =O8*(1+'.c12_inputs.hr'!$E$5)+(O16*(1+'.c12_inputs.hr'!$E$6)) -> 31504.143 | P25: =P8*(1+'.c12_inputs.hr'!$E$5)+(P16*(1+'.c12_inputs.hr'!$E$6)) -> 31504.143 | Q25: =Q8*(1+'.c12_inputs.hr'!$E$5)+(Q16*(1+'.c12_inputs.hr'!$E$6)) -> 31504.143
A26: =+A9 -> Personal Assistant (CD) | B26: c | C26: total_salary | D26: cd | F26: 31928.571 | G26: 31928.571 | I26: 31928.571 | J26: =J9*(1+'.c12_inputs.hr'!$E$5)+(J17*(1+'.c12_inputs.hr'!$E$6)) -> 31928.571 | K26: =K9*(1+'.c12_inputs.hr'!$E$5)+(K17*(1+'.c12_inputs.hr'!$E$6)) -> 31928.571 | L26: =L9*(1+'.c12_inputs.hr'!$E$5)+(L17*(1+'.c12_inputs.hr'!$E$6)) -> 31928.571 | M26: =M9*(1+'.c12_inputs.hr'!$E$5)+(M17*(1+'.c12_inputs.hr'!$E$6)) -> 47513.571 | N26: =N9*(1+'.c12_inputs.hr'!$E$5)+(N17*(1+'.c12_inputs.hr'!$E$6)) -> 47513.571 | O26: =O9*(1+'.c12_inputs.hr'!$E$5)+(O17*(1+'.c12_inputs.hr'!$E$6)) -> 47513.571 | P26: =P9*(1+'.c12_inputs.hr'!$E$5)+(P17*(1+'.c12_inputs.hr'!$E$6)) -> 47513.571 | Q26: =Q9*(1+'.c12_inputs.hr'!$E$5)+(Q17*(1+'.c12_inputs.hr'!$E$6)) -> 47513.571
A27: =+A10 -> philanthropy assist (100%roots) | B27: c | C27: total_salary | D27: philanthropy | F27: 0 | G27: 0 | I27: 0 | J27: =J10*(1+'.c12_inputs.hr'!$E$5)+(J18*(1+'.c12_inputs.hr'!$E$6)) -> 0 | K27: =K10*(1+'.c12_inputs.hr'!$E$5)+(K18*(1+'.c12_inputs.hr'!$E$6)) -> 0 | L27: =L10*(1+'.c12_inputs.hr'!$E$5)+(L18*(1+'.c12_inputs.hr'!$E$6)) -> 0 | M27: =M10*(1+'.c12_inputs.hr'!$E$5)+(M18*(1+'.c12_inputs.hr'!$E$6)) -> 0 | N27: =N10*(1+'.c12_inputs.hr'!$E$5)+(N18*(1+'.c12_inputs.hr'!$E$6)) -> 0 | O27: =O10*(1+'.c12_inputs.hr'!$E$5)+(O18*(1+'.c12_inputs.hr'!$E$6)) -> 0 | P27: =P10*(1+'.c12_inputs.hr'!$E$5)+(P18*(1+'.c12_inputs.hr'!$E$6)) -> 0 | Q27: =Q10*(1+'.c12_inputs.hr'!$E$5)+(Q18*(1+'.c12_inputs.hr'!$E$6)) -> 0
A28: =+A11 -> TM (gone) | B28: c | C28: total_salary | D28: tm | F28: 89400 | G28: 421880 | I28: 89400 | J28: =J11*(1+'.c12_inputs.hr'!$E$5)+(J19*(1+'.c12_inputs.hr'!$E$6)) -> 421880 | K28: =K11*(1+'.c12_inputs.hr'!$E$5)+(K19*(1+'.c12_inputs.hr'!$E$6)) -> 0 | L28: =L11*(1+'.c12_inputs.hr'!$E$5)+(L19*(1+'.c12_inputs.hr'!$E$6)) -> 0 | M28: =M11*(1+'.c12_inputs.hr'!$E$5)+(M19*(1+'.c12_inputs.hr'!$E$6)) -> 519500 | N28: =N11*(1+'.c12_inputs.hr'!$E$5)+(N19*(1+'.c12_inputs.hr'!$E$6)) -> 519500 | O28: =O11*(1+'.c12_inputs.hr'!$E$5)+(O19*(1+'.c12_inputs.hr'!$E$6)) -> 519500 | P28: =P11*(1+'.c12_inputs.hr'!$E$5)+(P19*(1+'.c12_inputs.hr'!$E$6)) -> 519500 | Q28: =Q11*(1+'.c12_inputs.hr'!$E$5)+(Q19*(1+'.c12_inputs.hr'!$E$6)) -> 519500
A30: Grand Total | B30: o | C30: hr_grand_total | F30: 514861.43 | G30: 863260.57 | I30: 514861.43 | J30: =SUM(J23:J28) -> 863260.57 | K30: =SUM(K23:K28) -> 441380.57 | L30: =SUM(L23:L28) -> 441380.57 | M30: =SUM(M23:M28) -> 981660.57 | N30: =SUM(N23:N28) -> 981660.57 | O30: =SUM(O23:O28) -> 981660.57 | P30: =SUM(P23:P28) -> 981660.57 | Q30: =SUM(Q23:Q28) -> 981660.57
A31: reimbersable to hotel | B31: o | C31: hr_reimbursable | F31: 0 | G31: 0 | I31: 0 | J31: =SUMPRODUCT('.c12_alloc'!$H$6:$H$11,J23:J28) -> 0 | K31: =SUMPRODUCT('.c12_alloc'!$H$6:$H$11,K23:K28) -> 0 | L31: =SUMPRODUCT('.c12_alloc'!$H$6:$H$11,L23:L28) -> 0 | M31: =SUMPRODUCT('.c12_alloc'!$H$6:$H$11,M23:M28) -> 0 | N31: =SUMPRODUCT('.c12_alloc'!$H$6:$H$11,N23:N28) -> 0 | O31: =SUMPRODUCT('.c12_alloc'!$H$6:$H$11,O23:O28) -> 0 | P31: =SUMPRODUCT('.c12_alloc'!$H$6:$H$11,P23:P28) -> 0 | Q31: =SUMPRODUCT('.c12_alloc'!$H$6:$H$11,Q23:Q28) -> 0
A32: not reimbersable by hotel, but paid by lgh | B32: o | C32: hr_not_reimbursable | F32: 472542.86 | G32: 805022.86 | I32: 472542.86 | J32: =SUMPRODUCT('.c12_alloc'!$G$6:$G$11,J23:J28) -> 805022.86 | K32: =SUMPRODUCT('.c12_alloc'!$G$6:$G$11,K23:K28) -> 383142.86 | L32: =SUMPRODUCT('.c12_alloc'!$G$6:$G$11,L23:L28) -> 383142.86 | M32: =SUMPRODUCT('.c12_alloc'!$G$6:$G$11,M23:M28) -> 902642.86 | N32: =SUMPRODUCT('.c12_alloc'!$G$6:$G$11,N23:N28) -> 902642.86 | O32: =SUMPRODUCT('.c12_alloc'!$G$6:$G$11,O23:O28) -> 902642.86 | P32: =SUMPRODUCT('.c12_alloc'!$G$6:$G$11,P23:P28) -> 902642.86 | Q32: =SUMPRODUCT('.c12_alloc'!$G$6:$G$11,Q23:Q28) -> 902642.86
A33: only paid by c12 | B33: o | C33: hr_only_c12 | F33: 42318.571 | G33: 58237.714 | I33: 42318.571 | J33: =SUMPRODUCT('.c12_alloc'!$E$6:$E$11,J23:J28) -> 58237.714 | K33: =SUMPRODUCT('.c12_alloc'!$E$6:$E$11,K23:K28) -> 58237.714 | L33: =SUMPRODUCT('.c12_alloc'!$E$6:$E$11,L23:L28) -> 58237.714 | M33: =SUMPRODUCT('.c12_alloc'!$E$6:$E$11,M23:M28) -> 79017.714 | N33: =SUMPRODUCT('.c12_alloc'!$E$6:$E$11,N23:N28) -> 79017.714 | O33: =SUMPRODUCT('.c12_alloc'!$E$6:$E$11,O23:O28) -> 79017.714 | P33: =SUMPRODUCT('.c12_alloc'!$E$6:$E$11,P23:P28) -> 79017.714 | Q33: =SUMPRODUCT('.c12_alloc'!$E$6:$E$11,Q23:Q28) -> 79017.714

Sheet .c12_hm_hr
A2: Year | E2: 45657 | F2: 46022 | G2: 46112 | H2: 46203 | I2: 46022 | J2: 46112 | K2: 46203 | L2: 46295 | M2: 46387 | N2: 46477 | O2: 46568 | P2: 46660 | Q2: 46752
E3: actual | I3: i/o
B4: i/o | C4: field_name | D4: index
A5: base
A6: ACEO Loren Hotels (CE) | B6: i | C6: base_salary | D6: ce | F6: 125000 | G6: 125000 | I6: 125000 | J6: 125000 | K6: 125000 | L6: 125000 | M6: 125000 | N6: 125000 | O6: 125000 | P6: 125000 | Q6: 125000
A7: VP Operations (WS) | B7: i | C7: base_salary | D7: ws | F7: 68750 | G7: 72500 | I7: 68750 | J7: 72500 | K7: 72500 | L7: 72500 | M7: 72500 | N7: 72500 | O7: 72500 | P7: 72500 | Q7: 72500
A8: seniorS&Mexe (CL) | B8: i | C8: base_salary | D8: cl | F8: 0 | G8: 75000 | I8: 0 | J8: 75000 | K8: 75000 | L8: 75000 | M8: 75000 | N8: 75000 | O8: 75000 | P8: 75000 | Q8: 75000
A9: Senior Associate (RF) | B9: i | C9: base_salary | D9: rf | F9: 37500 | G9: 40000 | I9: 37500 | J9: 40000 | K9: 40000 | L9: 40000 | M9: 40000 | N9: 40000 | O9: 40000 | P9: 40000 | Q9: 40000
A10: associate (MT) | B10: i | C10: base_salary | D10: mt | F10: 27500 | G10: 27500 | I10: 27500 | J10: 27500 | K10: 27500 | L10: 27500 | M10: 27500 | N10: 27500 | O10: 27500 | P10: 27500 | Q10: 27500
A11: project manager | B11: i | C11: base_salary | D11: project | F11: 0 | G11: 0 | I11: 0 | J11: 0 | K11: 0 | L11: 37500 | M11: 37500 | N11: 37500 | O11: 37500 | P11: 37500 | Q11: 37500
A12: Total | F12: 258750 | G12: 340000 | I12: 258750 | J12: =SUM(J6:J11) -> 340000 | K12: =SUM(K6:K11) -> 340000 | L12: =SUM(L6:L11) -> 377500 | M12: =SUM(M6:M11) -> 377500 | N12: =SUM(N6:N11) -> 377500 | O12: =SUM(O6:O11) -> 377500 | P12: =SUM(P6:P11) -> 377500 | Q12: =SUM(Q6:Q11) -> 377500
A14: Bonus
A15: =A6 -> ACEO Loren Hotels (CE) | B15: i | C15: bonus | D15: ce | F15: 250000 | G15: 0 | I15: 250000 | J15: 0 | K15: 0 | L15: 0 | M15: 250000 | N15: 250000 | O15: 250000 | P15: 250000 | Q15: 250000
A16: =A7 -> VP Operations (WS) | B16: i | C16: bonus | D16: ws | F16: 115000 | G16: 0 | I16: 115000 | J16: 0 | K16: 0 | L16: 0 | M16: 75000 | N16: 75000 | O16: 75000 | P16: 75000 | Q16: 75000
A17: =A8 -> seniorS&Mexe (CL) | B17: i | C17: bonus | D17: cl | F17: 20000 | G17: 0 | I17: 20000 | J17: 0 | K17: 0 | L17: 0 | M17: 75000 | N17: 75000 | O17: 75000 | P17: 75000 | Q17: 75000
A18: =A9 -> Senior Associate (RF) | B18: i | C18: bonus | D18: rf | F18: 50000 | G18: 0 | I18: 50000 | J18: 0 | K18: 0 | L18: 0 | M18: 50000 | N18: 50000 | O18: 50000 | P18: 50000 | Q18: 50000
A19: =A10 -> associate (MT) | B19: i | C19: bonus | D19: mt | F19: 20000 | G19: 0 | I19: 20000 | J19: 0 | K19: 0 | L19: 0 | M19: 40000 | N19: 40000 | O19: 40000 | P19: 40000 | Q19: 40000
A20: =A11 -> project manager | B20: i | C20: bonus | D20: project | F20: 0 | G20: 0 | I20: 0 | J20: 0 | K20: 0 | L20: 0 | M20: 5000 | N20: 5000 | O20: 5000 | P20: 5000 | Q20: 5000
A21: Total | F21: 455000 | G21: 0 | I21: 455000 | J21: =SUM(J15:J20) -> 0 | K21: =SUM(K15:K20) -> 0 | L21: =SUM(L15:L20) -> 0 | M21: =SUM(M15:M20) -> 495000 | N21: =SUM(N15:N20) -> 495000 | O21: =SUM(O15:O20) -> 495000 | P21: =SUM(P15:P20) -> 495000 | Q21: =SUM(Q15:Q20) -> 495000
A23: Total Salaries
A24: =A15 -> ACEO Loren Hotels (CE) | B24: c | C24: total_salary | D24: ce | F24: 403750 | G24: 144000 | I24: 403750 | J24: =J6*(1+'.c12_inputs.hr'!$E$8)+(J15*(1+'.c12_inputs.hr'!$E$9)) -> 144000 | K24: =K6*(1+'.c12_inputs.hr'!$E$8)+(K15*(1+'.c12_inputs.hr'!$E$9)) -> 144000 | L24: =L6*(1+'.c12_inputs.hr'!$E$8)+(L15*(1+'.c12_inputs.hr'!$E$9)) -> 144000 | M24: =M6*(1+'.c12_inputs.hr'!$E$8)+(M15*(1+'.c12_inputs.hr'!$E$9)) -> 403750 | N24: =N6*(1+'.c12_inputs.hr'!$E$8)+(N15*(1+'.c12_inputs.hr'!$E$9)) -> 403750 | O24: =O6*(1+'.c12_inputs.hr'!$E$8)+(O15*(1+'.c12_inputs.hr'!$E$9)) -> 403750 | P24: =P6*(1+'.c12_inputs.hr'!$E$8)+(P15*(1+'.c12_inputs.hr'!$E$9)) -> 403750 | Q24: =Q6*(1+'.c12_inputs.hr'!$E$8)+(Q15*(1+'.c12_inputs.hr'!$E$9)) -> 403750
A25: =A16 -> VP Operations (WS) | B25: c | C25: total_salary | D25: ws | F25: 198685 | G25: 83520 | I25: 198685 | J25: =J7*(1+'.c12_inputs.hr'!$E$8)+(J16*(1+'.c12_inputs.hr'!$E$9)) -> 83520 | K25: =K7*(1+'.c12_inputs.hr'!$E$8)+(K16*(1+'.c12_inputs.hr'!$E$9)) -> 83520 | L25: =L7*(1+'.c12_inputs.hr'!$E$8)+(L16*(1+'.c12_inputs.hr'!$E$9)) -> 83520 | M25: =M7*(1+'.c12_inputs.hr'!$E$8)+(M16*(1+'.c12_inputs.hr'!$E$9)) -> 161445 | N25: =N7*(1+'.c12_inputs.hr'!$E$8)+(N16*(1+'.c12_inputs.hr'!$E$9)) -> 161445 | O25: =O7*(1+'.c12_inputs.hr'!$E$8)+(O16*(1+'.c12_inputs.hr'!$E$9)) -> 161445 | P25: =P7*(1+'.c12_inputs.hr'!$E$8)+(P16*(1+'.c12_inputs.hr'!$E$9)) -> 161445 | Q25: =Q7*(1+'.c12_inputs.hr'!$E$8)+(Q16*(1+'.c12_inputs.hr'!$E$9)) -> 161445
A26: =A17 -> seniorS&Mexe (CL) | B26: c | C26: total_salary | D26: cl | F26: 20780 | G26: 86400 | I26: 20780 | J26: =J8*(1+'.c12_inputs.hr'!$E$8)+(J17*(1+'.c12_inputs.hr'!$E$9)) -> 86400 | K26: =K8*(1+'.c12_inputs.hr'!$E$8)+(K17*(1+'.c12_inputs.hr'!$E$9)) -> 86400 | L26: =L8*(1+'.c12_inputs.hr'!$E$8)+(L17*(1+'.c12_inputs.hr'!$E$9)) -> 86400 | M26: =M8*(1+'.c12_inputs.hr'!$E$8)+(M17*(1+'.c12_inputs.hr'!$E$9)) -> 164325 | N26: =N8*(1+'.c12_inputs.hr'!$E$8)+(N17*(1+'.c12_inputs.hr'!$E$9)) -> 164325 | O26: =O8*(1+'.c12_inputs.hr'!$E$8)+(O17*(1+'.c12_inputs.hr'!$E$9)) -> 164325 | P26: =P8*(1+'.c12_inputs.hr'!$E$8)+(P17*(1+'.c12_inputs.hr'!$E$9)) -> 164325 | Q26: =Q8*(1+'.c12_inputs.hr'!$E$8)+(Q17*(1+'.c12_inputs.hr'!$E$9)) -> 164325
A27: =A18 -> Senior Associate (RF) | B27: c | C27: total_salary | D27: rf | F27: 95150 | G27: 46080 | I27: 95150 | J27: =J9*(1+'.c12_inputs.hr'!$E$8)+(J18*(1+'.c12_inputs.hr'!$E$9)) -> 46080 | K27: =K9*(1+'.c12_inputs.hr'!$E$8)+(K18*(1+'.c12_inputs.hr'!$E$9)) -> 46080 | L27: =L9*(1+'.c12_inputs.hr'!$E$8)+(L18*(1+'.c12_inputs.hr'!$E$9)) -> 46080 | M27: =M9*(1+'.c12_inputs.hr'!$E$8)+(M18*(1+'.c12_inputs.hr'!$E$9)) -> 98030 | N27: =N9*(1+'.c12_inputs.hr'!$E$8)+(N18*(1+'.c12_inputs.hr'!$E$9)) -> 98030 | O27: =O9*(1+'.c12_inputs.hr'!$E$8)+(O18*(1+'.c12_inputs.hr'!$E$9)) -> 98030 | P27: =P9*(1+'.c12_inputs.hr'!$E$8)+(P18*(1+'.c12_inputs.hr'!$E$9)) -> 98030 | Q27: =Q9*(1+'.c12_inputs.hr'!$E$8)+(Q18*(1+'.c12_inputs.hr'!$E$9)) -> 98030
A28: =A19 -> associate (MT) | B28: c | C28: total_salary | D28: mt | F28: 52460 | G28: 31680 | I28: 52460 | J28: =J10*(1+'.c12_inputs.hr'!$E$8)+(J19*(1+'.c12_inputs.hr'!$E$9)) -> 31680 | K28: =K10*(1+'.c12_inputs.hr'!$E$8)+(K19*(1+'.c12_inputs.hr'!$E$9)) -> 31680 | L28: =L10*(1+'.c12_inputs.hr'!$E$8)+(L19*(1+'.c12_inputs.hr'!$E$9)) -> 31680 | M28: =M10*(1+'.c12_inputs.hr'!$E$8)+(M19*(1+'.c12_inputs.hr'!$E$9)) -> 73240 | N28: =N10*(1+'.c12_inputs.hr'!$E$8)+(N19*(1+'.c12_inputs.hr'!$E$9)) -> 73240 | O28: =O10*(1+'.c12_inputs.hr'!$E$8)+(O19*(1+'.c12_inputs.hr'!$E$9)) -> 73240 | P28: =P10*(1+'.c12_inputs.hr'!$E$8)+(P19*(1+'.c12_inputs.hr'!$E$9)) -> 73240 | Q28: =Q10*(1+'.c12_inputs.hr'!$E$8)+(Q19*(1+'.c12_inputs.hr'!$E$9)) -> 73240
A29: =A20 -> project manager | B29: c | C29: total_salary | D29: project | F29: 0 | G29: 0 | I29: 0 | J29: =J11*(1+'.c12_inputs.hr'!$E$8)+(J20*(1+'.c12_inputs.hr'!$E$9)) -> 0 | K29: =K11*(1+'.c12_inputs.hr'!$E$8)+(K20*(1+'.c12_inputs.hr'!$E$9)) -> 0 | L29: =L11*(1+'.c12_inputs.hr'!$E$8)+(L20*(1+'.c12_inputs.hr'!$E$9)) -> 43200 | M29: =M11*(1+'.c12_inputs.hr'!$E$8)+(M20*(1+'.c12_inputs.hr'!$E$9)) -> 48395 | N29: =N11*(1+'.c12_inputs.hr'!$E$8)+(N20*(1+'.c12_inputs.hr'!$E$9)) -> 48395 | O29: =O11*(1+'.c12_inputs.hr'!$E$8)+(O20*(1+'.c12_inputs.hr'!$E$9)) -> 48395 | P29: =P11*(1+'.c12_inputs.hr'!$E$8)+(P20*(1+'.c12_inputs.hr'!$E$9)) -> 48395 | Q29: =Q11*(1+'.c12_inputs.hr'!$E$8)+(Q20*(1+'.c12_inputs.hr'!$E$9)) -> 48395
A31: Grand Total | B31: o | C31: hr_grand_total | F31: 770825 | G31: 391680 | I31: 770825 | J31: =SUM(J24:J29) -> 391680 | K31: =SUM(K24:K29) -> 391680 | L31: =SUM(L24:L29) -> 434880 | M31: =SUM(M24:M29) -> 949185 | N31: =SUM(N24:N29) -> 949185 | O31: =SUM(O24:O29) -> 949185 | P31: =SUM(P24:P29) -> 949185 | Q31: =SUM(Q24:Q29) -> 949185
A32: reimbersable to hotel | B32: o | C32: hr_reimbursable | F32: 367075 | G32: 247680 | I32: 367075 | J32: =SUMPRODUCT('.c12_alloc'!$H$15:$H$20,'.c12_hm_hr'!J$24:J$29) -> 247680 | K32: =SUMPRODUCT('.c12_alloc'!$H$15:$H$20,'.c12_hm_hr'!K$24:K$29) -> 247680 | L32: =SUMPRODUCT('.c12_alloc'!$H$15:$H$20,'.c12_hm_hr'!L$24:L$29) -> 290880 | M32: =SUMPRODUCT('.c12_alloc'!$H$15:$H$20,'.c12_hm_hr'!M$24:M$29) -> 545435 | N32: =SUMPRODUCT('.c12_alloc'!$H$15:$H$20,'.c12_hm_hr'!N$24:N$29) -> 545435 | O32: =SUMPRODUCT('.c12_alloc'!$H$15:$H$20,'.c12_hm_hr'!O$24:O$29) -> 545435 | P32: =SUMPRODUCT('.c12_alloc'!$H$15:$H$20,'.c12_hm_hr'!P$24:P$29) -> 545435 | Q32: =SUMPRODUCT('.c12_alloc'!$H$15:$H$20,'.c12_hm_hr'!Q$24:Q$29) -> 545435
A33: not reimbersable by hotel, but paid by lgh | B33: o | C33: hr_not_reimbursable | F33: 403750 | G33: 144000 | I33: 403750 | J33: =SUMPRODUCT('.c12_alloc'!$G$15:$G$20,'.c12_hm_hr'!J$24:J$29) -> 144000 | K33: =SUMPRODUCT('.c12_alloc'!$G$15:$G$20,'.c12_hm_hr'!K$24:K$29) -> 144000 | L33: =SUMPRODUCT('.c12_alloc'!$G$15:$G$20,'.c12_hm_hr'!L$24:L$29) -> 144000 | M33: =SUMPRODUCT('.c12_alloc'!$G$15:$G$20,'.c12_hm_hr'!M$24:M$29) -> 403750 | N33: =SUMPRODUCT('.c12_alloc'!$G$15:$G$20,'.c12_hm_hr'!N$24:N$29) -> 403750 | O33: =SUMPRODUCT('.c12_alloc'!$G$15:$G$20,'.c12_hm_hr'!O$24:O$29) -> 403750 | P33: =SUMPRODUCT('.c12_alloc'!$G$15:$G$20,'.c12_hm_hr'!P$24:P$29) -> 403750 | Q33: =SUMPRODUCT('.c12_alloc'!$G$15:$G$20,'.c12_hm_hr'!Q$24:Q$29) -> 403750
A34: only paid by c12 | B34: o | C34: hr_only_c12 | F34: 0 | G34: 0 | I34: 0 | J34: =SUMPRODUCT('.c12_alloc'!$E$15:$E$20,'.c12_hm_hr'!J$24:J$29) -> 0 | K34: =SUMPRODUCT('.c12_alloc'!$E$15:$E$20,'.c12_hm_hr'!K$24:K$29) -> 0 | L34: =SUMPRODUCT('.c12_alloc'!$E$15:$E$20,'.c12_hm_hr'!L$24:L$29) -> 0 | M34: =SUMPRODUCT('.c12_alloc'!$E$15:$E$20,'.c12_hm_hr'!M$24:M$29) -> 0 | N34: =SUMPRODUCT('.c12_alloc'!$E$15:$E$20,'.c12_hm_hr'!N$24:N$29) -> 0 | O34: =SUMPRODUCT('.c12_alloc'!$E$15:$E$20,'.c12_hm_hr'!O$24:O$29) -> 0 | P34: =SUMPRODUCT('.c12_alloc'!$E$15:$E$20,'.c12_hm_hr'!P$24:P$29) -> 0 | Q34: =SUMPRODUCT('.c12_alloc'!$E$15:$E$20,'.c12_hm_hr'!Q$24:Q$29) -> 0

Sheet .c12_d&s_hr
A2: Year | E2: 45657 | F2: 46022 | G2: 46112 | H2: 46203 | I2: 46022 | J2: 46112 | K2: 46203 | L2: 46295 | M2: 46387 | N2: 46477 | O2: 46568 | P2: 46660 | Q2: 46752
E3: actual | I3: i/o
B4: i/o | C4: field_name | D4: index
A5: base
A6: HODS (RB) | B6: i | C6: base_salary | D6: rb | F6: 87500 | G6: 187500 | I6: 87500 | J6: 187500 | K6: 187500 | L6: 187500 | M6: 187500 | N6: 187500 | O6: 187500 | P6: 187500 | Q6: 187500
A7: Project Executive (LS) (100%) | B7: i | C7: base_salary | D7: ls | F7: 46250 | G7: 46250 | I7: 46250 | J7: 46250 | K7: 46250 | L7: 46250 | M7: 46250 | N7: 46250 | O7: 46250 | P7: 46250 | Q7: 46250
A8: Project Manager (BD) (100%) | B8: i | C8: base_salary | D8: bd | F8: 27500 | G8: 28125 | I8: 27500 | J8: 28125 | K8: 28125 | L8: 28125 | M8: 28125 | N8: 28125 | O8: 28125 | P8: 28125 | Q8: 28125
A9: Counsel (KT) | B9: i | C9: base_salary | D9: kt | F9: 62500 | G9: 65000 | I9: 62500 | J9: 65000 | K9: 65000 | L9: 65000 | M9: 65000 | N9: 65000 | O9: 65000 | P9: 65000 | Q9: 65000
A10: Development Manager??? (alexi?) | B10: i | C10: base_salary | D10: development | F10: 0 | G10: 0 | I10: 0 | J10: 0 | K10: 0 | L10: 0 | M10: 0 | N10: 0 | O10: 0 | P10: 0 | Q10: 0
A11: Banker (tBD) | B11: i | C11: base_salary | D11: banker | F11: 75000 | G11: 0 | I11: 75000 | J11: 0 | K11: 0 | L11: 0 | M11: 0 | N11: 0 | O11: 0 | P11: 0 | Q11: 0
A12: Senior Design Manager (AM) | B12: i | C12: base_salary | D12: am | F12: 45000 | G12: 47500 | I12: 45000 | J12: 47500 | K12: 47500 | L12: 47500 | M12: 47500 | N12: 47500 | O12: 47500 | P12: 47500 | Q12: 47500
A13: Design Manager (AL) (gone) | B13: i | C13: base_salary | D13: al | F13: 32500 | G13: 34375 | I13: 32500 | J13: 34375 | K13: 0 | L13: 0 | M13: 0 | N13: 0 | O13: 0 | P13: 0 | Q13: 0
A14: new design manager (TBD) | B14: i | C14: base_salary | D14: tbd | F14: 0 | G14: 0 | I14: 0 | J14: 0 | K14: 0 | L14: 34375 | M14: 34375 | N14: 34375 | O14: 34375 | P14: 34375 | Q14: 34375
A15: FF&E (SB) | B15: i | C15: base_salary | D15: sb | F15: 27500 | G15: 27500 | I15: 27500 | J15: 27500 | K15: 27500 | L15: 27500 | M15: 27500 | N15: 27500 | O15: 27500 | P15: 27500 | Q15: 27500
A16: Senior Financial Analyst (KS) | B16: i | C16: base_salary | D16: ks | G16: 50000 | I16: 0 | J16: 50000 | K16: 50000 | L16: 50000 | M16: 50000 | N16: 50000 | O16: 50000 | P16: 50000 | Q16: 50000
A17: Total | F17: 403750 | G17: 486250 | I17: 403750 | J17: =SUM(J6:J16) -> 486250 | K17: =SUM(K6:K16) -> 451875 | L17: =SUM(L6:L16) -> 486250 | M17: =SUM(M6:M16) -> 486250 | N17: =SUM(N6:N16) -> 486250 | O17: =SUM(O6:O16) -> 486250 | P17: =SUM(P6:P16) -> 486250 | Q17: =SUM(Q6:Q16) -> 486250
A19: Bonus
A20: =+A6 -> HODS (RB) | B20: i | C20: bonus | D20: rb | F20: 685000 | G20: 0 | I20: 685000 | J20: 0 | K20: 0 | L20: 0 | M20: 250000 | N20: 250000 | O20: 250000 | P20: 250000 | Q20: 250000
A21: =+A7 -> Project Executive (LS) (100%) | B21: i | C21: bonus | D21: ls | F21: 20000 | G21: 0 | I21: 20000 | J21: 0 | K21: 0 | L21: 0 | M21: 15000 | N21: 15000 | O21: 15000 | P21: 15000 | Q21: 15000
A22: =+A8 -> Project Manager (BD) (100%) | B22: i | C22: bonus | D22: bd | F22: 17500 | G22: 0 | I22: 17500 | J22: 0 | K22: 0 | L22: 0 | M22: 15000 | N22: 15000 | O22: 15000 | P22: 15000 | Q22: 15000
A23: =+A9 -> Counsel (KT) | B23: i | C23: bonus | D23: kt | F23: 230000 | G23: 0 | I23: 230000 | J23: 0 | K23: 0 | L23: 0 | M23: 125000 | N23: 125000 | O23: 125000 | P23: 125000 | Q23: 125000
A24: =+A10 -> Development Manager??? (alexi?) | B24: i | C24: bonus | D24: development | F24: 0 | G24: 0 | I24: 0 | J24: 0 | K24: 0 | L24: 0 | M24: 0 | N24: 0 | O24: 0 | P24: 0 | Q24: 0
A25: =+A11 -> Banker (tBD) | B25: i | C25: bonus | D25: banker | F25: 50000 | G25: 0 | I25: 50000 | J25: 0 | K25: 0 | L25: 0 | M25: 100000 | N25: 100000 | O25: 100000 | P25: 100000 | Q25: 100000
A26: =+A12 -> Senior Design Manager (AM) | B26: i | C26: bonus | D26: am | F26: 65000 | G26: 0 | I26: 65000 | J26: 0 | K26: 0 | L26: 0 | M26: 55000 | N26: 55000 | O26: 55000 | P26: 55000 | Q26: 55000
A27: =+A13 -> Design Manager (AL) (gone) | B27: i | C27: bonus | D27: al | F27: 25000 | G27: 0 | I27: 25000 | J27: 0 | K27: 0 | L27: 0 | M27: 0 | N27: 0 | O27: 0 | P27: 0 | Q27: 0
A28: =+A14 -> new design manager (TBD) | B28: i | C28: bonus | D28: tbd | F28: 0 | G28: 0 | I28: 0 | J28: 0 | K28: 0 | L28: 0 | M28: 11250 | N28: 11250 | O28: 11250 | P28: 11250 | Q28: 11250
A29: =+A15 -> FF&E (SB) | B29: i | C29: bonus | D29: sb | F29: 0 | G29: 0 | I29: 0 | J29: 0 | K29: 0 | L29: 0 | M29: 15000 | N29: 15000 | O29: 15000 | P29: 15000 | Q29: 15000
A30: =+A16 -> Senior Financial Analyst (KS) | B30: i | C30: bonus | D30: ks | F30: 50000 | I30: 50000 | M30: 50000 | N30: 50000 | O30: 50000 | P30: 50000 | Q30: 50000
A31: Total | F31: 1142500 | G31: 0 | I31: 1142500 | J31: 0 | K31: 0 | L31: 0 | M31: 897500 | N31: 897500 | O31: 897500 | P31: 897500 | Q31: 897500
A33: Total Salaries
