Workbook
Name DepartmentNum: '.c12_inputs.hr'!$E$4

Sheet registry
A1: Year | E1: 45657 | F1: 45747 | G1: 45838 | H1: 45930 | I1: 46022 | J1: 46112 | K1: 46203 | L1: 45747 | M1: 45838 | N1: 45930 | O1: 46022 | P1: 46112 | Q1: 46203 | R1: 46295 | S1: 46387
E2: actual | L2: i/o
T3: io | U3: field | V3: index | W3: src_row | X3: src_page
A5: [not sourced from c12]
A6: [not sourced from c12]
A7: [not sourced from c12]
A10: [not sourced from c12]
A11: [not sourced from c12]
A12: [not sourced from c12]
A13: [not sourced from c12]
A14: [not sourced from c12]
A15: [not sourced from c12]
A16: [not sourced from c12]
A17: [not sourced from c12]
A18: [not sourced from c12]
... A43: [not sourced from c12]
A46: Total LGH HM Fees | E46: =+'c12_hm'!E60 -> 0 | F46: =+'c12_hm'!F60 -> 0 | G46: =+'c12_hm'!G60 -> 0 | H46: =+'c12_hm'!H60 -> 0 | I46: =+'c12_hm'!I60 -> 447597 | J46: =+'c12_hm'!J60 -> 310715.79 | K46: =+'c12_hm'!K60 -> 0 | L46: =+'c12_hm'!L60 -> 558947 | ... S46: =+'c12_hm'!S60 -> 2385063.6 | T46: o | U46: total_lgh_hm_revenue | W46: 60 | X46: c12_hm
A47: c12 Participation | E47: =+'c12_hm'!E70 -> 0 | F47: =+'c12_hm'!F70 -> 0 | G47: =+'c12_hm'!G70 -> 0 | H47: =+'c12_hm'!H70 -> 0 | I47: =+'c12_hm'!I70 -> 447597 | J47: =+'c12_hm'!J70 -> 63035.789 | K47: =+'c12_hm'!K70 -> 0 | L47: =+'c12_hm'!L70 -> 558947 | ... S47: =+'c12_hm'!S70 -> 662529.63 | T47: o | U47: total_c12_hm_revenue | W47: 70 | X47: c12_hm
A49: [not sourced from c12]
A50: [not sourced from c12]
A51: [not sourced from c12]
A55: Total LGH D&s Fees | E55: ='c12_d&s'!E60 -> 0 | F55: ='c12_d&s'!F60 -> 0 | G55: ='c12_d&s'!G60 -> 0 | H55: ='c12_d&s'!H60 -> 0 | I55: ='c12_d&s'!I60 -> 911235.5 | J55: ='c12_d&s'!J60 -> 1735259.1 | K55: ='c12_d&s'!K60 -> 0 | L55: ='c12_d&s'!L60 -> 128735.5 | ... S55: ='c12_d&s'!S60 -> 5828630.3 | T55: o | U55: total_lgh_ds_revenue | W55: 60 | X55: c12_d&s
A56: c12 D&s Participation | E56: ='c12_d&s'!E70 -> 0 | F56: ='c12_d&s'!F70 -> 0 | G56: ='c12_d&s'!G70 -> 0 | H56: ='c12_d&s'!H70 -> 0 | I56: ='c12_d&s'!I70 -> 455617.75 | J56: ='c12_d&s'!J70 -> 806580.95 | K56: ='c12_d&s'!K70 -> 0 | L56: ='c12_d&s'!L70 -> 64367.75 | ... S56: ='c12_d&s'!S70 -> 2208920.6 | T56: o | U56: total_c12_ds_revenue | W56: 70 | X56: c12_d&s
A58: total c12 participation | E58: ='c12_oc'!E10 -> 2452451 | F58: ='c12_oc'!F10 -> 0 | G58: ='c12_oc'!G10 -> 0 | H58: ='c12_oc'!H10 -> 0 | I58: ='c12_oc'!I10 -> 0 | J58: ='c12_oc'!J10 -> 0 | K58: ='c12_oc'!K10 -> 0 | L58: ='c12_oc'!L10 -> 623314.75 | ... S58: ='c12_oc'!S10 -> 2898497.4 | T58: o | U58: total_participation_revenue_actual | W58: 10 | X58: c12_oc
A59: total lgh revenue | E59: ='c12_oc'!E87 -> 0 | F59: ='c12_oc'!F87 -> 0 | G59: ='c12_oc'!G87 -> 0 | H59: ='c12_oc'!H87 -> 0 | I59: ='c12_oc'!I87 -> 0 | J59: ='c12_oc'!J87 -> 0 | K59: ='c12_oc'!K87 -> 0 | L59: ='c12_oc'!L87 -> 687682.5 | ... S59: ='c12_oc'!S87 -> 8574636 | T59: o | U59: total_lgh_revenue | W59: 87 | X59: c12_oc
A60: art leases | E60: ='c12_sk'!E7 -> 0 | F60: ='c12_sk'!F7 -> 0 | G60: ='c12_sk'!G7 -> 0 | H60: ='c12_sk'!H7 -> 0 | I60: ='c12_sk'!I7 -> 0 | J60: ='c12_sk'!J7 -> 0 | K60: ='c12_sk'!K7 -> 0 | L60: ='c12_sk'!L7 -> 0 | ... S60: ='c12_sk'!S7 -> 50000 | T60: i | U60: lease_payments | V60: sk | W60: 7 | X60: c12_sk
A62: [not sourced from c12]
A63: [not sourced from c12]
A66: [not sourced from c12]
A67: [not sourced from c12]
A68: [not sourced from c12]
A71: [not sourced from c12]
A72: [not sourced from c12]
A73: [not sourced from c12]
A77: [not sourced from c12]
A78: [not sourced from c12]
A79: [not sourced from c12]
A82: [not sourced from c12]
A83: guarantee payments | E83: ='c12_sk'!E8 -> 0 | F83: ='c12_sk'!F8 -> 0 | G83: ='c12_sk'!G8 -> 0 | H83: ='c12_sk'!H8 -> 0 | I83: ='c12_sk'!I8 -> 0 | J83: ='c12_sk'!J8 -> 0 | K83: ='c12_sk'!K8 -> 0 | L83: ='c12_sk'!L8 -> -250000 | ... S83: ='c12_sk'!S8 -> -250000 | T83: i | U83: guarantee_fees | V83: sk | W83: 8 | X83: c12_sk
A86: [not sourced from c12]
...

Sheet c12_inputs
A2: Year
A3: Period
B4: i/o | C4: field_name | D4: index
A5: cost inflation | B5: i | C5: cost_inflation_rate_actual | E5: 0.03
A7: Charge Back Percentage | B7: i | C7: chargeback_pct_actual | E7: 0.05
A8: participation% | B8: i | C8: participation_pct_actual | E8: 0.35
A11: actual thru | B11: i | C11: actuals_thru | E11: 46112
A12: projections from | B12: i | C12: projections_from | E12: 46203
A13: projections to | B13: i | C13: projections_to | E13: 46387

Sheet c12_oc
A2: Year | E2: 45657 | F2: 45747 | G2: 45838 | H2: 45930 | I2: 46022 | J2: 46112 | K2: 46203 | L2: 45747 | M2: 45838 | N2: 45930 | O2: 46022 | P2: 46112 | Q2: 46203 | R2: 46295 | S2: 46387
E3: actual | L3: i/o
B4: i/o | C4: field_name | D4: index
A5: C12 Participation Revenue (not c/b reimb)
A6: HM Fees | L6: ='c12_hm'!L70 -> 558947 | M6: ='c12_hm'!M70 -> 558947 | N6: ='c12_hm'!N70 -> 558947 | O6: ='c12_hm'!O70 -> 447597 | P6: ='c12_hm'!P70 -> 63035.789 | Q6: ='c12_hm'!Q70 -> 398173.65 | R6: ='c12_hm'!R70 -> 400447.34 | S6: ='c12_hm'!S70 -> 662529.63
A7: BI&F Fees | L7: ='c12_bi&F'!L70 -> 0 | M7: ='c12_bi&F'!M70 -> 0 | N7: ='c12_bi&F'!N70 -> 0 | O7: ='c12_bi&F'!O70 -> 0 | P7: ='c12_bi&F'!P70 -> 16714.737 | Q7: ='c12_bi&F'!Q70 -> 16714.737 | R7: ='c12_bi&F'!R70 -> 22398.947 | S7: ='c12_bi&F'!S70 -> 27047.105
A8: DS Fees | L8: ='c12_d&s'!L70 -> 64367.75 | M8: ='c12_d&s'!M70 -> 64367.75 | N8: ='c12_d&s'!N70 -> 349567.75 | O8: ='c12_d&s'!O70 -> 455617.75 | P8: ='c12_d&s'!P70 -> 806580.95 | Q8: ='c12_d&s'!Q70 -> 1015405.1 | R8: ='c12_d&s'!R70 -> 935314.59 | S8: ='c12_d&s'!S70 -> 2208920.6
A10: total participation revenue | B10: o | C10: total_participation_revenue_actual | E10: 2452451 | L10: =SUM(L6:L9) -> 623314.75 | M10: =SUM(M6:M9) -> 623314.75 | N10: =SUM(N6:N9) -> 908514.75 | O10: =SUM(O6:O9) -> 903214.75 | P10: =SUM(P6:P9) -> 886331.48 | Q10: =SUM(Q6:Q9) -> 1430293.5 | R10: =SUM(R6:R9) -> 1358160.9 | S10: =SUM(S6:S9) -> 2898497.4 | T10: revenues in nominal dollars
A12: Infrastructure | B12: i | C12: nonrecur_exp | D12: infrastructure | T12: this now two people in bi&f
A13: Professional services | B13: i | C13: nonrecur_exp | D13: professional_services | Q13: 100000 | R13: 100000
A14: Hiring Costs | B14: i | C14: nonrecur_exp | D14: hiring_costs | Q14: 100000
A15: signing bonuses | B15: i | C15: nonrecur_exp | D15: signing_bonus
A16: Restructuring | B16: i | C16: nonrecur_exp | D16: restructuring | P16: 0 | Q16: 0 | R16: 0 | S16: 0 | T16: put this in c12_oc_hr costs
A17: housing | B17: i | C17: nonrecur_exp | D17: housing | P17: 0 | Q17: 0 | R17: 0 | S17: 0 | T17: I think this is in oop cos paid by me
A18: Total | B18: c | C18: total_nonrecur_exp | L18: =SUM(L12:L17) -> 0 | M18: =SUM(M12:M17) -> 0 | N18: =SUM(N12:N17) -> 0 | O18: =SUM(O12:O17) -> 0 | P18: =SUM(P12:P17) -> 0 | Q18: =SUM(Q12:Q17) -> 200000 | R18: =SUM(R12:R17) -> 100000 | S18: =SUM(S12:S17) -> 0
A20: Reimbursable Operating Expenses (inc holtel) | L20: =-L39 -> 1637186 | M20: =-M39 -> 1733477 | N20: =-N39 -> 1694124 | O20: =-O39 -> 2917273 | P20: =-P39 -> 4057849.9 | Q20: =-Q39 -> 4457407 | R20: =-R39 -> 2834607 | S20: =-S39 -> 4930793.2
A22: revenue from lgh | L22: =L20+L10 -> 2260500.8 | M22: =M20+M10 -> 2356791.8 | N22: =N20+N10 -> 2602638.8 | O22: =O20+O10 -> 3820487.8 | P22: =P20+P10 -> 4944181.3 | Q22: =Q20+Q10 -> 5887700.5 | R22: =R20+R10 -> 4192767.9 | S22: =S20+S10 -> 7829290.6
A24: compensation
A25: Hotel Management | L25: =-('c12_hm'!L78+'c12_hm'!L79) -> -298080 | M25: =-('c12_hm'!M78+'c12_hm'!M79) -> -298080 | N25: =-('c12_hm'!N78+'c12_hm'!N79) -> -298080 | O25: =-('c12_hm'!O78+'c12_hm'!O79) -> -770825 | P25: =-('c12_hm'!P78+'c12_hm'!P79) -> -391680 | Q25: =-('c12_hm'!Q78+'c12_hm'!Q79) -> -391680 | R25: =-('c12_hm'!R78+'c12_hm'!R79) -> -434880 | S25: =-('c12_hm'!S78+'c12_hm'!S79) -> -949185
A26: Business Infrastructure & Finance | L26: =-('c12_bi&F'!L78+'c12_bi&F'!L79) -> -250560 | M26: =-('c12_bi&F'!M78+'c12_bi&F'!M79) -> -250560 | N26: =-('c12_bi&F'!N78+'c12_bi&F'!N79) -> -336960 | O26: =-('c12_bi&F'!O78+'c12_bi&F'!O79) -> -602497.5 | P26: =-('c12_bi&F'!P78+'c12_bi&F'!P79) -> -296640 | Q26: =-('c12_bi&F'!Q78+'c12_bi&F'!Q79) -> -477677.14 | R26: =-('c12_bi&F'!R78+'c12_bi&F'!R79) -> -672077.14 | S26: =-('c12_bi&F'!S78+'c12_bi&F'!S79) -> -1173394.6
A27: Development & Structuring | L27: =-('c12_d&s'!L78+'c12_d&s'!L79) -> -515520 | M27: =-('c12_d&s'!M78+'c12_d&s'!M79) -> -515520 | N27: =-('c12_d&s'!N78+'c12_d&s'!N79) -> -515520 | O27: =-('c12_d&s'!O78+'c12_d&s'!O79) -> -1652177.5 | P27: =-('c12_d&s'!P78+'c12_d&s'!P79) -> -560160 | Q27: =-('c12_d&s'!Q78+'c12_d&s'!Q79) -> -520560 | R27: =-('c12_d&s'!R78+'c12_d&s'!R79) -> -560160 | S27: =-('c12_d&s'!S78+'c12_d&s'!S79) -> -1221223.8
A28: C12 headoffice | L28: =-(L78-L81) -> -472542.86 | M28: =-(M78-M81) -> -472542.86 | N28: =-(N78-N81) -> -472542.86 | O28: =-(O78-O81) -> -472542.86 | P28: =-(P78-P81) -> -805022.86 | Q28: =-(Q78-Q81) -> -383142.86 | R28: =-(R78-R81) -> -383142.86 | S28: =-(S78-S81) -> -902642.86 | T28: this was double counting sk, deleted 1.5m
A29: Head office expenses
A30: office costs (rent & reoccuring) | B30: i | C30: ho_exp | D30: office_costs | L30: =-189940/4 -> -47485 | M30: =-189940/4 -> -47485 | N30: =-189940/4 -> -47485 | O30: =-189940/4 -> -47485 | P30: =-540000/4 -> -135000 | Q30: =-540000/4 -> -135000 | R30: =-540000/4 -> -135000 | S30: =-540000/4 -> -135000 | T30: is this updated?
A31: Departmental OOP paid via sk | L31: ='c12_sk'!L6 -> -112553 | M31: ='c12_sk'!M6 -> -186705 | N31: ='c12_sk'!N6 -> -148699 | O31: ='c12_sk'!O6 -> -249431 | P31: ='c12_sk'!P6 -> -174347 | Q31: ='c12_sk'!Q6 -> -174347 | R31: ='c12_sk'!R6 -> -174347 | S31: ='c12_sk'!S6 -> -174347 | T31: should come from danielle
A32: Departmental OOP not paid via sk | B32: i | C32: ho_exp | D32: oop_notsk | P32: -75000 | Q32: -75000 | R32: -75000 | S32: -75000 | T32: added mastercard cos not all paid by sk
A33: Non-recurring Items paid by LGH | B33: i | C33: ho_exp | D33: nonrecur_lgh | L33: =-L18 -> 0 | M33: =-M18 -> 0 | N33: =-N18 -> 0 | O33: =-O18 -> 0 | P33: =-P18 -> 0 | Q33: =-Q18 -> -200000 | R33: =-R18 -> -100000 | S33: =-S18 -> 0
A34: C12 Accounts Payable | B34: i | C34: ho_exp | D34: accounts_payable | N34: -45000 | O34: -599728 | P34: -1620000 | Q34: -2100000 | R34: -300000 | S34: -300000 | T34: WHAT IS THIS? Not double counting?
A35: inflation multiplier | B35: i | C35: inflation_multiplier | L35: 1 | M35: 1 | N35: 1 | O35: 1 | P35: 1 | Q35: 1 | R35: 1 | S35: 1
A36: Inflation | B36: c | C36: inflation | L36: =(L35-1)*SUM(L25:L34) -> 0 | M36: =(M35-1)*SUM(M25:M34) -> 0 | N36: =(N35-1)*SUM(N25:N34) -> 0 | O36: =(O35-1)*SUM(O25:O34) -> 0 | P36: =(P35-1)*SUM(P25:P34) -> 0 | Q36: =(Q35-1)*SUM(Q25:Q34) -> 0 | R36: =(R35-1)*SUM(R25:R34) -> 0 | S36: =(S35-1)*SUM(S25:S34) -> 0 | T36: revs in nominal dollars cos business forecast nominal, but personnel costs real
A37: Compensation - total | B37: o | C37: compensation_total | E37: -3970569 | F37: -1102148 | G37: -1124287 | H37: -1077940 | I37: -1645629 | L37: =IF(AND((F37<>""),(L$2<46204)),(F37),SUM(L25:L28)) -> -1102148 | M37: =IF(AND((G37<>""),(M$2<46204)),(G37),SUM(M25:M28)) -> -1124287 | N37: =IF(AND((H37<>""),(N$2<46204)),(H37),SUM(N25:N28)) -> -1077940 | O37: =IF(AND((I37<>""),(O$2<46204)),(I37),SUM(O25:O28)) -> -1645629 | P37: =IF(AND((J37<>""),(P$2<46204)),(J37),SUM(P25:P28)) -> -2053502.9 | Q37: =IF(AND((K37<>""),(Q$2<46204)),(K37),SUM(Q25:Q28)) -> -1773060 | R37: =IF(AND((L37<>""),(R$2<46204)),(L37),SUM(R25:R28)) -> -2050260 | S37: =IF(AND((M37<>""),(S$2<46204)),(M37),SUM(S25:S28)) -> -4246446.2
A38: Direct compensation not via trinet | B38: i | C38: compensation_direct | F38: -375000 | G38: -375000 | H38: -375000 | I38: -375000 | L38: =IF(AND((F38<>""),(L$2<46204)),(F38),0) -> -375000 | M38: =IF(AND((G38<>""),(M$2<46204)),(G38),0) -> -375000 | N38: =IF(AND((H38<>""),(N$2<46204)),(H38),0) -> -375000 | O38: =IF(AND((I38<>""),(O$2<46204)),(I38),0) -> -375000 | P38: =IF(AND((J38<>""),(P$2<46204)),(J38),0) -> 0 | Q38: =IF(AND((K38<>""),(Q$2<46204)),(K38),0) -> 0 | R38: =IF(AND((L38<>""),(R$2<46204)),(L38),0) -> 0 | S38: =IF(AND((M38<>""),(S$2<46204)),(M38),0) -> 0
A39: Total c12 Expenses paid by LGH | B39: o | C39: total_c12_exp_lgh_actual | E39: -5450569 | L39: =SUM(L30:L34,L36,L37:L38) -> -1637186 | M39: =SUM(M30:M34,M36,M37:M38) -> -1733477 | N39: =SUM(N30:N34,N36,N37:N38) -> -1694124 | O39: =SUM(O30:O34,O36,O37:O38) -> -2917273 | P39: =SUM(P30:P34,P36,P37:P38) -> -4057849.9 | Q39: =SUM(Q30:Q34,Q36,Q37:Q38) -> -4457407 | R39: =SUM(R30:R34,R36,R37:R38) -> -2834607 | S39: =SUM(S30:S34,S36,S37:S38) -> -4930793.2
A41: C12 H/O compensation not paid by lgh | L41: =-L81 -> -31928.571 | M41: =-M81 -> -31928.571 | N41: =-N81 -> -31928.571 | O41: =-O81 -> -42318.571 | P41: =-P81 -> -58237.714 | Q41: =-Q81 -> -58237.714 | R41: =-R81 -> -58237.714 | S41: =-S81 -> -79017.714
A42: Roots donation by c12 | B42: i | C42: roots_donation | S42: -200000
A43: Total c12 Expenses Not paid by lgh | B43: c | C43: total_c12_exp_not_lgh | L43: =SUM(L41:L42) -> -31928.571 | M43: =SUM(M41:M42) -> -31928.571 | N43: =SUM(N41:N42) -> -31928.571 | O43: =SUM(O41:O42) -> -42318.571 | P43: =SUM(P41:P42) -> -58237.714 | Q43: =SUM(Q41:Q42) -> -58237.714 | R43: =SUM(R41:R42) -> -58237.714 | S43: =SUM(S41:S42) -> -279017.71
A45: total costs | B45: c | C45: total_c12_costs | L45: =L43+L39 -> -1669114.6 | M45: =M43+M39 -> -1765405.6 | N45: =N43+N39 -> -1726052.6 | O45: =O43+O39 -> -2959591.6 | P45: =P43+P39 -> -4116087.6 | Q45: =Q43+Q39 -> -4515644.7 | R45: =R43+R39 -> -2892844.7 | S45: =S43+S39 -> -5209811
A47: Total C12 Profit | B47: o | C47: total_c12_profit_actual | E47: 3119951 | L47: =L22+L45 -> 591386.18 | M47: =M22+M45 -> 591386.18 | N47: =N22+N45 -> 876586.18 | O47: =O22+O45 -> 860896.18 | P47: =P22+P45 -> 828093.76 | Q47: =Q22+Q45 -> 1372055.8 | R47: =R22+R45 -> 1299923.2 | S47: =S22+S45 -> 2619479.6
A48: c12 profit margin | B48: c | C48: c12_profit_margin | L48: =L47/L22 -> 0.26161733 | M48: =M47/M22 -> 0.25092848 | N48: =N47/N22 -> 0.3368067 | O48: =O47/O22 -> 0.22533672 | P48: =P47/P22 -> 0.16748855 | Q48: =Q47/Q22 -> 0.23303763 | R48: =R47/R22 -> 0.31003938 | S48: =S47/S22 -> 0.33457433
A51: Bank transfers (actual or danielle)
...

Sheet c12_sk
A2: Year | E2: 45657 | F2: 45747 | G2: 45838 | H2: 45930 | I2: 46022 | J2: 46112 | K2: 46203 | L2: 45747 | M2: 45838 | N2: 45930 | O2: 46022 | P2: 46112 | Q2: 46203 | R2: 46295 | S2: 46387
E3: actual | L3: i/o
B4: i/o | C4: field_name | D4: index
A5: Bank transfers | B5: i | C5: bank_transfers | D5: sk | L5: =-7701527.99/4 -> -1925382 | M5: =L5 -> -1925382 | N5: =M5 -> -1925382 | O5: =N5 -> -1925382 | P5: =+P4 -> 0 | Q5: =+Q4 -> 0 | R5: =+R4 -> 0 | S5: =+S4 -> 0
A6: Departmental OOP paid via sk | B6: i | C6: ho_exp | D6: oop_sk | L6: -112553 | M6: -186705 | N6: -148699 | O6: -249431 | P6: -174347 | Q6: -174347 | R6: -174347 | S6: -174347 | T6: should come from danielle
A7: art lease payments to sk | B7: i | C7: lease_payments | D7: sk | E7: 0 | L7: 0 | M7: 0 | N7: 0 | O7: 0 | P7: 50000 | Q7: 50000 | R7: 50000 | S7: 50000
A8: guarantee fees to sk | B8: i | C8: guarantee_fees | D8: sk | E8: 0 | L8: -250000 | M8: -250000 | N8: -250000 | O8: -250000 | P8: -250000 | Q8: -250000 | R8: -250000 | S8: -250000
A9: cuda buy back | B9: i | C9: cuda_buyback | D9: sk | M9: -1200000

Sheet c12_bs
A2: Year | E2: 45657 | F2: 45747 | G2: 45838 | H2: 45930 | I2: 46022 | J2: 46112 | K2: 46203 | L2: 45747 | M2: 45838 | N2: 45930 | O2: 46022 | P2: 46112 | Q2: 46203 | R2: 46295 | S2: 46387
E3: actual | L3: i/o
B4: i/o | C4: field_name | D4: index
A5: assets
A6: cash open | E6: =0 -> 0 | I6: 9950 | J6: 9950 | L6: =E11 -> 9950 | M6: =L11 -> 9950 | N6: =M11 -> 9950 | O6: =N11 -> 9950 | P6: =O11 -> 9950 | Q6: =P11 -> 1303505.5 | R6: =Q11 -> 3524908.3 | S6: =R11 -> 5674178.4
A7: c12 profit | E7: ='c12_oc'!E47 -> 3119951 | I7: 860896.18 | J7: 828093.76 | L7: ='c12_oc'!L47 -> 591386.18 | M7: ='c12_oc'!M47 -> 591386.18 | N7: ='c12_oc'!N47 -> 876586.18 | O7: ='c12_oc'!O47 -> 860896.18 | P7: ='c12_oc'!P47 -> 828093.76 | Q7: ='c12_oc'!Q47 -> 1372055.8 | R7: ='c12_oc'!R47 -> 1299923.2 | S7: ='c12_oc'!S47 -> 2619479.6
A8: borrow from c12 loc | E8: =-'c12_oc'!E62 -> 1540999 | I8: -1009945.2 | J8: -383885.28 | L8: =-'c12_oc'!L62+'c12_oc'!E62+'c12_oc'!L61 -> 596442.82 | M8: =-'c12_oc'!M62+'c12_oc'!L62+'c12_oc'!M61 -> -677709.18 | N8: =-'c12_oc'!N62+'c12_oc'!M62+'c12_oc'!N61 -> 275096.82 | O8: =-'c12_oc'!O62+'c12_oc'!N62+'c12_oc'!O61 -> 190054.82 | P8: =-'c12_oc'!P62+'c12_oc'!O62+'c12_oc'!P61 -> -383885.28 | Q8: =-'c12_oc'!Q62+'c12_oc'!P62+'c12_oc'!Q61 -> 0 | R8: =-'c12_oc'!R62+'c12_oc'!Q62+'c12_oc'!R61 -> 0 | S8: =-'c12_oc'!S62+'c12_oc'!R62+'c12_oc'!S61 -> 0
A9: LGH to sk (from danielle) | E9: ='c12_oc'!E59 -> -4651000 | I9: 149049 | J9: 849347 | L9: ='c12_oc'!L59 -> -1187829 | M9: ='c12_oc'!M59 -> 86323.002 | N9: ='c12_oc'!N59 -> -1151683 | O9: ='c12_oc'!O59 -> -1050951 | P9: ='c12_oc'!P59 -> 849347 | Q9: ='c12_oc'!Q59 -> 849347 | R9: ='c12_oc'!R59 -> 849347 | S9: ='c12_oc'!S59 -> 849347
A10: c12 to sk (jp dist) | B10: i
A11: cash close | E11: =SUM(E6:E10) -> 9950 | I11: 9950 | J11: 1303505.5 | L11: =SUM(L6:L10) -> 9950 | M11: =SUM(M6:M10) -> 9950 | N11: =SUM(N6:N10) -> 9950 | O11: =SUM(O6:O10) -> 9950 | P11: =SUM(P6:P10) -> 1303505.5 | Q11: =SUM(Q6:Q10) -> 3524908.3 | R11: =SUM(R6:R10) -> 5674178.4 | S11: =SUM(S6:S10) -> 9143005
A12: participation accrual | E12: =-'c12_oc'!E74 -> 0 | I12: -2964570.5 | J12: -2970159.3 | L12: =-'c12_oc'!L74 -> -264555.12 | M12: =-'c12_oc'!M74 -> -1654110.2 | N12: =-'c12_oc'!N74 -> -2356165.4 | O12: =-'c12_oc'!O74 -> -2964570.5 | P12: =-'c12_oc'!P74 -> -2970159.3 | Q12: =-'c12_oc'!Q74 -> -2465036.1 | R12: =-'c12_oc'!R74 -> -2022503.4 | S12: =-'c12_oc'!S74 -> -1664945.5
A13: total assets | E13: =SUM(E11:E12) -> 9950 | I13: -2954620.5 | J13: -1666653.8 | L13: =SUM(L11:L12) -> -254605.12 | M13: =SUM(M11:M12) -> -1644160.2 | N13: =SUM(N11:N12) -> -2346215.4 | O13: =SUM(O11:O12) -> -2954620.5 | P13: =SUM(P11:P12) -> -1666653.8 | Q13: =SUM(Q11:Q12) -> 1059872.2 | R13: =SUM(R11:R12) -> 3651675 | S13: =SUM(S11:S12) -> 7478059.5
A15: liabilities
A16: c12loc | E16: ='c12_oc'!E62 -> -1540999 | I16: -1924884.3 | J16: 0 | L16: ='c12_oc'!L62 -> -2137441.8 | M16: ='c12_oc'!M62 -> -1459732.6 | N16: ='c12_oc'!N62 -> -1734829.5 | O16: ='c12_oc'!O62 -> -1924884.3 | P16: ='c12_oc'!P62 -> 0 | Q16: ='c12_oc'!Q62 -> 0 | R16: ='c12_oc'!R62 -> 0 | S16: ='c12_oc'!S62 -> 0
A18: NAV | E18: =E16+E13 -> -1531049 | I18: -4879504.8 | J18: -1666653.8 | L18: =L16+L13 -> -2392046.9 | M18: =M16+M13 -> -3103892.9 | N18: =N16+N13 -> -4081044.8 | O18: =O16+O13 -> -4879504.8 | P18: =P16+P13 -> -1666653.8 | Q18: =Q16+Q13 -> 1059872.2 | R18: =R16+R13 -> 3651675 | S18: =S16+S13 -> 7478059.5

Sheet c12_hm
A2: Year | E2: 45657 | F2: 45747 | G2: 45838 | H2: 45930 | I2: 46022 | J2: 46112 | K2: 46203 | L2: 45747 | M2: 45838 | N2: 45930 | O2: 46022 | P2: 46112 | Q2: 46203 | R2: 46295 | S2: 46387
E3: actual | L3: i/o
B4: i/o | C4: field_name | D4: index
A5: LGH Fee Revenue | C5: lgh_fee_revenue_section
A6: Bermuda PB Mgt | B6: i | C6: mgmt_fee | D6: pb | E6: 535096.5 | I6: 174125 | J6: 186369 | L6: =696500/4 -> 174125 | M6: =696500/4 -> 174125 | N6: =696500/4 -> 174125 | O6: =696500/4 -> 174125 | P6: =745476/4 -> 186369 | Q6: =745476/4 -> 186369 | R6: =745476/4 -> 186369 | S6: =745476/4 -> 186369 | T6: INPUT
A7: Bermuda PB Inc | B7: i | C7: incentive_fee | D7: pb | E7: 535096.5 | I7: 176042 | J7: 181323.26 | L7: =704168/4 -> 176042 | M7: =704168/4 -> 176042 | N7: =704168/4 -> 176042 | O7: =704168/4 -> 176042 | P7: =+O7*1.03 -> 181323.26 | Q7: =+P7 -> 181323.26 | R7: =+Q7 -> 181323.26 | S7: =+R7 -> 181323.26
A8: Austin Mgt | B8: i | C8: mgmt_fee | D8: austin | E8: 569458 | I8: 161030 | J8: 208682.75 | L8: =644120/4 -> 161030 | M8: =644120/4 -> 161030 | N8: =644120/4 -> 161030 | O8: =644120/4 -> 161030 | P8: =834731/4 -> 208682.75 | Q8: =834731/4 -> 208682.75 | R8: =834731/4 -> 208682.75 | S8: =834731/4 -> 208682.75
A9: Austin Inc | B9: i | C9: incentive_fee | D9: austin | I9: 70827.75 | J9: 72952.583 | L9: =283311/4 -> 70827.75 | M9: =283311/4 -> 70827.75 | N9: =283311/4 -> 70827.75 | O9: =283311/4 -> 70827.75 | P9: =+O9*1.03 -> 72952.583 | Q9: =+P9 -> 72952.583 | R9: =+Q9 -> 72952.583 | S9: =+R9 -> 72952.583
A10: Turks Mgt | B10: i | C10: mgmt_fee | D10: turks | I10: 0 | J10: 0 | L10: 0 | M10: 0 | N10: 0 | O10: 0 | P10: 0 | Q10: 0 | R10: 0 | S10: 0
A11: Turks Inc | B11: i | C11: incentive_fee | D11: turks
A12: Frithholme | B12: i | C12: mgmt_fee | D12: fritholme | I12: 0 | J12: 0 | L12: 0 | M12: 0 | N12: 0 | O12: 0 | P12: 0 | Q12: 0 | R12: 0 | S12: 0
A13: Elbow | B13: i | C13: mgmt_fee | D13: elbow | I13: 0 | J13: 0 | L13: 0 | M13: 0 | N13: 0 | O13: 0 | P13: 0
A14: [LSAT] | B14: i | C14: mgmt_fee | D14: lsat | S14: 0
A15: [blank]
A16: [blank]
A17: [blank]
A18: [blank]
A19: [blank]
A20: [blank]
A21: [blank]
A22: [blank]
A23: [blank]
A24: [L4] | B24: i | C24: mgmt_fee | D24: l4
A25: Total LGH Fees Earned | B25: c | C25: total_fees_earned | I25: 582024.75 | J25: 649327.59 | L25: =SUM(L6:L24) -> 582024.75 | M25: =SUM(M6:M24) -> 582024.75 | N25: =SUM(N6:N24) -> 582024.75 | O25: =SUM(O6:O24) -> 582024.75 | P25: =SUM(P6:P24) -> 649327.59 | Q25: =SUM(Q6:Q24) -> 649327.59 | R25: =SUM(R6:R24) -> 649327.59 | S25: =SUM(S6:S24) -> 649327.59
A27: Deferred Period Fee | B27: i | C27: deferred_fee | I27: -182177.75 | J27: -649327.59 | L27: =-L9 -> -70827.75 | M27: =-M9 -> -70827.75 | N27: =-N9 -> -70827.75 | O27: =-O9-111350 -> -182177.75 | P27: =-P25 -> -649327.59 | Q27: =-Q7-Q9 -> -254275.84 | R27: =-R7-R9 -> -254275.84 | S27: =-S7-S9-S14 -> -254275.84 | T27: INPUT
A28: Paid Fee Accruals | B28: i | C28: paid_fee_accruals | J28: 50000 | P28: 50000 | Q28: 246869.75 | R28: 246869.75 | S28: 1246869.8
A29: Cumm. Balance Accrued Fee | B29: c | C29: cumm_accrued_fee | I29: -394661 | J29: -993988.59 | L29: =+L27+E29+L28 -> -70827.75 | M29: =+M27+L29+M28 -> -141655.5 | N29: =+N27+M29+N28 -> -212483.25 | O29: =+O27+N29+O28 -> -394661 | P29: =+P27+O29+P28 -> -993988.59 | Q29: =+Q27+P29+Q28 -> -1001394.7 | R29: =+R27+Q29+R28 -> -1008800.8 | S29: =+S27+R29+S28 -> -16206.87
A31: Paid Current Fees | B31: c | C31: paid_current_fees | I31: 399847 | J31: 0 | L31: =+L25+L27 -> 511197 | M31: =+M25+M27 -> 511197 | N31: =+N25+N27 -> 511197 | O31: =+O25+O27 -> 399847 | P31: =+P25+P27 -> 0 | Q31: =+Q25+Q27 -> 395051.75 | R31: =+R25+R27 -> 395051.75 | S31: =+S25+S27 -> 395051.75
A32: Total Fees Paid | B32: c | C32: total_fees_paid | I32: 399847 | J32: 50000 | L32: =+L28+L31 -> 511197 | M32: =+M28+M31 -> 511197 | N32: =+N28+N31 -> 511197 | O32: =+O28+O31 -> 399847 | P32: =+P28+P31 -> 50000 | Q32: =+Q28+Q31 -> 641921.5 | R32: =+R28+R31 -> 641921.5 | S32: =+S28+S31 -> 1641921.5
A34: LGH Service Revenue
A35: Bermuda PB | B35: i | C35: hm_service_fee | D35: pb | I35: 47750 | J35: 0 | L35: =191000/4 -> 47750 | M35: =191000/4 -> 47750 | N35: =191000/4 -> 47750 | O35: =191000/4 -> 47750 | P35: 0 | Q35: 0 | R35: 0 | S35: 0 | T35: INPUT
A36: Austin | B36: i | C36: hm_service_fee | D36: austin | I36: 42250 | J36: 0 | L36: =169000/4 -> 42250 | M36: =169000/4 -> 42250 | N36: =169000/4 -> 42250 | O36: =169000/4 -> 42250 | P36: 0 | Q36: 0 | R36: 0 | S36: 0
A37: Turks | B37: i | C37: hm_service_fee | D37: turks | I37: 0 | J37: 0 | L37: 0 | M37: 0 | N37: 0 | O37: 0 | P37: 0 | Q37: 0 | R37: 0 | S37: 0
A38: Elbow | B38: i | C38: hm_service_fee | D38: elbow | I38: 0 | J38: 0 | L38: 0 | M38: 0 | N38: 0 | O38: 0 | P38: 0 | Q38: 0 | R38: 0 | S38: 0
A39: [blank]
A40: [blank]
A41: [blank]
A42: [blank]
A43: [blank]
A44: [blank]
...

Sheet c12_d&s
A2: Year | E2: 45657 | F2: 45747 | G2: 45838 | H2: 45930 | I2: 46022 | J2: 46112 | K2: 46203 | L2: 45747 | M2: 45838 | N2: 45930 | O2: 46022 | P2: 46112 | Q2: 46203 | R2: 46295 | S2: 46387
E3: actual | L3: i/o
B4: i/o | C4: field_name | D4: index
A5: LGH Fee Revenue
A6: Pink Beach Design Fee | B6: i | C6: design_fee | D6: pb | I6: 0 | J6: 0 | O6: 0 | P6: 0 | Q6: 0 | R6: 0 | S6: 0
A7: Pink Beach Development Fee | B7: i | C7: development_fee | D7: pb | I7: 0 | J7: 0 | O7: 0 | P7: 0 | Q7: 0 | R7: 0 | S7: 0
A8: Pink Beach Structuring Fee | B8: i | C8: structuring_fee | D8: pb | N8: =520000 -> 520000 | Q8: 0 | S8: 0
A9: Austin Design Fee | B9: i | C9: design_fee | D9: austin | I9: 0 | J9: 0 | O9: 0 | P9: 0 | Q9: 0 | R9: 0 | S9: 0
A10: Austin Development Fee | B10: i | C10: development_fee | D10: austin | I10: 0 | J10: 0 | O10: 0 | P10: 0 | Q10: 0 | R10: 0 | S10: 0
A11: Turks Design Fee | B11: i | C11: design_fee | D11: turks | I11: 50000 | J11: 0 | O11: 50000 | P11: 0 | Q11: 0 | R11: 0 | S11: 0
A12: Turks Development Fee | B12: i | C12: development_fee | D12: turks | E12: 812800 | I12: 340000 | J12: 549375 | L12: 280000 | M12: 280000 | N12: 280000 | O12: 340000 | P12: =2930000/16*3 -> 549375 | Q12: =2930000/16*3 -> 549375 | R12: =2930000/16*3 -> 549375 | S12: =2930000/16*3 -> 549375
A13: Turks Structuring Fee | B13: i | C13: structuring_fee | D13: turks | I13: 250000 | J13: 0 | O13: 250000 | P13: 0 | Q13: 0 | R13: 0 | S13: 0
A14: Elbow Design Fee | B14: i | C14: design_fee | D14: elbow | I14: 375000 | J14: 487500 | N14: =750000/2 -> 375000 | O14: =750000/2 -> 375000 | P14: =(4500000*0.6-SUM($N$14:$O$14))/4 -> 487500 | Q14: =(4500000*0.6-SUM($N$14:$O$14))/4 -> 487500 | R14: =(4500000*0.6-SUM($N$14:$O$14))/4 -> 487500 | S14: =(4500000*0.6-SUM($N$14:$O$14))/4 -> 487500
A15: Elbow Development Fee | B15: i | C15: development_fee | D15: elbow | I15: 500000 | J15: 433333.33 | N15: =1000000/2 -> 500000 | O15: =1000000/2 -> 500000 | P15: =5200000/3/4 -> 433333.33 | Q15: =5200000/3/4 -> 433333.33 | R15: =5200000/3/4 -> 433333.33 | S15: =5200000/3/4 -> 433333.33
A16: Elbow Structuring Fee | B16: i | C16: structuring_fee | D16: elbow | I16: 0 | J16: 0 | L16: 0 | M16: 0 | N16: 0 | O16: 0 | P16: 0 | Q16: 0 | R16: 0 | S16: 0
A17: Elbow Construction Fee | B17: i | C17: construction_fee | D17: elbow | J17: 0 | P17: 0 | Q17: 0 | R17: 0 | S17: 0
A18: Elbow Acquisition Fee | B18: i | C18: acquisition_fee | D18: elbow | M18: 1000000
A19: [blank] | I19: 0 | J19: 0 | L19: 0 | M19: 0 | N19: 0 | O19: 0 | P19: 0 | Q19: 0 | R19: 0 | S19: 0
A20: Frith Acq Fee | B20: i | C20: acquisition_fee | D20: fritholme | I20: 0 | J20: 0 | L20: 0 | M20: 1250000 | N20: 0 | O20: 0 | P20: 0 | Q20: 0 | R20: 0 | S20: 0
A21: [blank] | I21: 0 | J21: 0 | L21: 0 | M21: 0 | N21: 0 | O21: 0 | P21: 0 | Q21: 0 | R21: 0 | S21: 0
A22: Frith Disposition fee | B22: i | C22: disposition_fee | D22: fritholme | I22: 0 | J22: 0 | O22: 0 | P22: 0 | Q22: 0 | R22: 0 | S22: 2500000
A23: SAT | B23: i | C23: development_fee | D23: lsat | S23: =500000+1600000 -> 2100000
A24: [L4] | B24: i | C24: development_fee | D24: l4 | R24: 0 | S24: 0
A25: Total LGH Fees Earned | B25: c | C25: total_fees_earned | I25: 1515000 | J25: 1470208.3 | L25: =SUM(L6:L24) -> 280000 | M25: =SUM(M6:M24) -> 2530000 | N25: =SUM(N6:N24) -> 1675000 | O25: =SUM(O6:O24) -> 1515000 | P25: =SUM(P6:P24) -> 1470208.3 | Q25: =SUM(Q6:Q24) -> 1470208.3 | R25: =SUM(R6:R24) -> 1470208.3 | S25: =SUM(S6:S24) -> 6070208.3
A27: Deferred Period Fee | B27: i | C27: deferred_fee | I27: -745000 | J27: -1470208 | L27: =-SUM(L6:L24) -> -280000 | M27: =-SUM(M6:M24) -> -2530000 | N27: -1155000 | O27: -745000 | P27: -1470208 | Q27: =-1000000+310000 -> -690000 | R27: -1000000 | S27: -2100000
A28: Paid Fee Accruals | B28: i | C28: paid_fee_accruals | J28: 1508647.3 | P28: 1508647.3 | Q28: 1177500 | R28: 1177500 | S28: 1177500
A29: Cumm. Balance Accrued Fee | B29: c | C29: cumm_accrued_fee | I29: -4710000 | J29: -4671560.7 | L29: =+L27+E29+L28 -> -280000 | M29: =+M27+L29+M28 -> -2810000 | N29: =+N27+M29+N28 -> -3965000 | O29: =+O27+N29+O28 -> -4710000 | P29: =+P27+O29+P28 -> -4671560.7 | Q29: =+Q27+P29+Q28 -> -4184060.7 | R29: =+R27+Q29+R28 -> -4006560.7 | S29: =+S27+R29+S28 -> -4929060.7
A31: Paid Current Fees | B31: c | C31: paid_current_fees | I31: 770000 | J31: 0.33333333 | L31: =+L25+L27 -> 0 | M31: =+M25+M27 -> 0 | N31: =+N25+N27 -> 520000 | O31: =+O25+O27 -> 770000 | P31: =+P25+P27 -> 0.33333333 | Q31: =+Q25+Q27 -> 780208.33 | R31: =+R25+R27 -> 470208.33 | S31: =+S25+S27 -> 3970208.3
A32: Total Fees Paid | B32: c | C32: total_fees_paid | I32: 770000 | J32: 1508647.7 | L32: =+L28+L31 -> 0 | M32: =+M28+M31 -> 0 | N32: =+N28+N31 -> 520000 | O32: =+O28+O31 -> 770000 | P32: =+P28+P31 -> 1508647.7 | Q32: =+Q28+Q31 -> 1957708.3 | R32: =+R28+R31 -> 1647708.3 | S32: =+S28+S31 -> 5147708.3
A34: LGH Service Revenue
A35: PB Design Services | B35: i | C35: design_service_fee | D35: pb | I35: 22110.5 | J35: 45000 | L35: =88442/4 -> 22110.5 | M35: =88442/4 -> 22110.5 | N35: =88442/4 -> 22110.5 | O35: =88442/4 -> 22110.5 | P35: =180000/4 -> 45000 | Q35: =180000/4 -> 45000 | R35: =180000/4 -> 45000 | S35: =180000/4 -> 45000
A36: Austin Design Services | B36: i | C36: design_service_fee | D36: austin | E36: 667500 | I36: 22954.75 | J36: 60000 | L36: =91819/4 -> 22954.75 | M36: =91819/4 -> 22954.75 | N36: =91819/4 -> 22954.75 | O36: =91819/4 -> 22954.75 | P36: =240000/4 -> 60000 | Q36: =240000/4 -> 60000 | R36: =240000/4 -> 60000 | S36: =240000/4 -> 60000
A37: Turks Design Services | B37: i | C37: design_service_fee | D37: turks | I37: 0 | J37: 50000 | L37: =200000/4*0 -> 0 | M37: =200000/4*0 -> 0 | N37: =200000/4*0 -> 0 | O37: =200000/4*0 -> 0 | P37: =200000/4 -> 50000 | Q37: =400000/4 -> 100000 | R37: =200000/4 -> 50000 | S37: =200000/4 -> 50000
A38: Elbow Design Services | B38: i | C38: design_service_fee | D38: elbow | I38: 0 | J38: 0 | L38: 0 | M38: 0 | N38: 0 | O38: 0 | P38: 0 | Q38: =180000/4 -> 45000 | R38: =180000/4 -> 45000 | S38: =+R38 -> 45000
A39: Elbow AM | B39: i | C39: am_fee | D39: elbow | I39: 0 | J39: 0 | L39: 0 | M39: 0 | N39: 0 | O39: 0 | P39: 0 | Q39: 0 | R39: 0 | S39: 0
A40: Frith Design Services | B40: i | C40: design_service_fee | D40: fritholme | I40: 0 | J40: 27000 | M40: =108000/4*0 -> 0 | N40: =108000/4*0 -> 0 | O40: =108000/4*0 -> 0 | P40: =108000/4 -> 27000 | Q40: =+P40 -> 27000 | R40: =+Q40 -> 27000 | S40: =+R40 -> 27000
A41: Frith AM | B41: i | C41: am_fee | D41: fritholme | I41: 12500 | J41: 12500 | L41: 0 | M41: 0 | N41: 50400 | O41: 12500 | P41: 12500 | Q41: 12500 | R41: 12500
A42: Bermuda PB AM | B42: i | C42: am_fee | D42: pb | I42: 57077.25 | J42: 72879 | L42: 57077.25 | M42: 57077.25 | N42: 57077.25 | O42: 57077.25 | P42: 72879 | Q42: 72879 | R42: 72879 | S42: 72879
A43: AustinAM | B43: i | C43: am_fee | D43: austin | I43: 49547.75 | J43: 63543 | L43: 49547.75 | M43: 49547.75 | N43: 49547.75 | O43: 49547.75 | P43: 63543 | Q43: 63543 | R43: 63543 | S43: 63543
A44: [blank]
...

Sheet c12_bi&F
A2: Year | E2: 45657 | F2: 45747 | G2: 45838 | H2: 45930 | I2: 46022 | J2: 46112 | K2: 46203 | L2: 45747 | M2: 45838 | N2: 45930 | O2: 46022 | P2: 46112 | Q2: 46203 | R2: 46295 | S2: 46387
E3: actual | L3: i/o
B4: i/o | C4: field_name | D4: index
A5: LGH Fee Revenue | C5: lgh_fee_revenue_section
A6: [blank]
A7: [blank]
A8: [blank]
A9: [blank]
A10: [blank]
A11: [blank]
A12: [blank]
A13: [blank]
A14: [blank]
A15: [blank]
A16: [blank]
A17: [blank]
... A21: [blank]
A22: [blank] | I22: 0 | J22: 0 | L22: 0 | M22: 0 | N22: 0 | O22: 0 | P22: 0 | Q22: 0 | R22: 0 | S22: 0
A23: [blank] | I23: 0 | J23: 0 | L23: 0 | M23: 0 | N23: 0 | O23: 0 | P23: 0 | Q23: 0 | R23: 0 | S23: 0
A24: [blank] | I24: 0 | J24: 0 | L24: 0 | M24: 0 | N24: 0 | O24: 0 | P24: 0 | Q24: 0 | R24: 0 | S24: 0
A25: Total LGH Fees Earned | B25: c | C25: total_fees_earned | I25: 0 | J25: 0 | L25: =SUM(L22:L24) -> 0 | M25: =SUM(M22:M24) -> 0 | N25: =SUM(N22:N24) -> 0 | O25: =SUM(O22:O24) -> 0 | P25: =SUM(P22:P24) -> 0 | Q25: =SUM(Q22:Q24) -> 0 | R25: =SUM(R22:R24) -> 0 | S25: =SUM(S22:S24) -> 0
A27: Deferred Period Fee | B27: i | C27: deferred_fee | I27: 0 | J27: 0 | L27: 0 | M27: 0 | N27: 0 | O27: 0 | P27: 0 | Q27: 0 | R27: 0 | S27: 0
A28: Paid Fee Accruals | B28: i | C28: paid_fee_accruals | I28: 0 | J28: 0 | L28: 0 | M28: 0 | N28: 0 | O28: 0 | P28: 0 | Q28: 0 | R28: 0 | S28: 0
A29: Cumm. Balance Accrued Fee | B29: c | C29: cumm_accrued_fee | I29: 0 | J29: 0 | L29: =+L27+E29+L28 -> 0 | M29: =+M27+L29+M28 -> 0 | N29: =+N27+M29+N28 -> 0 | O29: =+O27+N29+O28 -> 0 | P29: =+P27+O29+P28 -> 0 | Q29: =+Q27+P29+Q28 -> 0 | R29: =+R27+Q29+R28 -> 0 | S29: =+S27+R29+S28 -> 0
A31: Paid Current Fees | B31: c | C31: paid_current_fees | I31: 0 | J31: 0 | L31: =+L25+L27 -> 0 | M31: =+M25+M27 -> 0 | N31: =+N25+N27 -> 0 | O31: =+O25+O27 -> 0 | P31: =+P25+P27 -> 0 | Q31: =+Q25+Q27 -> 0 | R31: =+R25+R27 -> 0 | S31: =+S25+S27 -> 0
A32: Total Fees Paid | B32: c | C32: total_fees_paid | I32: 0 | J32: 0 | L32: =+L28+L31 -> 0 | M32: =+M28+M31 -> 0 | N32: =+N28+N31 -> 0 | O32: =+O28+O31 -> 0 | P32: =+P28+P31 -> 0 | Q32: =+Q28+Q31 -> 0 | R32: =+R28+R31 -> 0 | S32: =+S28+S31 -> 0
A34: LGH Service Revenue | C34: lgh_service_revenue_section
A35: Bermuda PB | B35: i | C35: accting_fee | D35: pb | I35: 0 | J35: 15000 | L35: 0 | M35: 0 | N35: 0 | O35: 0 | P35: =60000/4 -> 15000 | Q35: =60000/4 -> 15000 | R35: =60000/4 -> 15000 | S35: =60000/4 -> 15000
A36: 7f | B36: i | C36: accting_fee | D36: austin | I36: 0 | J36: 15000 | L36: 0 | M36: 0 | N36: 0 | O36: 0 | P36: =60000/4 -> 15000 | Q36: =60000/4 -> 15000 | R36: =60000/4 -> 15000 | S36: =60000/4 -> 15000
A37: Turks | B37: i | C37: accting_fee | D37: turks | I37: 0 | J37: 0 | L37: 0 | M37: 0 | N37: 0 | O37: 0 | P37: 0 | Q37: 0 | R37: 0 | S37: 0
A38: Elbow | B38: i | C38: accting_fee | D38: elbow | I38: 0 | J38: 0 | L38: 0 | M38: 0 | N38: 0 | O38: 0 | P38: 0 | Q38: 0 | R38: 0 | S38: 0
A39: Frith | B39: i | C39: accting_fee | D39: fritholme | I39: 0 | J39: 0 | L39: 0 | M39: 0 | N39: 0 | O39: 0 | P39: 0 | Q39: =+P39 -> 0 | R39: =+Q39 -> 0 | S39: =+R39 -> 0
A40: [blank]
A41: [blank]
A42: [blank]
A43: [blank]
A44: [blank]
A45: [LSAT] | B45: i | C45: accting_fee | D45: lsat
A46: Total LGH Bi&F Service Revenue | B46: c | C46: total_service_revenue | I46: 0 | J46: 30000 | L46: =SUM(L35:L45) -> 0 | M46: =SUM(M35:M45) -> 0 | N46: =SUM(N35:N45) -> 0 | O46: =SUM(O35:O45) -> 0 | P46: =SUM(P35:P45) -> 30000 | Q46: =SUM(Q35:Q45) -> 30000 | R46: =SUM(R35:R45) -> 30000 | S46: =SUM(S35:S45) -> 30000
A48: Deferred Period Fee | B48: i | C48: deferred_service_fee | L48: =-L36 -> 0
...

Sheet .c12_inputs.hr
B4: i/o | C4: field_name | D4: index
A5: ocBenefits | B5: i | C5: benefits_rate | D5: oc | E5: 0.021714286 | F5: adjusted down to assume sk doesn’t pay
A6: ocBonus Tax | B6: i | C6: bonus_tax_rate_actual | D6: oc | E6: 0.039
A8: hmBenefits | B8: i | C8: benefits_rate_actual | D8: hm | E8: 0.152
A9: hmBonus Tax | B9: i | C9: bonus_tax_rate_actual | D9: hm | E9: 0.039
A11: bfBenefits | B11: i | C11: benefits_rate_actual | D11: bif | E11: 0.152
A12: bfBonus Tax | B12: i | C12: bonus_tax_rate_actual | D12: bif | E12: 0.039
A15: dsBenefits | B15: i | C15: benefits_rate_actual | D15: ds | E15: 0.152
A16: dsBonus Tax | B16: i | C16: bonus_tax_rate_actual | D16: ds | E16: 0.039

Sheet .c12_oc_hr
A2: Year | E2: 45657 | F2: 45747 | G2: 45838 | H2: 45930 | I2: 46022 | J2: 46112 | K2: 46203 | L2: 45747 | M2: 45838 | N2: 45930 | O2: 46022 | P2: 46112 | Q2: 46203 | R2: 46295 | S2: 46387 | T2: 46752 | U2: 47118 | V2: 47483 | W2: 47848
E3: actual | L3: i/o
B4: i/o | C4: field_name | D4: index
A5: Base
A6: Managing Member (SK) | B6: i | C6: base_salary | D6: sk | I6: 375000 | J6: 375000 | L6: 375000 | M6: 375000 | N6: 375000 | O6: 375000 | P6: 375000 | Q6: 375000 | R6: 375000 | S6: 375000 | T6: 1500000 | U6: 1500000 | V6: 1500000 | W6: 1500000
A7: Philanropy senior exec (LM) (100%roots) | B7: i | C7: base_salary | D7: lm | I7: 0 | J7: 0 | L7: 0 | M7: 0 | N7: 0 | O7: 0 | P7: 0 | Q7: 0 | R7: 0 | S7: 0 | T7: 0 | U7: 0 | V7: 0 | W7: 0
A8: Bookkeeper (DD) | B8: i | C8: base_salary | D8: dd | I8: 0 | J8: 25750 | L8: 0 | M8: 0 | N8: 0 | O8: 0 | P8: 25750 | Q8: 25750 | R8: 25750 | S8: 25750 | T8: 103000 | U8: 103000 | V8: 103000 | W8: 103000
A9: Personal Assistant (CD) | B9: i | C9: base_salary | D9: cd | I9: 31250 | J9: 31250 | L9: 31250 | M9: 31250 | N9: 31250 | O9: 31250 | P9: 31250 | Q9: 31250 | R9: 31250 | S9: 31250 | T9: 125000 | U9: 125000 | V9: 125000 | W9: 125000
A10: philanthropy assist (100%roots) | B10: i | C10: base_salary | D10: philanthropy | I10: 0 | J10: 0 | L10: 0 | M10: 0 | N10: 0 | O10: 0 | P10: 0 | Q10: 0 | R10: 0 | S10: 0 | T10: 0 | U10: 0 | V10: 0 | W10: 0
A11: TM (gone) | B11: i | C11: base_salary | D11: tm | I11: 87500 | J11: 87500 | L11: 87500 | M11: 87500 | N11: 87500 | O11: 87500 | P11: 87500 | Q11: 0 | R11: 0 | S11: 0 | T11: 0 | U11: 0 | V11: 0 | W11: 0
A12: Total | I12: 493750 | J12: 519500 | L12: =SUM(L6:L11) -> 493750 | M12: =SUM(M6:M11) -> 493750 | N12: =SUM(N6:N11) -> 493750 | O12: =SUM(O6:O11) -> 493750 | P12: =SUM(P6:P11) -> 519500 | Q12: =SUM(Q6:Q11) -> 432000 | R12: =SUM(R6:R11) -> 432000 | S12: =SUM(S6:S11) -> 432000 | ... W12: =SUM(W6:W11) -> 1728000
A13: Bonus
A14: =+A6 -> Managing Member (SK) | B14: i | C14: bonus | D14: sk | I14: 0 | J14: 0 | L14: 0 | M14: 0 | N14: 0 | O14: 0 | P14: 0 | Q14: 0 | R14: 0 | S14: 0 | T14: 0 | U14: 0 | V14: 0 | W14: 0
A15: =+A7 -> Philanropy senior exec (LM) (100%roots) | B15: i | C15: bonus | D15: lm | I15: 0 | J15: 0 | L15: 0 | M15: 0 | N15: 0 | O15: 0 | P15: 0 | Q15: 0 | R15: 0 | S15: 0 | T15: 0 | U15: 0 | V15: 0 | W15: 0
A16: =+A8 -> Bookkeeper (DD) | B16: i | C16: bonus | D16: dd | I16: 10000 | J16: 0 | L16: 0 | N16: 0 | O16: 10000 | P16: 0 | Q16: 0 | R16: 0 | S16: 5000 | T16: 5000 | U16: 5000 | V16: 5000 | W16: 5000
A17: =+A9 -> Personal Assistant (CD) | B17: i | C17: bonus | D17: cd | I17: 0 | J17: 0 | L17: 0 | M17: 0 | N17: 0 | O17: 0 | P17: 0 | Q17: 0 | R17: 0 | S17: 15000 | T17: 15000 | U17: 15000 | V17: 15000 | W17: 15000
A18: =+A10 -> philanthropy assist (100%roots) | B18: i | C18: bonus | D18: philanthropy | I18: 0 | J18: 0 | L18: 0 | M18: 0 | N18: 0 | O18: 0 | P18: 0 | Q18: 0 | R18: 0 | S18: 0 | T18: 0 | U18: 0 | V18: 0 | W18: 0
A19: =+A11 -> TM (gone) | B19: i | C19: bonus | D19: tm | I19: 0 | J19: 320000 | L19: 0 | M19: 0 | N19: 0 | O19: 0 | P19: 320000 | Q19: 0 | R19: 0 | S19: 500000 | T19: 500000 | U19: 0 | V19: 0 | W19: 0
A20: Total | I20: 10000 | J20: 320000 | L20: =SUM(L14:L19) -> 0 | M20: =SUM(M14:M19) -> 0 | N20: =SUM(N14:N19) -> 0 | O20: =SUM(O14:O19) -> 10000 | P20: =SUM(P14:P19) -> 320000 | Q20: =SUM(Q14:Q19) -> 0 | R20: =SUM(R14:R19) -> 0 | S20: =SUM(S14:S19) -> 520000 | ... W20: =SUM(W14:W19) -> 20000
A22: Total
A23: =+A6 -> Managing Member (SK) | B23: c | C23: total_salary | D23: sk | I23: 383142.86 | J23: 383142.86 | L23: =L6*(1+'.c12_inputs.hr'!$E$5)+(L14*(1+'.c12_inputs.hr'!$E$6)) -> 383142.86 | M23: =M6*(1+'.c12_inputs.hr'!$E$5)+(M14*(1+'.c12_inputs.hr'!$E$6)) -> 383142.86 | N23: =N6*(1+'.c12_inputs.hr'!$E$5)+(N14*(1+'.c12_inputs.hr'!$E$6)) -> 383142.86 | O23: =O6*(1+'.c12_inputs.hr'!$E$5)+(O14*(1+'.c12_inputs.hr'!$E$6)) -> 383142.86 | P23: =P6*(1+'.c12_inputs.hr'!$E$5)+(P14*(1+'.c12_inputs.hr'!$E$6)) -> 383142.86 | Q23: =Q6*(1+'.c12_inputs.hr'!$E$5)+(Q14*(1+'.c12_inputs.hr'!$E$6)) -> 383142.86 | R23: =R6*(1+'.c12_inputs.hr'!$E$5)+(R14*(1+'.c12_inputs.hr'!$E$6)) -> 383142.86 | S23: =S6*(1+'.c12_inputs.hr'!$E$5)+(S14*(1+'.c12_inputs.hr'!$E$6)) -> 383142.86 | ... W23: =W6*(1+'.c12_inputs.hr'!$E$5)+(W14*(1+'.c12_inputs.hr'!$E$6)) -> 1532571.4
A24: =+A7 -> Philanropy senior exec (LM) (100%roots) | B24: c | C24: total_salary | D24: lm | I24: 0 | J24: 0 | L24: =L7*(1+'.c12_inputs.hr'!$E$5)+(L15*(1+'.c12_inputs.hr'!$E$6)) -> 0 | M24: =M7*(1+'.c12_inputs.hr'!$E$5)+(M15*(1+'.c12_inputs.hr'!$E$6)) -> 0 | N24: =N7*(1+'.c12_inputs.hr'!$E$5)+(N15*(1+'.c12_inputs.hr'!$E$6)) -> 0 | O24: =O7*(1+'.c12_inputs.hr'!$E$5)+(O15*(1+'.c12_inputs.hr'!$E$6)) -> 0 | P24: =P7*(1+'.c12_inputs.hr'!$E$5)+(P15*(1+'.c12_inputs.hr'!$E$6)) -> 0 | Q24: =Q7*(1+'.c12_inputs.hr'!$E$5)+(Q15*(1+'.c12_inputs.hr'!$E$6)) -> 0 | R24: =R7*(1+'.c12_inputs.hr'!$E$5)+(R15*(1+'.c12_inputs.hr'!$E$6)) -> 0 | S24: =S7*(1+'.c12_inputs.hr'!$E$5)+(S15*(1+'.c12_inputs.hr'!$E$6)) -> 0 | ... W24: =W7*(1+'.c12_inputs.hr'!$E$5)+(W15*(1+'.c12_inputs.hr'!$E$6)) -> 0
A25: =+A8 -> Bookkeeper (DD) | B25: c | C25: total_salary | D25: dd | I25: 10390 | J25: 26309.143 | L25: =L8*(1+'.c12_inputs.hr'!$E$5)+(L16*(1+'.c12_inputs.hr'!$E$6)) -> 0 | M25: =M8*(1+'.c12_inputs.hr'!$E$5)+(M16*(1+'.c12_inputs.hr'!$E$6)) -> 0 | N25: =N8*(1+'.c12_inputs.hr'!$E$5)+(N16*(1+'.c12_inputs.hr'!$E$6)) -> 0 | O25: =O8*(1+'.c12_inputs.hr'!$E$5)+(O16*(1+'.c12_inputs.hr'!$E$6)) -> 10390 | P25: =P8*(1+'.c12_inputs.hr'!$E$5)+(P16*(1+'.c12_inputs.hr'!$E$6)) -> 26309.143 | Q25: =Q8*(1+'.c12_inputs.hr'!$E$5)+(Q16*(1+'.c12_inputs.hr'!$E$6)) -> 26309.143 | R25: =R8*(1+'.c12_inputs.hr'!$E$5)+(R16*(1+'.c12_inputs.hr'!$E$6)) -> 26309.143 | S25: =S8*(1+'.c12_inputs.hr'!$E$5)+(S16*(1+'.c12_inputs.hr'!$E$6)) -> 31504.143 | ... W25: =W8*(1+'.c12_inputs.hr'!$E$5)+(W16*(1+'.c12_inputs.hr'!$E$6)) -> 110431.57
A26: =+A9 -> Personal Assistant (CD) | B26: c | C26: total_salary | D26: cd | I26: 31928.571 | J26: 31928.571 | L26: =L9*(1+'.c12_inputs.hr'!$E$5)+(L17*(1+'.c12_inputs.hr'!$E$6)) -> 31928.571 | M26: =M9*(1+'.c12_inputs.hr'!$E$5)+(M17*(1+'.c12_inputs.hr'!$E$6)) -> 31928.571 | N26: =N9*(1+'.c12_inputs.hr'!$E$5)+(N17*(1+'.c12_inputs.hr'!$E$6)) -> 31928.571 | O26: =O9*(1+'.c12_inputs.hr'!$E$5)+(O17*(1+'.c12_inputs.hr'!$E$6)) -> 31928.571 | P26: =P9*(1+'.c12_inputs.hr'!$E$5)+(P17*(1+'.c12_inputs.hr'!$E$6)) -> 31928.571 | Q26: =Q9*(1+'.c12_inputs.hr'!$E$5)+(Q17*(1+'.c12_inputs.hr'!$E$6)) -> 31928.571 | R26: =R9*(1+'.c12_inputs.hr'!$E$5)+(R17*(1+'.c12_inputs.hr'!$E$6)) -> 31928.571 | S26: =S9*(1+'.c12_inputs.hr'!$E$5)+(S17*(1+'.c12_inputs.hr'!$E$6)) -> 47513.571 | ... W26: =W9*(1+'.c12_inputs.hr'!$E$5)+(W17*(1+'.c12_inputs.hr'!$E$6)) -> 143299.29
A27: =+A10 -> philanthropy assist (100%roots) | B27: c | C27: total_salary | D27: philanthropy | I27: 0 | J27: 0 | L27: =L10*(1+'.c12_inputs.hr'!$E$5)+(L18*(1+'.c12_inputs.hr'!$E$6)) -> 0 | M27: =M10*(1+'.c12_inputs.hr'!$E$5)+(M18*(1+'.c12_inputs.hr'!$E$6)) -> 0 | N27: =N10*(1+'.c12_inputs.hr'!$E$5)+(N18*(1+'.c12_inputs.hr'!$E$6)) -> 0 | O27: =O10*(1+'.c12_inputs.hr'!$E$5)+(O18*(1+'.c12_inputs.hr'!$E$6)) -> 0 | P27: =P10*(1+'.c12_inputs.hr'!$E$5)+(P18*(1+'.c12_inputs.hr'!$E$6)) -> 0 | Q27: =Q10*(1+'.c12_inputs.hr'!$E$5)+(Q18*(1+'.c12_inputs.hr'!$E$6)) -> 0 | R27: =R10*(1+'.c12_inputs.hr'!$E$5)+(R18*(1+'.c12_inputs.hr'!$E$6)) -> 0 | S27: =S10*(1+'.c12_inputs.hr'!$E$5)+(S18*(1+'.c12_inputs.hr'!$E$6)) -> 0 | ... W27: =W10*(1+'.c12_inputs.hr'!$E$5)+(W18*(1+'.c12_inputs.hr'!$E$6)) -> 0
A28: =+A11 -> TM (gone) | B28: c | C28: total_salary | D28: tm | I28: 89400 | J28: 421880 | L28: =L11*(1+'.c12_inputs.hr'!$E$5)+(L19*(1+'.c12_inputs.hr'!$E$6)) -> 89400 | M28: =M11*(1+'.c12_inputs.hr'!$E$5)+(M19*(1+'.c12_inputs.hr'!$E$6)) -> 89400 | N28: =N11*(1+'.c12_inputs.hr'!$E$5)+(N19*(1+'.c12_inputs.hr'!$E$6)) -> 89400 | O28: =O11*(1+'.c12_inputs.hr'!$E$5)+(O19*(1+'.c12_inputs.hr'!$E$6)) -> 89400 | P28: =P11*(1+'.c12_inputs.hr'!$E$5)+(P19*(1+'.c12_inputs.hr'!$E$6)) -> 421880 | Q28: =Q11*(1+'.c12_inputs.hr'!$E$5)+(Q19*(1+'.c12_inputs.hr'!$E$6)) -> 0 | R28: =R11*(1+'.c12_inputs.hr'!$E$5)+(R19*(1+'.c12_inputs.hr'!$E$6)) -> 0 | S28: =S11*(1+'.c12_inputs.hr'!$E$5)+(S19*(1+'.c12_inputs.hr'!$E$6)) -> 519500 | ... W28: =W11*(1+'.c12_inputs.hr'!$E$5)+(W19*(1+'.c12_inputs.hr'!$E$6)) -> 0
A30: Grand Total | B30: o | C30: hr_grand_total | I30: 514861.43 | J30: 863260.57 | L30: =SUM(L23:L28) -> 504471.43 | M30: =SUM(M23:M28) -> 504471.43 | N30: =SUM(N23:N28) -> 504471.43 | O30: =SUM(O23:O28) -> 514861.43 | P30: =SUM(P23:P28) -> 863260.57 | Q30: =SUM(Q23:Q28) -> 441380.57 | R30: =SUM(R23:R28) -> 441380.57 | S30: =SUM(S23:S28) -> 981660.57 | ... W30: =SUM(W23:W28) -> 1786302.3
A31: reimbersable to hotel | B31: o | C31: hr_reimbursable | I31: 0 | J31: 0 | L31: =SUMPRODUCT('.c12_alloc'!$H$6:$H$11,L23:L28) -> 0 | M31: =SUMPRODUCT('.c12_alloc'!$H$6:$H$11,M23:M28) -> 0 | N31: =SUMPRODUCT('.c12_alloc'!$H$6:$H$11,N23:N28) -> 0 | O31: =SUMPRODUCT('.c12_alloc'!$H$6:$H$11,O23:O28) -> 0 | P31: =SUMPRODUCT('.c12_alloc'!$H$6:$H$11,P23:P28) -> 0 | Q31: =SUMPRODUCT('.c12_alloc'!$H$6:$H$11,Q23:Q28) -> 0 | R31: =SUMPRODUCT('.c12_alloc'!$H$6:$H$11,R23:R28) -> 0 | S31: =SUMPRODUCT('.c12_alloc'!$H$6:$H$11,S23:S28) -> 0 | ... W31: =SUMPRODUCT('.c12_alloc'!$H$6:$H$11,W23:W28) -> 0
A32: not reimbersable by hotel, but paid by lgh | B32: o | C32: hr_not_reimbursable | I32: 472542.86 | J32: 805022.86 | L32: =SUMPRODUCT('.c12_alloc'!$G$6:$G$11,L23:L28) -> 472542.86 | M32: =SUMPRODUCT('.c12_alloc'!$G$6:$G$11,M23:M28) -> 472542.86 | N32: =SUMPRODUCT('.c12_alloc'!$G$6:$G$11,N23:N28) -> 472542.86 | O32: =SUMPRODUCT('.c12_alloc'!$G$6:$G$11,O23:O28) -> 472542.86 | P32: =SUMPRODUCT('.c12_alloc'!$G$6:$G$11,P23:P28) -> 805022.86 | Q32: =SUMPRODUCT('.c12_alloc'!$G$6:$G$11,Q23:Q28) -> 383142.86 | R32: =SUMPRODUCT('.c12_alloc'!$G$6:$G$11,R23:R28) -> 383142.86 | S32: =SUMPRODUCT('.c12_alloc'!$G$6:$G$11,S23:S28) -> 902642.86 | ... W32: =SUMPRODUCT('.c12_alloc'!$G$6:$G$11,W23:W28) -> 1532571.4
A33: only paid by c12 | B33: o | C33: hr_only_c12 | I33: 42318.571 | J33: 58237.714 | L33: =SUMPRODUCT('.c12_alloc'!$E$6:$E$11,L23:L28) -> 31928.571 | M33: =SUMPRODUCT('.c12_alloc'!$E$6:$E$11,M23:M28) -> 31928.571 | N33: =SUMPRODUCT('.c12_alloc'!$E$6:$E$11,N23:N28) -> 31928.571 | O33: =SUMPRODUCT('.c12_alloc'!$E$6:$E$11,O23:O28) -> 42318.571 | P33: =SUMPRODUCT('.c12_alloc'!$E$6:$E$11,P23:P28) -> 58237.714 | Q33: =SUMPRODUCT('.c12_alloc'!$E$6:$E$11,Q23:Q28) -> 58237.714 | R33: =SUMPRODUCT('.c12_alloc'!$E$6:$E$11,R23:R28) -> 58237.714 | S33: =SUMPRODUCT('.c12_alloc'!$E$6:$E$11,S23:S28) -> 79017.714 | ... W33: =SUMPRODUCT('.c12_alloc'!$E$6:$E$11,W23:W28) -> 253730.86

Sheet .c12_hm_hr
A2: Year | E2: 45657 | F2: 45747 | G2: 45838 | H2: 45930 | I2: 46022 | J2: 46112 | K2: 46203 | L2: 45747 | M2: 45838 | N2: 45930 | O2: 46022 | P2: 46112 | Q2: 46203 | R2: 46295 | S2: 46387 | T2: 46752 | U2: 47118 | V2: 47483 | W2: 47848
E3: actual | L3: i/o
B4: i/o | C4: field_name | D4: index
A5: base
A6: ACEO Loren Hotels (CE) | B6: i | C6: base_salary | D6: ce | I6: 125000 | J6: 125000 | L6: 125000 | M6: 125000 | N6: 125000 | O6: 125000 | P6: 125000 | Q6: 125000 | R6: 125000 | S6: 125000 | T6: 500000 | U6: 500000 | V6: 500000 | W6: 500000
A7: VP Operations (WS) | B7: i | C7: base_salary | D7: ws | I7: 68750 | J7: 72500 | L7: 68750 | M7: 68750 | N7: 68750 | O7: 68750 | P7: 72500 | Q7: 72500 | R7: 72500 | S7: 72500 | T7: 290000 | U7: 290000 | V7: 290000 | W7: 290000
A8: seniorS&Mexe (CL) | B8: i | C8: base_salary | D8: cl | I8: 0 | J8: 75000 | L8: 0 | M8: 0 | N8: 0 | O8: 0 | P8: 75000 | Q8: 75000 | R8: 75000 | S8: 75000 | T8: 300000 | U8: 300000 | V8: 300000 | W8: 300000
A9: Senior Associate (RF) | B9: i | C9: base_salary | D9: rf | I9: 37500 | J9: 40000 | L9: 37500 | M9: 37500 | N9: 37500 | O9: 37500 | P9: 40000 | Q9: 40000 | R9: 40000 | S9: 40000 | T9: 160000 | U9: 160000 | V9: 160000 | W9: 160000
A10: associate (MT) | B10: i | C10: base_salary | D10: mt | I10: 27500 | J10: 27500 | L10: 27500 | M10: 27500 | N10: 27500 | O10: 27500 | P10: 27500 | Q10: 27500 | R10: 27500 | S10: 27500 | T10: 110000 | U10: 110000 | V10: 110000 | W10: 110000
A11: project manager | B11: i | C11: base_salary | D11: project | I11: 0 | J11: 0 | L11: 0 | M11: 0 | N11: 0 | O11: 0 | P11: 0 | Q11: 0 | R11: 37500 | S11: 37500 | T11: 150000 | U11: 150000 | V11: 150000 | W11: 150000
A12: Total | I12: 258750 | J12: 340000 | L12: =SUM(L6:L11) -> 258750 | M12: =SUM(M6:M11) -> 258750 | N12: =SUM(N6:N11) -> 258750 | O12: =SUM(O6:O11) -> 258750 | P12: =SUM(P6:P11) -> 340000 | Q12: =SUM(Q6:Q11) -> 340000 | R12: =SUM(R6:R11) -> 377500 | S12: =SUM(S6:S11) -> 377500 | ... W12: =SUM(W6:W11) -> 1510000
A14: Bonus
A15: =A6 -> ACEO Loren Hotels (CE) | B15: i | C15: bonus | D15: ce | I15: 250000 | J15: 0 | L15: 0 | M15: 0 | N15: 0 | O15: 250000 | P15: 0 | Q15: 0 | R15: 0 | S15: 250000 | T15: 500000 | U15: 500000 | V15: 500000 | W15: 500000
A16: =A7 -> VP Operations (WS) | B16: i | C16: bonus | D16: ws | I16: 115000 | J16: 0 | L16: 0 | M16: 0 | N16: 0 | O16: 115000 | P16: 0 | Q16: 0 | R16: 0 | S16: 75000 | T16: 75000 | U16: 75000 | V16: 75000 | W16: 75000
A17: =A8 -> seniorS&Mexe (CL) | B17: i | C17: bonus | D17: cl | I17: 20000 | J17: 0 | L17: 0 | M17: 0 | N17: 0 | O17: 20000 | P17: 0 | Q17: 0 | R17: 0 | S17: 75000 | T17: 75000 | U17: 75000 | V17: 75000 | W17: 75000
A18: =A9 -> Senior Associate (RF) | B18: i | C18: bonus | D18: rf | I18: 50000 | J18: 0 | L18: 0 | M18: 0 | N18: 0 | O18: 50000 | P18: 0 | Q18: 0 | R18: 0 | S18: 50000 | T18: 50000 | U18: 50000 | V18: 50000 | W18: 50000
A19: =A10 -> associate (MT) | B19: i | C19: bonus | D19: mt | I19: 20000 | J19: 0 | L19: 0 | M19: 0 | N19: 0 | O19: 20000 | P19: 0 | Q19: 0 | R19: 0 | S19: 40000 | T19: 40000 | U19: 40000 | V19: 40000 | W19: 40000
A20: =A11 -> project manager | B20: i | C20: bonus | D20: project | I20: 0 | J20: 0 | L20: 0 | M20: 0 | N20: 0 | O20: 0 | P20: 0 | Q20: 0 | R20: 0 | S20: 5000 | T20: 10000 | U20: 10000 | V20: 10000 | W20: 10000
A21: Total | I21: 455000 | J21: 0 | L21: =SUM(L15:L20) -> 0 | M21: =SUM(M15:M20) -> 0 | N21: =SUM(N15:N20) -> 0 | O21: =SUM(O15:O20) -> 455000 | P21: =SUM(P15:P20) -> 0 | Q21: =SUM(Q15:Q20) -> 0 | R21: =SUM(R15:R20) -> 0 | S21: =SUM(S15:S20) -> 495000 | ... W21: =SUM(W15:W20) -> 750000
A23: Total Salaries
A24: =A15 -> ACEO Loren Hotels (CE) | B24: c | C24: total_salary | D24: ce | I24: 403750 | J24: 144000 | L24: =L6*(1+'.c12_inputs.hr'!$E$8)+(L15*(1+'.c12_inputs.hr'!$E$9)) -> 144000 | M24: =M6*(1+'.c12_inputs.hr'!$E$8)+(M15*(1+'.c12_inputs.hr'!$E$9)) -> 144000 | N24: =N6*(1+'.c12_inputs.hr'!$E$8)+(N15*(1+'.c12_inputs.hr'!$E$9)) -> 144000 | O24: =O6*(1+'.c12_inputs.hr'!$E$8)+(O15*(1+'.c12_inputs.hr'!$E$9)) -> 403750 | P24: =P6*(1+'.c12_inputs.hr'!$E$8)+(P15*(1+'.c12_inputs.hr'!$E$9)) -> 144000 | Q24: =Q6*(1+'.c12_inputs.hr'!$E$8)+(Q15*(1+'.c12_inputs.hr'!$E$9)) -> 144000 | R24: =R6*(1+'.c12_inputs.hr'!$E$8)+(R15*(1+'.c12_inputs.hr'!$E$9)) -> 144000 | S24: =S6*(1+'.c12_inputs.hr'!$E$8)+(S15*(1+'.c12_inputs.hr'!$E$9)) -> 403750 | ... W24: =W6*(1+'.c12_inputs.hr'!$E$8)+(W15*(1+'.c12_inputs.hr'!$E$9)) -> 1095500
A25: =A16 -> VP Operations (WS) | B25: c | C25: total_salary | D25: ws | I25: 198685 | J25: 83520 | L25: =L7*(1+'.c12_inputs.hr'!$E$8)+(L16*(1+'.c12_inputs.hr'!$E$9)) -> 79200 | M25: =M7*(1+'.c12_inputs.hr'!$E$8)+(M16*(1+'.c12_inputs.hr'!$E$9)) -> 79200 | N25: =N7*(1+'.c12_inputs.hr'!$E$8)+(N16*(1+'.c12_inputs.hr'!$E$9)) -> 79200 | O25: =O7*(1+'.c12_inputs.hr'!$E$8)+(O16*(1+'.c12_inputs.hr'!$E$9)) -> 198685 | P25: =P7*(1+'.c12_inputs.hr'!$E$8)+(P16*(1+'.c12_inputs.hr'!$E$9)) -> 83520 | Q25: =Q7*(1+'.c12_inputs.hr'!$E$8)+(Q16*(1+'.c12_inputs.hr'!$E$9)) -> 83520 | R25: =R7*(1+'.c12_inputs.hr'!$E$8)+(R16*(1+'.c12_inputs.hr'!$E$9)) -> 83520 | S25: =S7*(1+'.c12_inputs.hr'!$E$8)+(S16*(1+'.c12_inputs.hr'!$E$9)) -> 161445 | ... W25: =W7*(1+'.c12_inputs.hr'!$E$8)+(W16*(1+'.c12_inputs.hr'!$E$9)) -> 412005
A26: =A17 -> seniorS&Mexe (CL) | B26: c | C26: total_salary | D26: cl | I26: 20780 | J26: 86400 | L26: =L8*(1+'.c12_inputs.hr'!$E$8)+(L17*(1+'.c12_inputs.hr'!$E$9)) -> 0 | M26: =M8*(1+'.c12_inputs.hr'!$E$8)+(M17*(1+'.c12_inputs.hr'!$E$9)) -> 0 | N26: =N8*(1+'.c12_inputs.hr'!$E$8)+(N17*(1+'.c12_inputs.hr'!$E$9)) -> 0 | O26: =O8*(1+'.c12_inputs.hr'!$E$8)+(O17*(1+'.c12_inputs.hr'!$E$9)) -> 20780 | P26: =P8*(1+'.c12_inputs.hr'!$E$8)+(P17*(1+'.c12_inputs.hr'!$E$9)) -> 86400 | Q26: =Q8*(1+'.c12_inputs.hr'!$E$8)+(Q17*(1+'.c12_inputs.hr'!$E$9)) -> 86400 | R26: =R8*(1+'.c12_inputs.hr'!$E$8)+(R17*(1+'.c12_inputs.hr'!$E$9)) -> 86400 | S26: =S8*(1+'.c12_inputs.hr'!$E$8)+(S17*(1+'.c12_inputs.hr'!$E$9)) -> 164325 | ... W26: =W8*(1+'.c12_inputs.hr'!$E$8)+(W17*(1+'.c12_inputs.hr'!$E$9)) -> 423525
A27: =A18 -> Senior Associate (RF) | B27: c | C27: total_salary | D27: rf | I27: 95150 | J27: 46080 | L27: =L9*(1+'.c12_inputs.hr'!$E$8)+(L18*(1+'.c12_inputs.hr'!$E$9)) -> 43200 | M27: =M9*(1+'.c12_inputs.hr'!$E$8)+(M18*(1+'.c12_inputs.hr'!$E$9)) -> 43200 | N27: =N9*(1+'.c12_inputs.hr'!$E$8)+(N18*(1+'.c12_inputs.hr'!$E$9)) -> 43200 | O27: =O9*(1+'.c12_inputs.hr'!$E$8)+(O18*(1+'.c12_inputs.hr'!$E$9)) -> 95150 | P27: =P9*(1+'.c12_inputs.hr'!$E$8)+(P18*(1+'.c12_inputs.hr'!$E$9)) -> 46080 | Q27: =Q9*(1+'.c12_inputs.hr'!$E$8)+(Q18*(1+'.c12_inputs.hr'!$E$9)) -> 46080 | R27: =R9*(1+'.c12_inputs.hr'!$E$8)+(R18*(1+'.c12_inputs.hr'!$E$9)) -> 46080 | S27: =S9*(1+'.c12_inputs.hr'!$E$8)+(S18*(1+'.c12_inputs.hr'!$E$9)) -> 98030 | ... W27: =W9*(1+'.c12_inputs.hr'!$E$8)+(W18*(1+'.c12_inputs.hr'!$E$9)) -> 236270
A28: =A19 -> associate (MT) | B28: c | C28: total_salary | D28: mt | I28: 52460 | J28: 31680 | L28: =L10*(1+'.c12_inputs.hr'!$E$8)+(L19*(1+'.c12_inputs.hr'!$E$9)) -> 31680 | M28: =M10*(1+'.c12_inputs.hr'!$E$8)+(M19*(1+'.c12_inputs.hr'!$E$9)) -> 31680 | N28: =N10*(1+'.c12_inputs.hr'!$E$8)+(N19*(1+'.c12_inputs.hr'!$E$9)) -> 31680 | O28: =O10*(1+'.c12_inputs.hr'!$E$8)+(O19*(1+'.c12_inputs.hr'!$E$9)) -> 52460 | P28: =P10*(1+'.c12_inputs.hr'!$E$8)+(P19*(1+'.c12_inputs.hr'!$E$9)) -> 31680 | Q28: =Q10*(1+'.c12_inputs.hr'!$E$8)+(Q19*(1+'.c12_inputs.hr'!$E$9)) -> 31680 | R28: =R10*(1+'.c12_inputs.hr'!$E$8)+(R19*(1+'.c12_inputs.hr'!$E$9)) -> 31680 | S28: =S10*(1+'.c12_inputs.hr'!$E$8)+(S19*(1+'.c12_inputs.hr'!$E$9)) -> 73240 | ... W28: =W10*(1+'.c12_inputs.hr'!$E$8)+(W19*(1+'.c12_inputs.hr'!$E$9)) -> 168280
A29: =A20 -> project manager | B29: c | C29: total_salary | D29: project | I29: 0 | J29: 0 | L29: =L11*(1+'.c12_inputs.hr'!$E$8)+(L20*(1+'.c12_inputs.hr'!$E$9)) -> 0 | M29: =M11*(1+'.c12_inputs.hr'!$E$8)+(M20*(1+'.c12_inputs.hr'!$E$9)) -> 0 | N29: =N11*(1+'.c12_inputs.hr'!$E$8)+(N20*(1+'.c12_inputs.hr'!$E$9)) -> 0 | O29: =O11*(1+'.c12_inputs.hr'!$E$8)+(O20*(1+'.c12_inputs.hr'!$E$9)) -> 0 | P29: =P11*(1+'.c12_inputs.hr'!$E$8)+(P20*(1+'.c12_inputs.hr'!$E$9)) -> 0 | Q29: =Q11*(1+'.c12_inputs.hr'!$E$8)+(Q20*(1+'.c12_inputs.hr'!$E$9)) -> 0 | R29: =R11*(1+'.c12_inputs.hr'!$E$8)+(R20*(1+'.c12_inputs.hr'!$E$9)) -> 43200 | S29: =S11*(1+'.c12_inputs.hr'!$E$8)+(S20*(1+'.c12_inputs.hr'!$E$9)) -> 48395 | ... W29: =W11*(1+'.c12_inputs.hr'!$E$8)+(W20*(1+'.c12_inputs.hr'!$E$9)) -> 183190
A31: Grand Total | B31: o | C31: hr_grand_total | I31: 770825 | J31: 391680 | L31: =SUM(L24:L29) -> 298080 | M31: =SUM(M24:M29) -> 298080 | N31: =SUM(N24:N29) -> 298080 | O31: =SUM(O24:O29) -> 770825 | P31: =SUM(P24:P29) -> 391680 | Q31: =SUM(Q24:Q29) -> 391680 | R31: =SUM(R24:R29) -> 434880 | S31: =SUM(S24:S29) -> 949185 | ... W31: =SUM(W24:W29) -> 2518770
A32: reimbersable to hotel | B32: o | C32: hr_reimbursable | I32: 367075 | J32: 247680 | L32: =SUMPRODUCT('.c12_alloc'!$H$15:$H$20,'.c12_hm_hr'!L$24:L$29) -> 154080 | M32: =SUMPRODUCT('.c12_alloc'!$H$15:$H$20,'.c12_hm_hr'!M$24:M$29) -> 154080 | N32: =SUMPRODUCT('.c12_alloc'!$H$15:$H$20,'.c12_hm_hr'!N$24:N$29) -> 154080 | O32: =SUMPRODUCT('.c12_alloc'!$H$15:$H$20,'.c12_hm_hr'!O$24:O$29) -> 367075 | P32: =SUMPRODUCT('.c12_alloc'!$H$15:$H$20,'.c12_hm_hr'!P$24:P$29) -> 247680 | Q32: =SUMPRODUCT('.c12_alloc'!$H$15:$H$20,'.c12_hm_hr'!Q$24:Q$29) -> 247680 | R32: =SUMPRODUCT('.c12_alloc'!$H$15:$H$20,'.c12_hm_hr'!R$24:R$29) -> 290880 | S32: =SUMPRODUCT('.c12_alloc'!$H$15:$H$20,'.c12_hm_hr'!S$24:S$29) -> 545435 | ... W32: =SUMPRODUCT('.c12_alloc'!$H$15:$H$20,'.c12_hm_hr'!W$24:W$29) -> 1423270
A33: not reimbersable by hotel, but paid by lgh | B33: o | C33: hr_not_reimbursable | I33: 403750 | J33: 144000 | L33: =SUMPRODUCT('.c12_alloc'!$G$15:$G$20,'.c12_hm_hr'!L$24:L$29) -> 144000 | M33: =SUMPRODUCT('.c12_alloc'!$G$15:$G$20,'.c12_hm_hr'!M$24:M$29) -> 144000 | N33: =SUMPRODUCT('.c12_alloc'!$G$15:$G$20,'.c12_hm_hr'!N$24:N$29) -> 144000 | O33: =SUMPRODUCT('.c12_alloc'!$G$15:$G$20,'.c12_hm_hr'!O$24:O$29) -> 403750 | P33: =SUMPRODUCT('.c12_alloc'!$G$15:$G$20,'.c12_hm_hr'!P$24:P$29) -> 144000 | Q33: =SUMPRODUCT('.c12_alloc'!$G$15:$G$20,'.c12_hm_hr'!Q$24:Q$29) -> 144000 | R33: =SUMPRODUCT('.c12_alloc'!$G$15:$G$20,'.c12_hm_hr'!R$24:R$29) -> 144000 | S33: =SUMPRODUCT('.c12_alloc'!$G$15:$G$20,'.c12_hm_hr'!S$24:S$29) -> 403750 | ... W33: =SUMPRODUCT('.c12_alloc'!$G$15:$G$20,'.c12_hm_hr'!W$24:W$29) -> 1095500
A34: only paid by c12 | B34: o | C34: hr_only_c12 | I34: 0 | J34: 0 | L34: =SUMPRODUCT('.c12_alloc'!$E$15:$E$20,'.c12_hm_hr'!L$24:L$29) -> 0 | M34: =SUMPRODUCT('.c12_alloc'!$E$15:$E$20,'.c12_hm_hr'!M$24:M$29) -> 0 | N34: =SUMPRODUCT('.c12_alloc'!$E$15:$E$20,'.c12_hm_hr'!N$24:N$29) -> 0 | O34: =SUMPRODUCT('.c12_alloc'!$E$15:$E$20,'.c12_hm_hr'!O$24:O$29) -> 0 | P34: =SUMPRODUCT('.c12_alloc'!$E$15:$E$20,'.c12_hm_hr'!P$24:P$29) -> 0 | Q34: =SUMPRODUCT('.c12_alloc'!$E$15:$E$20,'.c12_hm_hr'!Q$24:Q$29) -> 0 | R34: =SUMPRODUCT('.c12_alloc'!$E$15:$E$20,'.c12_hm_hr'!R$24:R$29) -> 0 | S34: =SUMPRODUCT('.c12_alloc'!$E$15:$E$20,'.c12_hm_hr'!S$24:S$29) -> 0 | ... W34: =SUMPRODUCT('.c12_alloc'!$E$15:$E$20,'.c12_hm_hr'!W$24:W$29) -> 0

Sheet .c12_d&s_hr
A2: Year | E2: 45657 | F2: 45747 | G2: 45838 | H2: 45930 | I2: 46022 | J2: 46112 | K2: 46203 | L2: 45747 | M2: 45838 | N2: 45930 | O2: 46022 | P2: 46112 | Q2: 46203 | R2: 46295 | S2: 46387 | T2: 46752 | U2: 47118 | V2: 47483 | W2: 47848
E3: actual | L3: i/o
B4: i/o | C4: field_name | D4: index
A5: base
A6: HODS (RB) | B6: i | C6: base_salary | D6: rb | I6: 87500 | J6: 187500 | L6: 87500 | M6: 87500 | N6: 87500 | O6: 87500 | P6: 187500 | Q6: 187500 | R6: 187500 | S6: 187500 | T6: 750000 | U6: 750000 | V6: 750000 | W6: 750000
A7: Project Executive (LS) (100%) | B7: i | C7: base_salary | D7: ls | I7: 46250 | J7: 46250 | L7: 46250 | M7: 46250 | N7: 46250 | O7: 46250 | P7: 46250 | Q7: 46250 | R7: 46250 | S7: 46250 | T7: 185000 | U7: 185000 | V7: 185000 | W7: 185000
A8: Project Manager (BD) (100%) | B8: i | C8: base_salary | D8: bd | I8: 27500 | J8: 28125 | L8: 27500 | M8: 27500 | N8: 27500 | O8: 27500 | P8: 28125 | Q8: 28125 | R8: 28125 | S8: 28125 | T8: 112500 | U8: 112500 | V8: 112500 | W8: 112500
A9: Counsel (KT) | B9: i | C9: base_salary | D9: kt | I9: 62500 | J9: 65000 | L9: 62500 | M9: 62500 | N9: 62500 | O9: 62500 | P9: 65000 | Q9: 65000 | R9: 65000 | S9: 65000 | T9: 260000 | U9: 260000 | V9: 260000 | W9: 260000
A10: Development Manager??? (alexi?) | B10: i | C10: base_salary | D10: development | I10: 0 | J10: 0 | L10: 43750 | M10: 43750 | N10: 43750 | O10: 0 | P10: 0 | Q10: 0 | R10: 0 | S10: 0 | T10: 0 | U10: 0 | V10: 0 | W10: 0
A11: Banker (tBD) | B11: i | C11: base_salary | D11: banker | I11: 75000 | J11: 0 | L11: 75000 | M11: 75000 | N11: 75000 | O11: 75000 | P11: 0 | Q11: 0 | R11: 0 | S11: 0 | T11: 0 | U11: 0 | V11: 0 | W11: 0
A12: Senior Design Manager (AM) | B12: i | C12: base_salary | D12: am | I12: 45000 | J12: 47500 | L12: 45000 | M12: 45000 | N12: 45000 | O12: 45000 | P12: 47500 | Q12: 47500 | R12: 47500 | S12: 47500 | T12: 190000 | U12: 190000 | V12: 190000 | W12: 190000
A13: Design Manager (AL) (gone) | B13: i | C13: base_salary | D13: al | I13: 32500 | J13: 34375 | L13: 32500 | M13: 32500 | N13: 32500 | O13: 32500 | P13: 34375 | Q13: 0 | R13: 0 | S13: 0 | T13: 0 | U13: 0 | V13: 0 | W13: 0
A14: new design manager (TBD) | B14: i | C14: base_salary | D14: tbd | I14: 0 | J14: 0 | L14: 0 | M14: 0 | N14: 0 | O14: 0 | P14: 0 | Q14: 0 | R14: 34375 | S14: 34375 | T14: 137500 | U14: 137500 | V14: 137500 | W14: 137500
A15: FF&E (SB) | B15: i | C15: base_salary | D15: sb | I15: 27500 | J15: 27500 | L15: 27500 | M15: 27500 | N15: 27500 | O15: 27500 | P15: 27500 | Q15: 27500 | R15: 27500 | S15: 27500 | T15: 110000 | U15: 110000 | V15: 110000 | W15: 110000
A16: Senior Financial Analyst (KS) | B16: i | C16: base_salary | D16: ks | J16: 50000 | P16: 50000 | Q16: 50000 | R16: 50000 | S16: 50000 | T16: 200000 | U16: 200000 | V16: 200000 | W16: 200000
A17: Total | I17: 403750 | J17: 486250 | L17: =SUM(L6:L16) -> 447500 | M17: =SUM(M6:M16) -> 447500 | N17: =SUM(N6:N16) -> 447500 | O17: =SUM(O6:O16) -> 403750 | P17: =SUM(P6:P16) -> 486250 | Q17: =SUM(Q6:Q16) -> 451875 | R17: =SUM(R6:R16) -> 486250 | S17: =SUM(S6:S16) -> 486250 | ... W17: =SUM(W6:W16) -> 1945000
A19: Bonus
