Workbook
Name DepartmentNum: '.c12_inputs.hr'!$E$4

Sheet registry
A1: Year | B1: =+lgh_bs!D2 -> 45657 | C1: =+lgh_bs!E2 -> 45747 | D1: =+lgh_bs!F2 -> 45838 | E1: =+lgh_bs!G2 -> 45930 | F1: =+lgh_bs!H2 -> 46022 | G1: =+lgh_bs!I2 -> 46112 | H1: =+lgh_bs!J2 -> 46203 | I1: =+lgh_bs!K2 -> 46295 | ... N1: =+lgh_bs!P2 -> 47848
A2: subcategory | B2: =+lgh_bs!D3 -> Q4 | C2: =+lgh_bs!E3 -> Q1 | D2: =+lgh_bs!F3 -> Q2 | E2: =+lgh_bs!G3 -> Q3 | F2: =+lgh_bs!H3 -> Q4 | G2: =+lgh_bs!I3 -> Q1 | H2: =+lgh_bs!J3 -> Q2 | I2: =+lgh_bs!K3 -> Q3 | ... N2: =+lgh_bs!P3 -> Q4
A5: Cash Inflows | B5: =+pink_cs2!B17 -> 1562074 | C5: =+pink_cs2!C17 -> 3250000 | D5: =+pink_cs2!D17 -> 3388588 | E5: =+pink_cs2!E17 -> 1475962 | F5: =+pink_cs2!F17 -> 8336733 | G5: =+pink_cs2!G17 -> 0 | H5: =+pink_cs2!H17 -> 0 | I5: =+pink_cs2!I17 -> 0 | ... N5: =+pink_cs2!N17 -> 4123684
A6: Cash Outflows | B6: =+pink_cs2!B25 -> 0 | C6: =+pink_cs2!C25 -> -125000 | D6: =+pink_cs2!D25 -> -3717883 | E6: =+pink_cs2!E25 -> -3472013.3 | F6: =+pink_cs2!F25 -> 0 | G6: =+pink_cs2!G25 -> 0 | H6: =+pink_cs2!H25 -> 0 | I6: =+pink_cs2!I25 -> 0 | ... N6: =+pink_cs2!N25 -> 0
A7: Net Asset Value (NAV) | B7: =+pink_cs2!B60 -> 56391899 | C7: =+pink_cs2!C60 -> 48342875 | D7: =+pink_cs2!D60 -> 49230680 | E7: =+pink_cs2!E60 -> 51936303 | F7: =+pink_cs2!F60 -> 46803857 | G7: =+pink_cs2!G60 -> 46688396 | H7: =+pink_cs2!H60 -> 47318459 | I7: =+pink_cs2!I60 -> 47193849 | ... N7: =+pink_cs2!N60 -> 85421360
A10: Cash Inflows | B10: =+aus_cs2!E19 -> 814451.63 | C10: =+aus_cs2!F19 -> 5515000 | D10: =+aus_cs2!G19 -> 0 | E10: =+aus_cs2!H19 -> 525000 | F10: =+aus_cs2!I19 -> 0 | G10: =+aus_cs2!J19 -> 0 | H10: =+aus_cs2!K19 -> 0 | I10: =+aus_cs2!L19 -> 0 | ... N10: =+aus_cs2!Q19 -> 0
A11: Cash Outflows | B11: =+aus_cs2!E28 -> 0 | C11: =+aus_cs2!F28 -> -50000 | D11: =+aus_cs2!G28 -> -2025000 | E11: =+aus_cs2!H28 -> -230000 | F11: =+aus_cs2!I28 -> -289495 | G11: =+aus_cs2!J28 -> -1750000 | H11: =+aus_cs2!K28 -> -3420000 | I11: =+aus_cs2!L28 -> 0 | ... N11: =+aus_cs2!Q28 -> 0
A12: LGH NAV | B12: =+aus_cs2!E75 -> 15926855 | C12: =+aus_cs2!F75 -> 18088592 | D12: =+aus_cs2!G75 -> 17359150 | E12: =+aus_cs2!H75 -> 15109714 | F12: =+aus_cs2!I75 -> 7753407.4 | G12: =+aus_cs2!J75 -> 6038275.4 | H12: =+aus_cs2!K75 -> 4849926.1 | I12: =+aus_cs2!L75 -> 3974250.2 | ... N12: =+aus_cs2!Q75 -> 0
A13: Mezz Owned | B13: =+aus_cs2!E80 -> 8621252.7 | C13: =+aus_cs2!F80 -> 2691709.1 | D13: =+aus_cs2!G80 -> 2849465 | E13: =+aus_cs2!H80 -> 3017222.8 | F13: =+aus_cs2!I80 -> 4124556.9 | G13: =+aus_cs2!J80 -> 4237689.3 | H13: =+aus_cs2!K80 -> 6873678.2 | I13: =+aus_cs2!L80 -> 7084139.4 | ... N13: =+aus_cs2!Q80 -> 42318729
A14: Pref Owned | B14: =+aus_cs2!E83 -> 5608281.4 | C14: =+aus_cs2!F83 -> 5792434.5 | D14: =+aus_cs2!G83 -> 5984782.4 | E14: =+aus_cs2!H83 -> 6185737.8 | F14: =+aus_cs2!I83 -> 6393440.8 | G14: =+aus_cs2!J83 -> 6603375.3 | H14: =+aus_cs2!K83 -> 6822651.9 | I14: =+aus_cs2!L83 -> 7051741.1 | ... N14: =+aus_cs2!Q83 -> 4764456.8
A15: Net Asset Value (NAV) | B15: =+aus_cs2!E85 -> 30156389 | C15: =+aus_cs2!F85 -> 26572736 | D15: =+aus_cs2!G85 -> 26193398 | E15: =+aus_cs2!H85 -> 24312675 | F15: =+aus_cs2!I85 -> 6321102 | G15: =+aus_cs2!J85 -> 6506360 | H15: =+aus_cs2!K85 -> 9217684.1 | I15: =+aus_cs2!L85 -> 9506851.6 | ... N15: =+aus_cs2!Q85 -> 47083185
A16: Pref Liquidation adj. | B16: =+aus_cs2!E84-aus_cs2!E83 -> 0 | C16: =+aus_cs2!F84-aus_cs2!F83 -> 0 | D16: =+aus_cs2!G84-aus_cs2!G83 -> 0 | E16: =+aus_cs2!H84-aus_cs2!H83 -> 0 | F16: =+aus_cs2!I84-aus_cs2!I83 -> -4196895.7 | G16: =+aus_cs2!J84-aus_cs2!J83 -> -4334704.6 | H16: =+aus_cs2!K84-aus_cs2!K83 -> -4478646.1 | I16: =+aus_cs2!L84-aus_cs2!L83 -> -4629028.8 | ... N16: =+aus_cs2!Q84-aus_cs2!Q83 -> 0
A17: Equity Liquidation adj. | B17: =+aus_cs2!E76-aus_cs2!E75 -> 0 | C17: =+aus_cs2!F76-aus_cs2!F75 -> 0 | D17: =+aus_cs2!G76-aus_cs2!G75 -> 0 | E17: =+aus_cs2!H76-aus_cs2!H75 -> 0 | F17: =+aus_cs2!I76-aus_cs2!I75 -> -7753407.4 | G17: =+aus_cs2!J76-aus_cs2!J75 -> -6038275.4 | H17: =+aus_cs2!K76-aus_cs2!K75 -> -4849926.1 | I17: =+aus_cs2!L76-aus_cs2!L75 -> -3974250.2 | ... N17: =+aus_cs2!Q76-aus_cs2!Q75 -> 0
B18: 0 | C18: =-aus_cs2!F64 -> 215000 | D18: =-aus_cs2!G64 -> 289000 | E18: =-aus_cs2!H64 -> 0 | F18: =-aus_cs2!I64 -> 289495 | G18: =-aus_cs2!J64 -> 1289495 | H18: =-aus_cs2!K64 -> 1909495 | I18: =-aus_cs2!L64 -> 1909495 | J18: =-aus_cs2!M64 -> 2659495 | ... N18: =-aus_cs2!Q64 -> 0
A21: Cash Inflows | B21: =+turks_cs2!B20 -> 0 | C21: =+turks_cs2!C20 -> 0 | D21: =+turks_cs2!D20 -> 0 | E21: =+turks_cs2!E20 -> 0 | F21: =+turks_cs2!F20 -> 350000 | G21: =+turks_cs2!G20 -> 0 | H21: =+turks_cs2!H20 -> 350000 | I21: =+turks_cs2!I20 -> 0 | ... N21: =+turks_cs2!N20 -> 1371287
A22: Cash Outflows | B22: =+turks_cs2!B27 -> 0 | C22: =+turks_cs2!C27 -> -382967 | D22: =+turks_cs2!D27 -> -2326328 | E22: =+turks_cs2!E27 -> -3292886 | F22: =+turks_cs2!F27 -> -5106622 | G22: =+turks_cs2!G27 -> -420000 | H22: =+turks_cs2!H27 -> -200000 | I22: =+turks_cs2!I27 -> -150000 | ... N22: =+turks_cs2!N27 -> 0
A23: LGH NAV | B23: =+turks_cs2!B70 -> 30602658 | C23: =+turks_cs2!C70 -> 35723216 | D23: =+turks_cs2!D70 -> 38565928 | E23: =+turks_cs2!E70 -> 40379581 | F23: =+turks_cs2!F70 -> 40032701 | G23: =+turks_cs2!G70 -> 36265000 | H23: =+turks_cs2!H70 -> 38900747 | I23: =+turks_cs2!I70 -> 41760245 | ... N23: =+turks_cs2!N70 -> 37231193
A26: Cash Inflows | B26: =+frith_cs2!B17 -> 0 | C26: =+frith_cs2!C17 -> 0 | D26: =+frith_cs2!D17 -> 0 | E26: =+frith_cs2!E17 -> 0 | F26: =+frith_cs2!F17 -> 0 | G26: =+frith_cs2!G17 -> 2400000 | H26: =+frith_cs2!H17 -> 3600000 | I26: =+frith_cs2!I17 -> 0 | ... N26: =+frith_cs2!N17 -> 0
A27: Cash Outflows | B27: =+frith_cs2!B24 -> 0 | C27: =+frith_cs2!C24 -> 0 | D27: =+frith_cs2!D24 -> 0 | E27: =+frith_cs2!E24 -> 0 | F27: =+frith_cs2!F24 -> -860000 | G27: =+frith_cs2!G24 -> 0 | H27: =+frith_cs2!H24 -> -1750000 | I27: =+frith_cs2!I24 -> 0 | ... N27: =+frith_cs2!N24 -> 0
A28: LGH NAV | B28: =+frith_cs2!B60 -> 0 | C28: =+frith_cs2!C60 -> 11353680 | D28: =+frith_cs2!D60 -> 13799240 | E28: =+frith_cs2!E60 -> 15549103 | F28: =+frith_cs2!F60 -> 15839974 | G28: =+frith_cs2!G60 -> 15929659 | H28: =+frith_cs2!H60 -> 15182357 | I28: =+frith_cs2!I60 -> 17072720 | ... N28: =+frith_cs2!N60 -> 0
A31: Cash Inflows | B31: =+elbow_cs2!B18 -> 0 | C31: =+elbow_cs2!C18 -> 0 | D31: =+elbow_cs2!D18 -> 2500000 | E31: =+elbow_cs2!E18 -> 2500000 | F31: =+elbow_cs2!F18 -> 6137500 | G31: =+elbow_cs2!G18 -> 5640000 | H31: =+elbow_cs2!H18 -> 7300000 | I31: =+elbow_cs2!I18 -> 0 | ... N31: =+elbow_cs2!N18 -> 0
A32: Cash Outflows | B32: =+elbow_cs2!B24 -> 0 | C32: =+elbow_cs2!C24 -> -2500000 | D32: =+elbow_cs2!D24 -> 0 | E32: =+elbow_cs2!E24 -> 0 | F32: =+elbow_cs2!F24 -> 0 | G32: =+elbow_cs2!G24 -> -1000000 | H32: =+elbow_cs2!H24 -> -2040000 | I32: =+elbow_cs2!I24 -> -2000000 | ... N32: =+elbow_cs2!N24 -> 0
A33: LGH NAV | B33: =+elbow_cs2!B53 -> 5000000 | C33: =+elbow_cs2!C53 -> 17383391 | D33: =+elbow_cs2!D53 -> 19070671 | E33: =+elbow_cs2!E53 -> 20943032 | F33: =+elbow_cs2!F53 -> 22999222 | G33: =+elbow_cs2!G53 -> 28009536 | H33: =+elbow_cs2!H53 -> 30460557 | I33: =+elbow_cs2!I53 -> 33156609 | ... N33: =+elbow_cs2!N53 -> 104879625
B36: =sat_cs2!B24 -> 0 | C36: =sat_cs2!C24 -> 0 | D36: =sat_cs2!D24 -> 0 | E36: =sat_cs2!E24 -> 0 | F36: =sat_cs2!F24 -> 0 | G36: =sat_cs2!G24 -> 0 | H36: =sat_cs2!H24 -> 0 | I36: =sat_cs2!I24 -> 0 | ... N36: =sat_cs2!N24 -> 1750000
B37: =sat_cs2!B17 -> 0 | C37: =sat_cs2!C17 -> 0 | D37: =sat_cs2!D17 -> 0 | E37: =sat_cs2!E17 -> 0 | F37: =sat_cs2!F17 -> 0 | G37: =sat_cs2!G17 -> 0 | H37: =sat_cs2!H17 -> 0 | I37: =sat_cs2!I17 -> 0 | ... N37: =sat_cs2!N17 -> 0
A42: Division Expenses
A43: Guarentee Fees | B43: =-(+pink_cs2!B$31+elbow_cs2!B$29+aus_cs2!E$33+turks_cs2!B$32+frith_cs2!B$29) -> 0 | C43: =-(+pink_cs2!C$31+elbow_cs2!C$29+aus_cs2!F$33+turks_cs2!C$32+frith_cs2!C$29) -> 0 | D43: =-(+pink_cs2!D$31+elbow_cs2!D$29+aus_cs2!G$33+turks_cs2!D$32+frith_cs2!D$29) -> 0 | E43: =-(+pink_cs2!E$31+elbow_cs2!E$29+aus_cs2!H$33+turks_cs2!E$32+frith_cs2!E$29) -> 0 | F43: =-(+pink_cs2!F$31+elbow_cs2!F$29+aus_cs2!I$33+turks_cs2!F$32+frith_cs2!F$29) -> 0 | G43: =-(+pink_cs2!G$31+elbow_cs2!G$29+aus_cs2!J$33+turks_cs2!G$32+frith_cs2!G$29) -> 0 | H43: =-(+pink_cs2!H$31+elbow_cs2!H$29+aus_cs2!K$33+turks_cs2!H$32+frith_cs2!H$29) -> 0 | I43: =-(+pink_cs2!I$31+elbow_cs2!I$29+aus_cs2!L$33+turks_cs2!I$32+frith_cs2!I$29) -> 0 | ... N43: =-(+pink_cs2!N$31+elbow_cs2!N$29+aus_cs2!Q$33+turks_cs2!N$32+frith_cs2!N$29) -> 0
A46: Total LGH HM Fees | B46: =+'c12_hm'!E60 -> 0 | C46: =+'c12_hm'!F60 -> 721136.47 | D46: =+'c12_hm'!G60 -> 721136.47 | E46: =+'c12_hm'!H60 -> 721136.47 | F46: =+'c12_hm'!I60 -> 833991.74 | G46: =+'c12_hm'!J60 -> 310715.79 | H46: =+'c12_hm'!K60 -> 902637.29 | I46: =+'c12_hm'!L60 -> 948110.97 | ... N46: =+'c12_hm'!Q60 -> 8232870
A47: c12 Participation | B47: =+'c12_hm'!E70 -> 0 | C47: =+'c12_hm'!F70 -> 567056.47 | D47: =+'c12_hm'!G70 -> 567056.47 | E47: =+'c12_hm'!H70 -> 567056.47 | F47: =+'c12_hm'!I70 -> 466916.74 | G47: =+'c12_hm'!J70 -> 63035.789 | H47: =+'c12_hm'!K70 -> 398173.65 | I47: =+'c12_hm'!L70 -> 400447.34 | ... N47: =+'c12_hm'!Q70 -> 2432050.8
A49: PV Loren fees (Key money) | B49: =+lgh_manco!C8 -> 20000000 | C49: =+lgh_manco!D8 -> 20000000 | D49: =+lgh_manco!E8 -> 20000000 | E49: =+lgh_manco!F8 -> 20000000 | F49: =+lgh_manco!G8 -> 20000000 | G49: =+lgh_manco!H8 -> 20600000 | H49: =+lgh_manco!I8 -> 21218000 | I49: =+lgh_manco!J8 -> 26854540 | ... N49: =+lgh_manco!O8 -> 41436272
A50: Enterprise value | B50: =+lgh_manco!C10 -> 10000000 | C50: =+lgh_manco!D10 -> 10000000 | D50: =+lgh_manco!E10 -> 10000000 | E50: =+lgh_manco!F10 -> 10000000 | F50: =+lgh_manco!G10 -> 10000000 | G50: =+lgh_manco!H10 -> 10300000 | H50: =+lgh_manco!I10 -> 12730800 | I50: =+lgh_manco!J10 -> 18798178 | ... N50: =+lgh_manco!O10 -> 82872544
A51: Other EV | B51: =+lgh_manco!C11 -> 0 | C51: =+lgh_manco!D11 -> 0 | D51: =+lgh_manco!E11 -> 0 | E51: =+lgh_manco!F11 -> 0 | F51: =+lgh_manco!G11 -> 0 | G51: =+lgh_manco!H11 -> 0 | H51: =+lgh_manco!I11 -> 0 | I51: =+lgh_manco!J11 -> 0 | ... N51: =+lgh_manco!O11 -> 100000000
A55: Total LGH D&s Fees | B55: ='c12_d&s'!E60 -> 1480300 | C55: ='c12_d&s'!F60 -> 218167.08 | D55: ='c12_d&s'!G60 -> 218167.08 | E55: ='c12_d&s'!H60 -> 788567.08 | F55: ='c12_d&s'!I60 -> 1041680.2 | G55: ='c12_d&s'!J60 -> 1735259.1 | H55: ='c12_d&s'!K60 -> 2473819.8 | I55: ='c12_d&s'!L60 -> 2205638.8 | ... N55: ='c12_d&s'!Q60 -> 4361744.7
A56: c12 D&s Participation | B56: ='c12_d&s'!E70 -> 740150 | C56: ='c12_d&s'!F70 -> 68839.329 | D56: ='c12_d&s'!G70 -> 68839.329 | E56: ='c12_d&s'!H70 -> 354039.33 | F56: ='c12_d&s'!I70 -> 462139.99 | G56: ='c12_d&s'!J70 -> 806580.95 | H56: ='c12_d&s'!K70 -> 1015405.1 | I56: ='c12_d&s'!L70 -> 935314.59 | ... N56: ='c12_d&s'!Q70 -> 1408540.1
A58: total c12 participation | B58: ='c12_oc'!E10 -> 2452451 | C58: ='c12_oc'!F10 -> 638700.01 | D58: ='c12_oc'!G10 -> 638700.01 | E58: ='c12_oc'!H10 -> 927158.96 | F58: ='c12_oc'!I10 -> 937170.54 | G58: ='c12_oc'!J10 -> 886331.48 | H58: ='c12_oc'!K10 -> 1430293.5 | I58: ='c12_oc'!L10 -> 1358160.9 | ... N58: ='c12_oc'!Q10 -> 3977928.6
A59: total lgh revenue | B59: ='c12_oc'!E88 -> 0 | C59: ='c12_oc'!F88 -> 995387.76 | D59: ='c12_oc'!G88 -> 995387.76 | E59: ='c12_oc'!H88 -> 1630966.7 | F59: ='c12_oc'!I88 -> 2037948.3 | G59: ='c12_oc'!J88 -> 2200269.7 | H59: ='c12_oc'!K88 -> 3530751.8 | I59: ='c12_oc'!L88 -> 3421728.7 | ... N59: ='c12_oc'!Q88 -> 13901367
A60: art leases | B60: =lgh_oc!B8 -> 0 | C60: =lgh_oc!C8 -> 50000 | D60: =lgh_oc!D8 -> 50000 | E60: =lgh_oc!E8 -> 50000 | F60: =lgh_oc!F8 -> 50000 | G60: =lgh_oc!G8 -> 50000 | H60: =lgh_oc!H8 -> 50000 | I60: =lgh_oc!I8 -> 50000 | ... N60: =lgh_oc!N8 -> 250000
A62: balance | B62: =+lgh_pref_equity!L47 -> 51080209 | C62: =+lgh_pref_equity!M47 -> 49890886 | D62: =+lgh_pref_equity!N47 -> 50888704 | E62: =+lgh_pref_equity!O47 -> 51906478 | F62: =+lgh_pref_equity!P47 -> 54144869 | G62: =+lgh_pref_equity!Q47 -> 56742198 | H62: =+lgh_pref_equity!R47 -> 58896376 | I62: =+lgh_pref_equity!S47 -> 60074303 | ... N62: =+lgh_pref_equity!X47 -> 87446502
A63: Total Sources/In from Pref | B63: =+lgh_pref_equity!L55 -> 0 | C63: =+lgh_pref_equity!M55 -> 6050000 | D63: =+lgh_pref_equity!N55 -> 0 | E63: =+lgh_pref_equity!O55 -> 0 | F63: =+lgh_pref_equity!P55 -> 1200000 | G63: =+lgh_pref_equity!Q55 -> 1500000 | H63: =+lgh_pref_equity!R55 -> 1000000 | I63: =+lgh_pref_equity!S55 -> 0 | ... N63: =+lgh_pref_equity!X55 -> 0
A66: Balance: Principal and interest | B66: =+lgh_debt!G33 -> 25387077 | C66: =+lgh_debt!I33 -> 29007182 | D66: =+lgh_debt!K33 -> 30149897 | E66: =+lgh_debt!M33 -> 9136912.2 | F66: =+lgh_debt!O33 -> 8575632.5 | G66: =+lgh_debt!Q33 -> 7900128.8 | H66: =+lgh_debt!S33 -> 12239223 | I66: =+lgh_debt!U33 -> 12195992 | J66: =+lgh_debt!W33 -> 7400513.4 | K66: =+lgh_debt!Y33 -> 0 | L66: =+lgh_debt!AA33 -> 0 | M66: =+lgh_debt!AC33 -> 0 | N66: =+lgh_debt!AE33 -> 0
...

Sheet lgh_returns
D2: LEVERED RETURN ANCHORS | K2: UNLEVERED RETURN ANCHORS | R2: UNLEVERED RETURN ANCHORS
D3: Initial Adj. Common (Q1 2026) | E3: =(lgh_bs!I51*E4)/1000000 -> 107.56403 | K3: Initial Adj. Unlevered Equity (Q1 2026) | L3: =(lgh_bs!I53*$L$4)/1000000 -> 155.29344 | R3: Initial Adj. Unlevered Equity (Q1 2026) | S3: 154.45991
D4: Discount Factor (1.0 = no discount) | E4: =1-E5 -> 1 | K4: Discount Factor (1.0 = no discount) | L4: =1-L5 -> 1 | R4: Discount Factor (1.0 = no discount) | S4: 1
D5: Applied Discount | E5: 0 | K5: Applied Discount | L5: 0 | R5: Applied Discount | S5: 0
E8: Levered Return Metrics | L8: Unlevered Return Metrics | S8: Unlevered Return Metrics
C9: 2026 | D9: 2027 | E9: 2028 | F9: 2029 | G9: 2030 | J9: 2026 | K9: 2027 | L9: 2028 | M9: 2029 | N9: 2030 | Q9: 2026 | R9: 2027 | S9: 2028 | T9: 2029 | U9: 2030
C10: Common Equity | J10: Total Shareholder's Equity (SE) + Reserve - C/I | Q10: Total Shareholder's Equity (SE) + Reserve - C/I
C11: =(+lgh_bs!L38)/1000000 -> 113.01808 | D11: =(+lgh_bs!M38)/1000000 -> 129.73141 | E11: =(+lgh_bs!N38)/1000000 -> 155.88661 | F11: =(+lgh_bs!O38)/1000000 -> 186.97282 | G11: =(+lgh_bs!P38)/1000000 -> 216.99383 | J11: =(lgh_bs!L39-lgh_bs!L35+lgh_bs!L41+lgh_bs!L40)/1000000 -> 169.39255 | K11: =(lgh_bs!M39-lgh_bs!M35+lgh_bs!M41+lgh_bs!M40)/1000000 -> 195.1976 | L11: =(lgh_bs!N39-lgh_bs!N35+lgh_bs!N41+lgh_bs!N40)/1000000 -> 229.88256 | M11: =(lgh_bs!O39-lgh_bs!O35+lgh_bs!O41+lgh_bs!O40)/1000000 -> 267.16984 | N11: =(lgh_bs!P39-lgh_bs!P35+lgh_bs!P41+lgh_bs!P40)/1000000 -> 304.44033 | Q11: 168.53976 | R11: 194.24565 | S11: 228.88667 | T11: 266.12869 | U11: 303.35256
B12: Mult | C12: =+C11/$E3 -> 1.0507051 | D12: =+D11/$E3 -> 1.2060855 | E12: =+E11/$E3 -> 1.4492448 | F12: =+F11/$E3 -> 1.7382467 | G12: =+G11/$E3 -> 2.0173457 | I12: Mult | J12: =+J11/$L$3 -> 1.0907901 | K12: =+K11/$L$3 -> 1.2569598 | L12: =+L11/$L$3 -> 1.4803109 | M12: =+M11/$L$3 -> 1.7204194 | N12: =+N11/$L$3 -> 1.9604198 | P12: Mult | Q12: 1.0911554 | R12: 1.2575797 | S12: 1.4818516 | T12: 1.7229628 | U12: 1.9639566
B13: YoY | C13: =+C11/E3-1 -> 0.050705098 | D13: =+D11/C11-1 -> 0.14788199 | E13: =+E11/D11-1 -> 0.20161038 | F13: =+F11/E11-1 -> 0.19941549 | G13: =+G11/F11-1 -> 0.16056351 | I13: YoY | J13: =+J11/L3-1 -> 0.09079015 | K13: =+K11/J11-1 -> 0.15233875 | L13: =+L11/K11-1 -> 0.17769154 | M13: =+M11/L11-1 -> 0.16220143 | N13: =+N11/M11-1 -> 0.13950111 | P13: YoY | Q13: 0.09115538 | R13: 0.15252121 | S13: 0.17833613 | T13: 0.16270942 | U13: 0.13987169
B14: Q1 2026 | C14: =(C11/$E3)^(1/((lgh_bs!L$2-lgh_bs!$I$2)/365))-1 -> 0.067851673 | D14: =(D11/$E3)^(1/((lgh_bs!M$2-lgh_bs!$I$2)/365))-1 -> 0.11278417 | E14: =($E$11/$E$3)^(1/((lgh_bs!$N$2-lgh_bs!$I$2)/365))-1 -> 0.14410516 | F14: =(F11/$E3)^(1/((lgh_bs!O$2-lgh_bs!$I$2)/365))-1 -> 0.15857626 | G14: =($G$11/$E$3)^(1/((lgh_bs!$P$2-lgh_bs!$I$2)/365))-1 -> 0.15899381 | I14: Q1 2026 | J14: =+(J11/$L$3)^(1/((lgh_bs!L$2-lgh_bs!$I$2)/365))-1 -> 0.12225843 | K14: =+(K11/$L$3)^(1/((lgh_bs!M$2-lgh_bs!$I$2)/365))-1 -> 0.13931607 | L14: =+(L11/$L$3)^(1/((lgh_bs!N$2-lgh_bs!$I$2)/365))-1 -> 0.15294336 | M14: =+(M11/$L$3)^(1/((lgh_bs!O$2-lgh_bs!$I$2)/365))-1 -> 0.1554009 | N14: =+(N11/$L$3)^(1/((lgh_bs!P$2-lgh_bs!$I$2)/365))-1 -> 0.1520396 | P14: Q1 2026 | Q14: 0.1227572 | R14: 0.13963651 | S14: 0.15337861 | T14: 0.1558554 | U14: 0.15247627
C16: Common + Pref MTM + Austin Adj. + Loren EV | J16: Total SE + Reserve - C/I + Loren EV | Q16: Total SE + Reserve - C/I + Loren EV
C17: =C11+(SUM(lgh_bs!L40:L42)/1000000)*(1-lgh_inputs!$D$4)+(lgh_bs!L46/1000000) -> 130.97301 | D17: =D11+(SUM(lgh_bs!M40:M42)/1000000)*(1-lgh_inputs!$D$4)+(lgh_bs!M46/1000000) -> 154.71453 | E17: =E11+(SUM(lgh_bs!N40:N42)/1000000)*(1-lgh_inputs!$D$4)+(lgh_bs!N46/1000000) -> 191.76577 | F17: =F11+(SUM(lgh_bs!O40:O42)/1000000)*(1-lgh_inputs!$D$4)+(lgh_bs!O46/1000000) -> 228.45219 | G17: =G11+(SUM(lgh_bs!P40:P42)/1000000)*(1-lgh_inputs!$D$4)+(lgh_bs!P46/1000000) -> 270.86098 | J17: =J11+(lgh_bs!L42/1000000)*(1-lgh_inputs!$D$4) -> 183.77584 | K17: =K11+(lgh_bs!M42/1000000)*(1-lgh_inputs!$D$4) -> 215.56794 | L17: =L11+(lgh_bs!N42/1000000)*(1-lgh_inputs!$D$4) -> 261.13622 | M17: =M11+(lgh_bs!O42/1000000)*(1-lgh_inputs!$D$4) -> 306.25924 | N17: =N11+(lgh_bs!P42/1000000)*(1-lgh_inputs!$D$4) -> 358.30749 | Q17: 182.92306 | R17: 214.61599 | S17: 260.14033 | T17: 305.21809 | U17: 357.21971
B18: Mult | C18: =+C17/$E$3 -> 1.2176283 | D18: =+D17/$E$3 -> 1.4383482 | E18: =+E17/$E$3 -> 1.7828057 | F18: =+F17/$E$3 -> 2.1238716 | G18: =+G17/$E$3 -> 2.5181372 | I18: Mult | J18: =+J17/$L$3 -> 1.1834102 | K18: =+K17/$L$3 -> 1.388133 | L18: =+L17/$L$3 -> 1.6815664 | M18: =+M17/$L$3 -> 1.9721326 | N18: =+N17/$L$3 -> 2.3072932 | P18: Mult | Q18: 1.1842753 | R18: 1.3894608 | S18: 1.6841932 | T18: 1.9760343 | U18: 2.3127018
B19: YoY | C19: =+C17/E3-1 -> 0.21762828 | D19: =+D17/C17-1 -> 0.18127035 | E19: =+E17/D17-1 -> 0.23948135 | F19: =+F17/E17-1 -> 0.19130849 | G19: =+G17/F17-1 -> 0.1856353 | I19: YoY | J19: =+J17/L3-1 -> 0.18341024 | K19: =+K17/J17-1 -> 0.17299387 | L19: =+L17/K17-1 -> 0.21138712 | M19: =+M17/L17-1 -> 0.17279495 | N19: =+N17/M17-1 -> 0.16994832 | P19: YoY | Q19: 0.18427528 | R19: 0.17325828 | S19: 0.21211999 | T19: 0.17328246 | U19: 0.1703753
B20: Q1 2026 | C20: =(C17/$E$3)^(1/((lgh_bs!L$2-lgh_bs!$I$2)/365))-1 -> 0.29867765 | D20: =(D17/$E$3)^(1/((lgh_bs!M$2-lgh_bs!$I$2)/365))-1 -> 0.23035894 | E20: =(E17/$E$3)^(1/((lgh_bs!N$2-lgh_bs!$I$2)/365))-1 -> 0.23340678 | F20: =(F17/$E$3)^(1/((lgh_bs!O$2-lgh_bs!$I$2)/365))-1 -> 0.22205581 | G20: =(G17/$E$3)^(1/((lgh_bs!P$2-lgh_bs!$I$2)/365))-1 -> 0.21430652 | I20: Q1 2026 | J20: =(J17/$L3)^(1/((lgh_bs!L$2-lgh_bs!$I$2)/365))-1 -> 0.25046206 | K20: =(K17/$L3)^(1/((lgh_bs!M$2-lgh_bs!$I$2)/365))-1 -> 0.20567489 | L20: =(L17/$L3)^(1/((lgh_bs!N$2-lgh_bs!$I$2)/365))-1 -> 0.20751977 | M20: =(M17/$L3)^(1/((lgh_bs!O$2-lgh_bs!$I$2)/365))-1 -> 0.19817583 | N20: =(N17/$L3)^(1/((lgh_bs!P$2-lgh_bs!$I$2)/365))-1 -> 0.1921849 | P20: Q1 2026 | Q20: 0.2516754 | R20: 0.20633249 | S20: 0.20820382 | T20: 0.19880647 | U20: 0.19277193
C22: Common + Pref MTM + Austin Adj. + Loren EV + Other EV | J22: Total SE + Reserve - C/I + Loren EV + Other EV | Q22: Total SE + Reserve - C/I + Loren EV + Other EV
C23: =(+lgh_bs!L51)/1000000 -> 130.97301 | D23: =(+lgh_bs!M51)/1000000 -> 154.71453 | E23: =(+lgh_bs!N51)/1000000 -> 208.01577 | F23: =(+lgh_bs!O51)/1000000 -> 260.95219 | G23: =(+lgh_bs!P51)/1000000 -> 335.86098 | J23: =+lgh_bs!L53/1000000 -> 186.5413 | K23: =+lgh_bs!M53/1000000 -> 216.95102 | L23: =+lgh_bs!N53/1000000 -> 277.72759 | M23: =+lgh_bs!O53/1000000 -> 339.02943 | N23: =+lgh_bs!P53/1000000 -> 423.30749 | Q23: 185.68852 | R23: 215.99907 | S23: 276.7317 | T23: 337.98827 | U23: 422.21971
B24: Mult | C24: =+C23/$E3 -> 1.2176283 | D24: =+D23/$E3 -> 1.4383482 | E24: =+E23/$E3 -> 1.9338786 | F24: =+F23/$E3 -> 2.4260172 | G24: =+G23/$E3 -> 3.1224284 | I24: Mult | J24: =+J23/$L3 -> 1.2012182 | K24: =+K23/$L3 -> 1.3970392 | L24: =+L23/$L3 -> 1.7884052 | M24: =+M23/$L3 -> 2.1831536 | N24: =+N23/$L3 -> 2.7258556 | P24: Mult | Q24: 1.2021793 | R24: 1.3984151 | S24: 1.7916085 | T24: 2.1881941 | U24: 2.7335229
B25: YoY | C25: =+C23/E3-1 -> 0.21762828 | D25: =+D23/C23-1 -> 0.18127035 | E25: =+E23/D23-1 -> 0.3445135 | F25: =+F23/E23-1 -> 0.25448273 | G25: =+G23/F23-1 -> 0.28705944 | I25: YoY | J25: =+J23/L3-1 -> 0.2012182 | K25: =+K23/J23-1 -> 0.16301869 | L25: =+L23/K23-1 -> 0.28013958 | M25: =+M23/L23-1 -> 0.2207265 | N25: =+N23/M23-1 -> 0.24858626 | P25: YoY | Q25: 0.20217934 | R25: 0.16323334 | S25: 0.28117076 | T25: 0.22135728 | U25: 0.24921408
B26: Q1 2026 | C26: =(C23/$E3)^(1/((lgh_bs!L$2-lgh_bs!$I$2)/365))-1 -> 0.29867765 | D26: =(D23/$E3)^(1/((lgh_bs!M$2-lgh_bs!$I$2)/365))-1 -> 0.23035894 | E26: =(E23/$E3)^(1/((lgh_bs!N$2-lgh_bs!$I$2)/365))-1 -> 0.2703492 | F26: =(F23/$E3)^(1/((lgh_bs!O$2-lgh_bs!$I$2)/365))-1 -> 0.26610559 | G26: =(G23/$E3)^(1/((lgh_bs!P$2-lgh_bs!$I$2)/365))-1 -> 0.2704827 | I26: Q1 2026 | J26: =(J23/$L3)^(1/((lgh_bs!L$2-lgh_bs!$I$2)/365))-1 -> 0.27549859 | K26: =(K23/$L3)^(1/((lgh_bs!M$2-lgh_bs!$I$2)/365))-1 -> 0.21008054 | L26: =(L23/$L3)^(1/((lgh_bs!N$2-lgh_bs!$I$2)/365))-1 -> 0.23481091 | M26: =(M23/$L3)^(1/((lgh_bs!O$2-lgh_bs!$I$2)/365))-1 -> 0.23104544 | N26: =(N23/$L3)^(1/((lgh_bs!P$2-lgh_bs!$I$2)/365))-1 -> 0.23471288 | P26: Q1 2026 | Q26: 0.27685335 | R26: 0.21076007 | S26: 0.23561293 | T26: 0.23180149 | U26: 0.23544228
J27: * Unlevered Equity is the sum of Common and Preferred Equity | Q27: * Unlevered Equity is the sum of Common and Preferred Equity

Sheet lgh_inputs
C3: ASSUMPTION INPUTS from lgh_returns page
C4: CI % | D4: 0.35
C6: Pref MTM Discount Rate | D6: 0.12
C8: return on cash balances (lgh_oc) | D8: 0.03
C10: pref unit size in dollars | D10: 25
C11: from pref page
C13: Valuation Assumptions
C14: Inflation | D14: 0.03
C15: from lgh_manco

Sheet lgh_diags
A1: Entity | B1: Subcategory | C1: {=_xlfn.TEXTAFTER(CELL("filename",C1),"]")} -> lgh_diags | AB1: {=_xlfn.TEXTAFTER(CELL("filename",AB1),"]")} -> lgh_diags
C2: Year | D2: 45657 | E2: 45747 | F2: 45838 | G2: 45930 | H2: 46022 | I2: 46112 | J2: 46203 | K2: 46295 | L2: 46387 | M2: 46752 | N2: 47118 | O2: 47483 | P2: 47848 | R2: 46022 | S2: 46112 | T2: 46203 | U2: 46295 | V2: 46387 | W2: 46752 | X2: 47118 | Y2: 47483 | Z2: 47848 | AB2: Year | AC2: 46022 | AD2: 46112 | AE2: 46203 | AF2: 46295 | AG2: 46387 | AH2: 46752 | AI2: 47118 | AJ2: 47483 | AK2: 47848
C3: Period | D3: Q4 | E3: Q1 | F3: Q2 | G3: Q3 | H3: Q4 | I3: Q1 | J3: Q2 | K3: Q3 | L3: Q4 | M3: Q4 | N3: Q4 | O3: Q4 | P3: Q4 | R3: Q4 | S3: Q1 | T3: Q2 | U3: Q3 | V3: Q4 | W3: Q4 | X3: Q4 | Y3: Q4 | Z3: Q4 | AB3: Period | AC3: Q4 | AD3: Q1 | AE3: Q2 | AF3: Q3 | AG3: Q4 | AH3: Q4 | AI3: Q4 | AJ3: Q4 | AK3: Q4
C4: Assets | AB4: Assets
A5: lgh_oc | B5: Cumm cash balance | C5: Cash | D5: =lgh_bs!D5 -> 251128 | E5: =lgh_bs!E5 -> 2637541.5 | F5: =lgh_bs!F5 -> -866943.45 | G5: =lgh_bs!G5 -> -2782648.6 | H5: =lgh_bs!H5 -> 420309.59 | I5: =lgh_bs!I5 -> 5306065 | J5: =lgh_bs!J5 -> 10576672 | K5: =lgh_bs!K5 -> 7017080.3 | ... P5: =lgh_bs!P5 -> 27568985 | R5: 420309.59 | S5: 5306065 | T5: 10576672 | U5: 7017080.3 | V5: 2766709.9 | W5: 5785838.6 | X5: 13083445 | Y5: 22908452 | Z5: 27568985 | AB5: Cash | AC5: =H5-R5 -> 0 | AD5: =I5-S5 -> 0 | AE5: =J5-T5 -> 0 | AF5: =K5-U5 -> 0 | AG5: =L5-V5 -> 0 | AH5: =M5-W5 -> 0 | AI5: =N5-X5 -> 0 | AJ5: =O5-Y5 -> 0 | AK5: =P5-Z5 -> 0
C6: Bermuda | D6: =lgh_bs!D6 -> 56391899 | E6: =lgh_bs!E6 -> 48342875 | F6: =lgh_bs!F6 -> 49230680 | G6: =lgh_bs!G6 -> 51936303 | H6: =lgh_bs!H6 -> 46803857 | I6: =lgh_bs!I6 -> 46688396 | J6: =lgh_bs!J6 -> 47318459 | K6: =lgh_bs!K6 -> 47193849 | ... P6: =lgh_bs!P6 -> 85421360 | R6: 46803857 | S6: 46688396 | T6: 47318459 | U6: 47193849 | V6: 60232309 | W6: 68658853 | X6: 78031616 | Y6: 73752765 | Z6: 85421360 | AB6: Bermuda | AC6: =H6-R6 -> 0 | AD6: =I6-S6 -> 0 | AE6: =J6-T6 -> 0 | AF6: =K6-U6 -> 0 | AG6: =L6-V6 -> 0 | AH6: =M6-W6 -> 0 | AI6: =N6-X6 -> 0 | AJ6: =O6-Y6 -> 0 | AK6: =P6-Z6 -> 0
A7: Bermuda Pink Beach | B7: Level 1 | C7: Equity | D7: =lgh_bs!D7 -> 56391899 | E7: =lgh_bs!E7 -> 48342875 | F7: =lgh_bs!F7 -> 49230680 | G7: =lgh_bs!G7 -> 51936303 | H7: =lgh_bs!H7 -> 46803857 | I7: =lgh_bs!I7 -> 46688396 | J7: =lgh_bs!J7 -> 47318459 | K7: =lgh_bs!K7 -> 47193849 | ... P7: =lgh_bs!P7 -> 85421360 | R7: 46803857 | S7: 46688396 | T7: 47318459 | U7: 47193849 | V7: 60232309 | W7: 68658853 | X7: 78031616 | Y7: 73752765 | Z7: 85421360 | AB7: Equity | AC7: =H7-R7 -> 0 | AD7: =I7-S7 -> 0 | AE7: =J7-T7 -> 0 | AF7: =K7-U7 -> 0 | AG7: =L7-V7 -> 0 | AH7: =M7-W7 -> 0 | AI7: =N7-X7 -> 0 | AJ7: =O7-Y7 -> 0 | AK7: =P7-Z7 -> 0
C8: Austin | D8: =lgh_bs!D8 -> 30156389 | E8: =lgh_bs!E8 -> 26787736 | F8: =lgh_bs!F8 -> 26482398 | G8: =lgh_bs!G8 -> 24312675 | H8: =lgh_bs!H8 -> 18560900 | I8: =lgh_bs!I8 -> 18168835 | J8: =lgh_bs!J8 -> 20455751 | K8: =lgh_bs!K8 -> 20019626 | ... P8: =lgh_bs!P8 -> 47083185 | R8: 18560900 | S8: 18168835 | T8: 20455751 | U8: 20019626 | V8: 20380869 | W8: 20527642 | X8: 17612726 | Y8: 39638789 | Z8: 47083185 | AB8: Austin | AC8: =H8-R8 -> 0 | AD8: =I8-S8 -> 0 | AE8: =J8-T8 -> 0 | AF8: =K8-U8 -> 0 | AG8: =L8-V8 -> 0 | AH8: =M8-W8 -> 0 | AI8: =N8-X8 -> 0 | AJ8: =O8-Y8 -> 0 | AK8: =P8-Z8 -> 0
A9: Austin Lady Bird Lake | B9: LGH NAV | C9: Equity | D9: =lgh_bs!D9 -> 15926855 | E9: =lgh_bs!E9 -> 18088592 | F9: =lgh_bs!F9 -> 17359150 | G9: =lgh_bs!G9 -> 15109714 | H9: =lgh_bs!H9 -> 7753407.4 | I9: =lgh_bs!I9 -> 6038275.4 | J9: =lgh_bs!J9 -> 4849926.1 | K9: =lgh_bs!K9 -> 3974250.2 | ... P9: =lgh_bs!P9 -> 0 | R9: 7753407.4 | S9: 6038275.4 | T9: 4849926.1 | U9: 3974250.2 | V9: 3116853.8 | W9: 0 | X9: 0 | Y9: 0 | Z9: 0 | AB9: Equity | AC9: =H9-R9 -> 0 | AD9: =I9-S9 -> 0 | AE9: =J9-T9 -> 0 | AF9: =K9-U9 -> 0 | AG9: =L9-V9 -> 0 | AH9: =M9-W9 -> 0 | AI9: =N9-X9 -> 0 | AJ9: =O9-Y9 -> 0 | AK9: =P9-Z9 -> 0
A10: Austin Lady Bird Lake | B10: Pref Owned | C10: Preferred Equity | D10: =lgh_bs!D10 -> 5608281.4 | E10: =lgh_bs!E10 -> 5792434.5 | F10: =lgh_bs!F10 -> 5984782.4 | G10: =lgh_bs!G10 -> 6185737.8 | H10: =lgh_bs!H10 -> 6393440.8 | I10: =lgh_bs!I10 -> 6603375.3 | J10: =lgh_bs!J10 -> 6822651.9 | K10: =lgh_bs!K10 -> 7051741.1 | ... P10: =lgh_bs!P10 -> 4764456.8 | R10: 6393440.8 | S10: 6603375.3 | T10: 6822651.9 | U10: 7051741.1 | V10: 7288522.5 | W10: 6806296.5 | X10: 4230778.4 | Y10: 4951306.9 | Z10: 4764456.8 | AB10: Preferred Equity | AC10: =H10-R10 -> 0 | AD10: =I10-S10 -> 0 | AE10: =J10-T10 -> 0 | AF10: =K10-U10 -> 0 | AG10: =L10-V10 -> 0 | AH10: =M10-W10 -> 0 | AI10: =N10-X10 -> 0 | AJ10: =O10-Y10 -> 0 | AK10: =P10-Z10 -> 0
A11: Austin Lady Bird Lake | B11: Mezz Owned | C11: Mezz Loan | D11: =lgh_bs!D11 -> 8621252.7 | E11: =lgh_bs!E11 -> 2691709.1 | F11: =lgh_bs!F11 -> 2849465 | G11: =lgh_bs!G11 -> 3017222.8 | H11: =lgh_bs!H11 -> 4124556.9 | I11: =lgh_bs!I11 -> 4237689.3 | J11: =lgh_bs!J11 -> 6873678.2 | K11: =lgh_bs!K11 -> 7084139.4 | ... P11: =lgh_bs!P11 -> 42318729 | R11: 4124556.9 | S11: 4237689.3 | T11: 6873678.2 | U11: 7084139.4 | V11: 7315998.2 | W11: 10662926 | X11: 9864765.6 | Y11: 34687482 | Z11: 42318729 | AB11: Mezz Loan | AC11: =H11-R11 -> 0 | AD11: =I11-S11 -> 0 | AE11: =J11-T11 -> 0 | AF11: =K11-U11 -> 0 | AG11: =L11-V11 -> 0 | AH11: =M11-W11 -> 0 | AI11: =N11-X11 -> 0 | AJ11: =O11-Y11 -> 0 | AK11: =P11-Z11 -> 0
C12: STL | D12: =lgh_bs!D12 -> 0 | E12: =lgh_bs!E12 -> 215000 | F12: =lgh_bs!F12 -> 289000 | G12: =lgh_bs!G12 -> 0 | H12: =lgh_bs!H12 -> 289495 | I12: =lgh_bs!I12 -> 1289495 | J12: =lgh_bs!J12 -> 1909495 | K12: =lgh_bs!K12 -> 1909495 | ... P12: =lgh_bs!P12 -> 0 | R12: 289495 | S12: 1289495 | T12: 1909495 | U12: 1909495 | V12: 2659495 | W12: 3058419.2 | X12: 3517182.1 | Y12: 0 | Z12: 0 | AB12: STL | AC12: =H12-R12 -> 0 | AD12: =I12-S12 -> 0 | AE12: =J12-T12 -> 0 | AF12: =K12-U12 -> 0 | AG12: =L12-V12 -> 0 | AH12: =M12-W12 -> 0 | AI12: =N12-X12 -> 0 | AJ12: =O12-Y12 -> 0 | AK12: =P12-Z12 -> 0
C13: Turks | D13: =lgh_bs!D13 -> 30602658 | E13: =lgh_bs!E13 -> 35723216 | F13: =lgh_bs!F13 -> 38565928 | G13: =lgh_bs!G13 -> 40379581 | H13: =lgh_bs!H13 -> 40032701 | I13: =lgh_bs!I13 -> 36265000 | J13: =lgh_bs!J13 -> 38900747 | K13: =lgh_bs!K13 -> 41760245 | ... P13: =lgh_bs!P13 -> 37231193 | R13: 40032701 | S13: 36265000 | T13: 38900747 | U13: 41760245 | V13: 50265874 | W13: 32637075 | X13: 33952187 | Y13: 35273003 | Z13: 37231193 | AB13: Turks | AC13: =H13-R13 -> 0 | AD13: =I13-S13 -> 0 | AE13: =J13-T13 -> 0 | AF13: =K13-U13 -> 0 | AG13: =L13-V13 -> 0 | AH13: =M13-W13 -> 0 | AI13: =N13-X13 -> 0 | AJ13: =O13-Y13 -> 0 | AK13: =P13-Z13 -> 0
A14: Turks & Caicos | B14: LGH NAV | C14: Equity | D14: =lgh_bs!D14 -> 30602658 | E14: =lgh_bs!E14 -> 35723216 | F14: =lgh_bs!F14 -> 38565928 | G14: =lgh_bs!G14 -> 40379581 | H14: =lgh_bs!H14 -> 40032701 | I14: =lgh_bs!I14 -> 36265000 | J14: =lgh_bs!J14 -> 38900747 | K14: =lgh_bs!K14 -> 41760245 | ... P14: =lgh_bs!P14 -> 37231193 | R14: 40032701 | S14: 36265000 | T14: 38900747 | U14: 41760245 | V14: 50265874 | W14: 32637075 | X14: 33952187 | Y14: 35273003 | Z14: 37231193 | AB14: Equity | AC14: =H14-R14 -> 0 | AD14: =I14-S14 -> 0 | AE14: =J14-T14 -> 0 | AF14: =K14-U14 -> 0 | AG14: =L14-V14 -> 0 | AH14: =M14-W14 -> 0 | AI14: =N14-X14 -> 0 | AJ14: =O14-Y14 -> 0 | AK14: =P14-Z14 -> 0
C15: Elbow | D15: =lgh_bs!D15 -> 5000000 | E15: =lgh_bs!E15 -> 17383391 | F15: =lgh_bs!F15 -> 19070671 | G15: =lgh_bs!G15 -> 20943032 | H15: =lgh_bs!H15 -> 22999222 | I15: =lgh_bs!I15 -> 28009536 | J15: =lgh_bs!J15 -> 30460557 | K15: =lgh_bs!K15 -> 33156609 | ... P15: =lgh_bs!P15 -> 104879625 | R15: 22999222 | S15: 28009536 | T15: 30460557 | U15: 33156609 | V15: 36091288 | W15: 56628545 | X15: 76968139 | Y15: 97729625 | Z15: 104879625 | AB15: Elbow | AC15: =H15-R15 -> 0 | AD15: =I15-S15 -> 0 | AE15: =J15-T15 -> 0 | AF15: =K15-U15 -> 0 | AG15: =L15-V15 -> 0 | AH15: =M15-W15 -> 0 | AI15: =N15-X15 -> 0 | AJ15: =O15-Y15 -> 0 | AK15: =P15-Z15 -> 0
A16: Bermuda: Elbow Beach | B16: LGH NAV | C16: Elbow Beach | D16: =lgh_bs!D16 -> 5000000 | E16: =lgh_bs!E16 -> 17383391 | F16: =lgh_bs!F16 -> 19070671 | G16: =lgh_bs!G16 -> 20943032 | H16: =lgh_bs!H16 -> 22999222 | I16: =lgh_bs!I16 -> 28009536 | J16: =lgh_bs!J16 -> 30460557 | K16: =lgh_bs!K16 -> 33156609 | ... P16: =lgh_bs!P16 -> 104879625 | R16: 22999222 | S16: 28009536 | T16: 30460557 | U16: 33156609 | V16: 36091288 | W16: 56628545 | X16: 76968139 | Y16: 97729625 | Z16: 104879625 | AB16: Elbow Beach | AC16: =H16-R16 -> 0 | AD16: =I16-S16 -> 0 | AE16: =J16-T16 -> 0 | AF16: =K16-U16 -> 0 | AG16: =L16-V16 -> 0 | AH16: =M16-W16 -> 0 | AI16: =N16-X16 -> 0 | AJ16: =O16-Y16 -> 0 | AK16: =P16-Z16 -> 0
C17: Fritholme | D17: =lgh_bs!D17 -> 0 | E17: =lgh_bs!E17 -> 11353680 | F17: =lgh_bs!F17 -> 13799240 | G17: =lgh_bs!G17 -> 15549103 | H17: =lgh_bs!H17 -> 15839974 | I17: =lgh_bs!I17 -> 15929659 | J17: =lgh_bs!J17 -> 15182357 | K17: =lgh_bs!K17 -> 17072720 | ... P17: =lgh_bs!P17 -> 0 | R17: 15839974 | S17: 15929659 | T17: 15182357 | U17: 17072720 | V17: 0 | W17: 0 | X17: 0 | Y17: 0 | Z17: 0 | AB17: Fritholme | AC17: =H17-R17 -> 0 | AD17: =I17-S17 -> 0 | AE17: =J17-T17 -> 0 | AF17: =K17-U17 -> 0 | AG17: =L17-V17 -> 0 | AH17: =M17-W17 -> 0 | AI17: =N17-X17 -> 0 | AJ17: =O17-Y17 -> 0 | AK17: =P17-Z17 -> 0
A18: Fritholme | B18: LGH NAV | C18: Fritholme | D18: =lgh_bs!D18 -> 0 | E18: =lgh_bs!E18 -> 11353680 | F18: =lgh_bs!F18 -> 13799240 | G18: =lgh_bs!G18 -> 15549103 | H18: =lgh_bs!H18 -> 15839974 | I18: =lgh_bs!I18 -> 15929659 | J18: =lgh_bs!J18 -> 15182357 | K18: =lgh_bs!K18 -> 17072720 | ... P18: =lgh_bs!P18 -> 0 | R18: 15839974 | S18: 15929659 | T18: 15182357 | U18: 17072720 | V18: 0 | W18: 0 | X18: 0 | Y18: 0 | Z18: 0 | AB18: Fritholme | AC18: =H18-R18 -> 0 | AD18: =I18-S18 -> 0 | AE18: =J18-T18 -> 0 | AF18: =K18-U18 -> 0 | AG18: =L18-V18 -> 0 | AH18: =M18-W18 -> 0 | AI18: =N18-X18 -> 0 | AJ18: =O18-Y18 -> 0 | AK18: =P18-Z18 -> 0
C19: =+C20 -> [LSAT] | D19: =lgh_bs!D19 -> 0 | E19: =lgh_bs!E19 -> 0 | F19: =lgh_bs!F19 -> 0 | G19: =lgh_bs!G19 -> 0 | H19: =lgh_bs!H19 -> 0 | I19: =lgh_bs!I19 -> 0 | J19: =lgh_bs!J19 -> 0 | K19: =lgh_bs!K19 -> 0 | ... P19: =lgh_bs!P19 -> 21709416 | R19: 0 | S19: 0 | T19: 0 | U19: 0 | V19: 16000000 | W19: 16000000 | X19: 20333333 | Y19: 22077381 | Z19: 21709416 | AB19: =+AB20 -> [LSAT] | AC19: =H19-R19 -> 0 | AD19: =I19-S19 -> 0 | AE19: =J19-T19 -> 0 | AF19: =K19-U19 -> 0 | AG19: =L19-V19 -> 0 | AH19: =M19-W19 -> 0 | AI19: =N19-X19 -> 0 | AJ19: =O19-Y19 -> 0 | AK19: =P19-Z19 -> 0
A20: lgh_other_assets | B20: [SAT] Balance Sheet | C20: [LSAT] | D20: =lgh_bs!D20 -> 0 | E20: =lgh_bs!E20 -> 0 | F20: =lgh_bs!F20 -> 0 | G20: =lgh_bs!G20 -> 0 | H20: =lgh_bs!H20 -> 0 | I20: =lgh_bs!I20 -> 0 | J20: =lgh_bs!J20 -> 0 | K20: =lgh_bs!K20 -> 0 | ... P20: =lgh_bs!P20 -> 21709416 | R20: 0 | S20: 0 | T20: 0 | U20: 0 | V20: 16000000 | W20: 16000000 | X20: 20333333 | Y20: 22077381 | Z20: 21709416 | AB20: [LSAT] | AC20: =H20-R20 -> 0 | AD20: =I20-S20 -> 0 | AE20: =J20-T20 -> 0 | AF20: =K20-U20 -> 0 | AG20: =L20-V20 -> 0 | AH20: =M20-W20 -> 0 | AI20: =N20-X20 -> 0 | AJ20: =O20-Y20 -> 0 | AK20: =P20-Z20 -> 0
C21: =+C22 -> [L4] | D21: =lgh_bs!D21 -> 0 | E21: =lgh_bs!E21 -> 0 | F21: =lgh_bs!F21 -> 0 | G21: =lgh_bs!G21 -> 0 | H21: =lgh_bs!H21 -> 0 | I21: =lgh_bs!I21 -> 0 | J21: =lgh_bs!J21 -> 0 | K21: =lgh_bs!K21 -> 0 | ... P21: =lgh_bs!P21 -> 45000000 | R21: 0 | S21: 0 | T21: 0 | U21: 0 | V21: 0 | W21: 12500000 | X21: 18750000 | Y21: 25000000 | Z21: 45000000 | AB21: =+AB22 -> [L4] | AC21: =H21-R21 -> 0 | AD21: =I21-S21 -> 0 | AE21: =J21-T21 -> 0 | AF21: =K21-U21 -> 0 | AG21: =L21-V21 -> 0 | AH21: =M21-W21 -> 0 | AI21: =N21-X21 -> 0 | AJ21: =O21-Y21 -> 0 | AK21: =P21-Z21 -> 0
A22: lgh_other_assets | B22: [WC] Balance Sheet | C22: [L4] | D22: =lgh_bs!D22 -> 0 | E22: =lgh_bs!E22 -> 0 | F22: =lgh_bs!F22 -> 0 | G22: =lgh_bs!G22 -> 0 | H22: =lgh_bs!H22 -> 0 | I22: =lgh_bs!I22 -> 0 | J22: =lgh_bs!J22 -> 0 | K22: =lgh_bs!K22 -> 0 | ... P22: =lgh_bs!P22 -> 45000000 | R22: 0 | S22: 0 | T22: 0 | U22: 0 | V22: 0 | W22: 12500000 | X22: 18750000 | Y22: 25000000 | Z22: 45000000 | AB22: [L4] | AC22: =H22-R22 -> 0 | AD22: =I22-S22 -> 0 | AE22: =J22-T22 -> 0 | AF22: =K22-U22 -> 0 | AG22: =L22-V22 -> 0 | AH22: =M22-W22 -> 0 | AI22: =N22-X22 -> 0 | AJ22: =O22-Y22 -> 0 | AK22: =P22-Z22 -> 0
C23: =+C24 -> PV Loren fees (Key money) | D23: =lgh_bs!D23 -> 20000000 | E23: =lgh_bs!E23 -> 20000000 | F23: =lgh_bs!F23 -> 20000000 | G23: =lgh_bs!G23 -> 20000000 | H23: =lgh_bs!H23 -> 20000000 | I23: =lgh_bs!I23 -> 20600000 | J23: =lgh_bs!J23 -> 21218000 | K23: =lgh_bs!K23 -> 26854540 | ... P23: =lgh_bs!P23 -> 41436272 | R23: 20000000 | S23: 20600000 | T23: 21218000 | U23: 26854540 | V23: 27660176 | W23: 28489981 | X23: 34344681 | Y23: 35375021 | Z23: 41436272 | AB23: =+AB24 -> PV Loren fees (Key money) | AC23: =H23-R23 -> 0 | AD23: =I23-S23 -> 0 | AE23: =J23-T23 -> 0 | AF23: =K23-U23 -> 0 | AG23: =L23-V23 -> 0 | AH23: =M23-W23 -> 0 | AI23: =N23-X23 -> 0 | AJ23: =O23-Y23 -> 0 | AK23: =P23-Z23 -> 0
A24: c12_hm_oc | B24: PV Loren fees (Key money) | C24: PV Loren fees (Key money) | D24: =lgh_bs!D24 -> 20000000 | E24: =lgh_bs!E24 -> 20000000 | F24: =lgh_bs!F24 -> 20000000 | G24: =lgh_bs!G24 -> 20000000 | H24: =lgh_bs!H24 -> 20000000 | I24: =lgh_bs!I24 -> 20600000 | J24: =lgh_bs!J24 -> 21218000 | K24: =lgh_bs!K24 -> 26854540 | ... P24: =lgh_bs!P24 -> 41436272 | R24: 20000000 | S24: 20600000 | T24: 21218000 | U24: 26854540 | V24: 27660176 | W24: 28489981 | X24: 34344681 | Y24: 35375021 | Z24: 41436272 | AB24: PV Loren fees (Key money) | AC24: =H24-R24 -> 0 | AD24: =I24-S24 -> 0 | AE24: =J24-T24 -> 0 | AF24: =K24-U24 -> 0 | AG24: =L24-V24 -> 0 | AH24: =M24-W24 -> 0 | AI24: =N24-X24 -> 0 | AJ24: =O24-Y24 -> 0 | AK24: =P24-Z24 -> 0
C25: Other | D25: =lgh_bs!D25 -> 3570254 | E25: =lgh_bs!E25 -> 4252788.9 | F25: =lgh_bs!F25 -> 5986171.9 | G25: =lgh_bs!G25 -> 4752346.8 | H25: =lgh_bs!H25 -> 4042423.2 | I25: =lgh_bs!I25 -> 3150709 | J25: =lgh_bs!J25 -> 3175738.3 | K25: =lgh_bs!K25 -> 3356358.1 | ... P25: =lgh_bs!P25 -> 5265898.3 | R25: 4042423.2 | S25: 3150709 | T25: 3175738.3 | U25: 3356358.1 | V25: 3280322 | W25: 3183766.1 | X25: 2489194.6 | Y25: 4037736 | Z25: 5265898.3 | AB25: Other | AC25: =H25-R25 -> 0 | AD25: =I25-S25 -> 0 | AE25: =J25-T25 -> 0 | AF25: =K25-U25 -> 0 | AG25: =L25-V25 -> 0 | AH25: =M25-W25 -> 0 | AI25: =N25-X25 -> 0 | AJ25: =O25-Y25 -> 0 | AK25: =P25-Z25 -> 0
A26: lgh_other_assets | B26: Balance | C26: Other Assets | D26: =lgh_bs!D26 -> 3570254 | E26: =lgh_bs!E26 -> 4252788.9 | F26: =lgh_bs!F26 -> 5986171.9 | G26: =lgh_bs!G26 -> 4752346.8 | H26: =lgh_bs!H26 -> 4042423.2 | I26: =lgh_bs!I26 -> 3150709 | J26: =lgh_bs!J26 -> 3175738.3 | K26: =lgh_bs!K26 -> 3356358.1 | ... P26: =lgh_bs!P26 -> 5265898.3 | R26: 4042423.2 | S26: 3150709 | T26: 3175738.3 | U26: 3356358.1 | V26: 3280322 | W26: 3183766.1 | X26: 2489194.6 | Y26: 4037736 | Z26: 5265898.3 | AB26: Other Assets | AC26: =H26-R26 -> 0 | AD26: =I26-S26 -> 0 | AE26: =J26-T26 -> 0 | AF26: =K26-U26 -> 0 | AG26: =L26-V26 -> 0 | AH26: =M26-W26 -> 0 | AI26: =N26-X26 -> 0 | AJ26: =O26-Y26 -> 0 | AK26: =P26-Z26 -> 0
C27: Total assets incl. Cash | D27: =lgh_bs!D27 -> 1.4597233e+08 | E27: =lgh_bs!E27 -> 1.6648123e+08 | F27: =lgh_bs!F27 -> 1.7226815e+08 | G27: =lgh_bs!G27 -> 1.7509039e+08 | H27: =lgh_bs!H27 -> 1.6869939e+08 | I27: =lgh_bs!I27 -> 1.741182e+08 | J27: =lgh_bs!J27 -> 1.8728828e+08 | K27: =lgh_bs!K27 -> 1.9643103e+08 | ... P27: =lgh_bs!P27 -> 4.1559593e+08 | R27: 1.6869939e+08 | S27: 1.741182e+08 | T27: 1.8728828e+08 | U27: 1.9643103e+08 | V27: 2.1667755e+08 | W27: 2.444117e+08 | X27: 2.9556532e+08 | Y27: 3.5579277e+08 | Z27: 4.1559593e+08 | AB27: Total assets incl. Cash | AC27: =H27-R27 -> 0 | AD27: =I27-S27 -> 0 | AE27: =J27-T27 -> 0 | AF27: =K27-U27 -> 0 | AG27: =L27-V27 -> 0 | AH27: =M27-W27 -> 0 | AI27: =N27-X27 -> 0 | AJ27: =O27-Y27 -> 0 | AK27: =P27-Z27 -> 0
C28: Liabilities | D28: =lgh_bs!D28 -> 0 | E28: =lgh_bs!E28 -> 0 | F28: =lgh_bs!F28 -> 0 | G28: =lgh_bs!G28 -> 0 | H28: =lgh_bs!H28 -> 0 | I28: =lgh_bs!I28 -> 0 | J28: =lgh_bs!J28 -> 0 | K28: =lgh_bs!K28 -> 0 | ... P28: =lgh_bs!P28 -> 0 | R28: 0 | S28: 0 | T28: 0 | U28: 0 | V28: 0 | W28: 0 | X28: 0 | Y28: 0 | Z28: 0 | AB28: Liabilities | AC28: =H28-R28 -> 0 | AD28: =I28-S28 -> 0 | AE28: =J28-T28 -> 0 | AF28: =K28-U28 -> 0 | AG28: =L28-V28 -> 0 | AH28: =M28-W28 -> 0 | AI28: =N28-X28 -> 0 | AJ28: =O28-Y28 -> 0 | AK28: =P28-Z28 -> 0
A29: lgh_debt | B29: Balance: Principal and interest | C29: LGH Debt | D29: =lgh_bs!D29 -> 25387077 | E29: =lgh_bs!E29 -> 29007182 | F29: =lgh_bs!F29 -> 30149897 | G29: =lgh_bs!G29 -> 9136912.2 | H29: =lgh_bs!H29 -> 8575632.5 | I29: =lgh_bs!I29 -> 7900128.8 | J29: =lgh_bs!J29 -> 12239223 | K29: =lgh_bs!K29 -> 12195992 | ... P29: =lgh_bs!P29 -> 0 | R29: 8575632.5 | S29: 7900128.8 | T29: 12239223 | U29: 12195992 | V29: 7400513.4 | W29: 0 | X29: 0 | Y29: 0 | Z29: 0 | AB29: LGH Debt | AC29: =H29-R29 -> 0 | AD29: =I29-S29 -> 0 | AE29: =J29-T29 -> 0 | AF29: =K29-U29 -> 0 | AG29: =L29-V29 -> 0 | AH29: =M29-W29 -> 0 | AI29: =N29-X29 -> 0 | AJ29: =O29-Y29 -> 0 | AK29: =P29-Z29 -> 0
A30: lgh_other_assets | B30: Total Capital Raised Other Projects | C30: Other Project Capital needs | D30: =lgh_bs!D30 -> 0 | E30: =lgh_bs!E30 -> 0 | F30: =lgh_bs!F30 -> 0 | G30: =lgh_bs!G30 -> 0 | H30: =lgh_bs!H30 -> 0 | I30: =lgh_bs!I30 -> 0 | J30: =lgh_bs!J30 -> 0 | K30: =lgh_bs!K30 -> 0 | ... P30: =lgh_bs!P30 -> 0 | R30: 0 | S30: 0 | T30: 0 | U30: 0 | V30: 0 | W30: 0 | X30: 0 | Y30: 0 | Z30: 0 | AB30: Other Project Capital needs | AC30: =H30-R30 -> 0 | AD30: =I30-S30 -> 0 | AE30: =J30-T30 -> 0 | AF30: =K30-U30 -> 0 | AG30: =L30-V30 -> 0 | AH30: =M30-W30 -> 0 | AI30: =N30-X30 -> 0 | AJ30: =O30-Y30 -> 0 | AK30: =P30-Z30 -> 0
A31: lgh_other_liabs | B31: balance | C31: LGH other | D31: =lgh_bs!D31 -> 812241.1 | E31: =lgh_bs!E31 -> 3383115.8 | F31: =lgh_bs!F31 -> 5020671.4 | G31: =lgh_bs!G31 -> 5081889.2 | H31: =lgh_bs!H31 -> 6989833.7 | I31: =lgh_bs!I31 -> 8001344.4 | J31: =lgh_bs!J31 -> 8575801.2 | K31: =lgh_bs!K31 -> 8582691.7 | ... P31: =lgh_bs!P31 -> 27995423 | R31: 6989833.7 | S31: 8001344.4 | T31: 8575801.2 | U31: 8582691.7 | V31: 17286474 | W31: 18797445 | X31: 21168562 | Y31: 24343846 | Z31: 27995423 | AB31: LGH other | AC31: =H31-R31 -> 0 | AD31: =I31-S31 -> 0 | AE31: =J31-T31 -> 0 | AF31: =K31-U31 -> 0 | AG31: =L31-V31 -> 0 | AH31: =M31-W31 -> 0 | AI31: =N31-X31 -> 0 | AJ31: =O31-Y31 -> 0 | AK31: =P31-Z31 -> 0
C32: Total Liabilities | D32: =lgh_bs!D32 -> 26199318 | E32: =lgh_bs!E32 -> 32390298 | F32: =lgh_bs!F32 -> 35170568 | G32: =lgh_bs!G32 -> 14218801 | H32: =lgh_bs!H32 -> 15565466 | I32: =lgh_bs!I32 -> 15901473 | J32: =lgh_bs!J32 -> 20815024 | K32: =lgh_bs!K32 -> 20778684 | ... P32: =lgh_bs!P32 -> 27995423 | R32: 15565466 | S32: 15901473 | T32: 20815024 | U32: 20778684 | V32: 24686988 | W32: 18797445 | X32: 21168562 | Y32: 24343846 | Z32: 27995423 | AB32: Total Liabilities | AC32: =H32-R32 -> 0 | AD32: =I32-S32 -> 0 | AE32: =J32-T32 -> 0 | AF32: =K32-U32 -> 0 | AG32: =L32-V32 -> 0 | AH32: =M32-W32 -> 0 | AI32: =N32-X32 -> 0 | AJ32: =O32-Y32 -> 0 | AK32: =P32-Z32 -> 0
C33: Net Asset Value (NAV) | D33: =lgh_bs!D33 -> 1.1977301e+08 | E33: =lgh_bs!E33 -> 1.3409093e+08 | F33: =lgh_bs!F33 -> 1.3709758e+08 | G33: =lgh_bs!G33 -> 1.6087159e+08 | H33: =lgh_bs!H33 -> 1.5313392e+08 | I33: =lgh_bs!I33 -> 1.5821673e+08 | J33: =lgh_bs!J33 -> 1.6647326e+08 | K33: =lgh_bs!K33 -> 1.7565234e+08 | ... P33: =lgh_bs!P33 -> 3.8760051e+08 | R33: 1.5313392e+08 | S33: 1.5821673e+08 | T33: 1.6647326e+08 | U33: 1.7565234e+08 | V33: 1.9199056e+08 | W33: 2.2561426e+08 | X33: 2.7439676e+08 | Y33: 3.3144893e+08 | Z33: 3.8760051e+08 | AB33: Net Asset Value (NAV) | AC33: =H33-R33 -> 0 | AD33: =I33-S33 -> 0 | AE33: =J33-T33 -> 0 | AF33: =K33-U33 -> 0 | AG33: =L33-V33 -> 0 | AH33: =M33-W33 -> 0 | AI33: =N33-X33 -> 0 | AJ33: =O33-Y33 -> 0 | AK33: =P33-Z33 -> 0
C34: Shareholders' Equity | D34: =lgh_bs!D34 -> 0 | E34: =lgh_bs!E34 -> 0 | F34: =lgh_bs!F34 -> 0 | G34: =lgh_bs!G34 -> 0 | H34: =lgh_bs!H34 -> 0 | I34: =lgh_bs!I34 -> 0 | J34: =lgh_bs!J34 -> 0 | K34: =lgh_bs!K34 -> 0 | ... P34: =lgh_bs!P34 -> 0 | R34: 0 | S34: 0 | T34: 0 | U34: 0 | V34: 0 | W34: 0 | X34: 0 | Y34: 0 | Z34: 0 | AB34: Shareholders' Equity | AC34: =H34-R34 -> 0 | AD34: =I34-S34 -> 0 | AE34: =J34-T34 -> 0 | AF34: =K34-U34 -> 0 | AG34: =L34-V34 -> 0 | AH34: =M34-W34 -> 0 | AI34: =N34-X34 -> 0 | AJ34: =O34-Y34 -> 0 | AK34: =P34-Z34 -> 0
A35: lgh_ci | B35: total | C35: Carried Interest | D35: =lgh_bs!D35 -> 0 | E35: =lgh_bs!E35 -> 0 | F35: =lgh_bs!F35 -> 0 | G35: =lgh_bs!G35 -> 3805056.4 | H35: =lgh_bs!H35 -> 1096872.2 | I35: =lgh_bs!I35 -> 2875854.6 | J35: =lgh_bs!J35 -> 5765639.9 | K35: =lgh_bs!K35 -> 8978320.2 | ... P35: =lgh_bs!P35 -> 83160179 | R35: 1096872.2 | S35: 2875854.6 | T35: 5765639.9 | U35: 8978320.2 | V35: 14696697 | W35: 26464990 | X35: 43538866 | Y35: 63507124 | Z35: 83160179 | AB35: Carried Interest | AC35: =H35-R35 -> 0 | AD35: =I35-S35 -> 0 | AE35: =J35-T35 -> 0 | AF35: =K35-U35 -> 0 | AG35: =L35-V35 -> 0 | AH35: =M35-W35 -> 0 | AI35: =N35-X35 -> 0 | AJ35: =O35-Y35 -> 0 | AK35: =P35-Z35 -> 0
A36: lgh_pref | B36: balance | C36: Preferred Equity | D36: =lgh_bs!D36 -> 51080209 | E36: =lgh_bs!E36 -> 49890886 | F36: =lgh_bs!F36 -> 50888704 | G36: =lgh_bs!G36 -> 51906478 | H36: =lgh_bs!H36 -> 54144869 | I36: =lgh_bs!I36 -> 56742198 | J36: =lgh_bs!J36 -> 58896376 | K36: =lgh_bs!K36 -> 60074303 | ... P36: =lgh_bs!P36 -> 87446502 | R36: 54144869 | S36: 56742198 | T36: 58896376 | U36: 60074303 | V36: 64275789 | W36: 69417853 | X36: 74971281 | Y36: 80968983 | Z36: 87446502 | AB36: Preferred Equity | AC36: =H36-R36 -> 0 | AD36: =I36-S36 -> 0 | AE36: =J36-T36 -> 0 | AF36: =K36-U36 -> 0 | AG36: =L36-V36 -> 0 | AH36: =M36-W36 -> 0 | AI36: =N36-X36 -> 0 | AJ36: =O36-Y36 -> 0 | AK36: =P36-Z36 -> 0
A37: cuda | B37: Distribution (cuda for pref) | C37: CUDA | D37: =lgh_bs!D37 -> -6000000 | E37: =lgh_bs!E37 -> 6050000 | F37: =lgh_bs!F37 -> 0 | G37: =lgh_bs!G37 -> 0 | H37: =lgh_bs!H37 -> 0 | I37: =lgh_bs!I37 -> 0 | J37: =lgh_bs!J37 -> 0 | K37: =lgh_bs!K37 -> 0 | ... P37: =lgh_bs!P37 -> 0 | R37: 0 | S37: 0 | T37: 0 | U37: 0 | V37: 0 | W37: 0 | X37: 0 | Y37: 0 | Z37: 0 | AB37: CUDA | AC37: =H37-R37 -> 0 | AD37: =I37-S37 -> 0 | AE37: =J37-T37 -> 0 | AF37: =K37-U37 -> 0 | AG37: =L37-V37 -> 0 | AH37: =M37-W37 -> 0 | AI37: =N37-X37 -> 0 | AJ37: =O37-Y37 -> 0 | AK37: =P37-Z37 -> 0
C38: Common Equity | D38: =lgh_bs!D38 -> 74692801 | E38: =lgh_bs!E38 -> 78150044 | F38: =lgh_bs!F38 -> 86208873 | G38: =lgh_bs!G38 -> 1.0516006e+08 | H38: =lgh_bs!H38 -> 97892179 | I38: =lgh_bs!I38 -> 98598675 | J38: =lgh_bs!J38 -> 1.0181124e+08 | K38: =lgh_bs!K38 -> 1.0659972e+08 | ... P38: =lgh_bs!P38 -> 2.1699383e+08 | R38: 97892179 | S38: 98598675 | T38: 1.0181124e+08 | U38: 1.0659972e+08 | V38: 1.1301808e+08 | W38: 1.2973141e+08 | X38: 1.5588661e+08 | Y38: 1.8697282e+08 | Z38: 2.1699383e+08 | AB38: Common Equity | AC38: =H38-R38 -> 0 | AD38: =I38-S38 -> 0 | AE38: =J38-T38 -> 0 | AF38: =K38-U38 -> 0 | AG38: =L38-V38 -> 0 | AH38: =M38-W38 -> 0 | AI38: =N38-X38 -> 0 | AJ38: =O38-Y38 -> 0 | AK38: =P38-Z38 -> 0
C39: Total Shareholder's Equity | D39: =lgh_bs!D39 -> 1.1977301e+08 | E39: =lgh_bs!E39 -> 1.3409093e+08 | F39: =lgh_bs!F39 -> 1.3709758e+08 | G39: =lgh_bs!G39 -> 1.6087159e+08 | H39: =lgh_bs!H39 -> 1.5313392e+08 | I39: =lgh_bs!I39 -> 1.5821673e+08 | J39: =lgh_bs!J39 -> 1.6647326e+08 | K39: =lgh_bs!K39 -> 1.7565234e+08 | ... P39: =lgh_bs!P39 -> 3.8760051e+08 | R39: 1.5313392e+08 | S39: 1.5821673e+08 | T39: 1.6647326e+08 | U39: 1.7565234e+08 | V39: 1.9199056e+08 | W39: 2.2561426e+08 | X39: 2.7439676e+08 | Y39: 3.3144893e+08 | Z39: 3.8760051e+08 | AB39: Total Shareholder's Equity | AC39: =H39-R39 -> 0 | AD39: =I39-S39 -> 0 | AE39: =J39-T39 -> 0 | AF39: =K39-U39 -> 0 | AG39: =L39-V39 -> 0 | AH39: =M39-W39 -> 0 | AI39: =N39-X39 -> 0 | AJ39: =O39-Y39 -> 0 | AK39: =P39-Z39 -> 0
A40: Austin Lady Bird Lake | B40: Pref Liquidation adj. | C40: Austin Pref Liquidation adj. | D40: =lgh_bs!D40 -> 0 | E40: =lgh_bs!E40 -> 0 | F40: =lgh_bs!F40 -> 0 | G40: =lgh_bs!G40 -> 0 | H40: =lgh_bs!H40 -> -4196895.7 | I40: =lgh_bs!I40 -> -4334704.6 | J40: =lgh_bs!J40 -> -4478646.1 | K40: =lgh_bs!K40 -> -4629028.8 | ... P40: =lgh_bs!P40 -> 0 | R40: -4196895.7 | S40: -4334704.6 | T40: -4478646.1 | U40: -4629028.8 | V40: -4784461.1 | W40: -3951666.5 | X40: -975331.81 | Y40: -771958.81 | Z40: 0 | AB40: Austin Pref Liquidation adj. | AC40: =H40-R40 -> 0 | AD40: =I40-S40 -> 0 | AE40: =J40-T40 -> 0 | AF40: =K40-U40 -> 0 | AG40: =L40-V40 -> 0 | AH40: =M40-W40 -> 0 | AI40: =N40-X40 -> 0 | AJ40: =O40-Y40 -> 0 | AK40: =P40-Z40 -> 0
...

Sheet lgh_bs
A1: Entity | B1: Subcategory | C1: {=_xlfn.TEXTAFTER(CELL("filename",C1),"]")} -> lgh_bs
C2: Year | D2: 45657 | E2: 45747 | F2: 45838 | G2: 45930 | H2: 46022 | I2: 46112 | J2: 46203 | K2: 46295 | L2: 46387 | M2: 46752 | N2: 47118 | O2: 47483 | P2: 47848
C3: Period | D3: Q4 | E3: Q1 | F3: Q2 | G3: Q3 | H3: Q4 | I3: Q1 | J3: Q2 | K3: Q3 | L3: Q4 | M3: Q4 | N3: Q4 | O3: Q4 | P3: Q4
C4: Assets
A5: lgh_oc | B5: Cumm cash balance | C5: Cash | D5: 251128 | E5: =+registry!C82 -> 2637541.5 | F5: =+registry!D82 -> -866943.45 | G5: =+registry!E82 -> -2782648.6 | H5: =+registry!F82 -> 420309.59 | I5: =+registry!G82 -> 5306065 | J5: =+registry!H82 -> 10576672 | K5: =+registry!I82 -> 7017080.3 | L5: =+registry!J82 -> 2766709.9 | ... P5: =+registry!N82 -> 27568985
C6: Bermuda | D6: 56391899 | E6: =SUM(E7:E7) -> 48342875 | F6: =SUM(F7:F7) -> 49230680 | G6: =SUM(G7:G7) -> 51936303 | H6: =SUM(H7:H7) -> 46803857 | I6: =SUM(I7:I7) -> 46688396 | J6: =SUM(J7:J7) -> 47318459 | K6: =SUM(K7:K7) -> 47193849 | L6: =SUM(L7:L7) -> 60232309 | ... P6: =SUM(P7:P7) -> 85421360
A7: Bermuda Pink Beach | B7: Level 1 | C7: Equity | D7: 56391899 | E7: =+registry!C7 -> 48342875 | F7: =+registry!D7 -> 49230680 | G7: =+registry!E7 -> 51936303 | H7: =+registry!F7 -> 46803857 | I7: =+registry!G7 -> 46688396 | J7: =+registry!H7 -> 47318459 | K7: =+registry!I7 -> 47193849 | L7: =+registry!J7 -> 60232309 | ... P7: =+registry!N7 -> 85421360
C8: Austin | D8: 30156389 | E8: =SUM(E9:E12) -> 26787736 | F8: =SUM(F9:F12) -> 26482398 | G8: =SUM(G9:G12) -> 24312675 | H8: =SUM(H9:H12) -> 18560900 | I8: =SUM(I9:I12) -> 18168835 | J8: =SUM(J9:J12) -> 20455751 | K8: =SUM(K9:K12) -> 20019626 | L8: =SUM(L9:L12) -> 20380869 | ... P8: =SUM(P9:P12) -> 47083185
A9: Austin Lady Bird Lake | B9: LGH NAV | C9: Equity | D9: 15926855 | E9: =+registry!C12 -> 18088592 | F9: =+registry!D12 -> 17359150 | G9: =+registry!E12 -> 15109714 | H9: =+registry!F12 -> 7753407.4 | I9: =+registry!G12 -> 6038275.4 | J9: =+registry!H12 -> 4849926.1 | K9: =+registry!I12 -> 3974250.2 | L9: =+registry!J12 -> 3116853.8 | ... P9: =+registry!N12 -> 0
A10: Austin Lady Bird Lake | B10: Pref Owned | C10: Preferred Equity | D10: 5608281.4 | E10: =+registry!C14 -> 5792434.5 | F10: =+registry!D14 -> 5984782.4 | G10: =+registry!E14 -> 6185737.8 | H10: =+registry!F14 -> 6393440.8 | I10: =+registry!G14 -> 6603375.3 | J10: =+registry!H14 -> 6822651.9 | K10: =+registry!I14 -> 7051741.1 | L10: =+registry!J14 -> 7288522.5 | ... P10: =+registry!N14 -> 4764456.8
A11: Austin Lady Bird Lake | B11: Mezz Owned | C11: Mezz Loan | D11: 8621252.7 | E11: =+registry!C13 -> 2691709.1 | F11: =+registry!D13 -> 2849465 | G11: =+registry!E13 -> 3017222.8 | H11: =+registry!F13 -> 4124556.9 | I11: =+registry!G13 -> 4237689.3 | J11: =+registry!H13 -> 6873678.2 | K11: =+registry!I13 -> 7084139.4 | L11: =+registry!J13 -> 7315998.2 | ... P11: =+registry!N13 -> 42318729
C12: STL | D12: =registry!B18 -> 0 | E12: =registry!C18 -> 215000 | F12: =registry!D18 -> 289000 | G12: =registry!E18 -> 0 | H12: =registry!F18 -> 289495 | I12: =registry!G18 -> 1289495 | J12: =registry!H18 -> 1909495 | K12: =registry!I18 -> 1909495 | ... P12: =registry!N18 -> 0
C13: Turks | D13: 30602658 | E13: =SUM(E14) -> 35723216 | F13: =SUM(F14) -> 38565928 | G13: =SUM(G14) -> 40379581 | H13: =SUM(H14) -> 40032701 | I13: =SUM(I14) -> 36265000 | J13: =SUM(J14) -> 38900747 | K13: =SUM(K14) -> 41760245 | L13: =SUM(L14) -> 50265874 | ... P13: =SUM(P14) -> 37231193
A14: Turks & Caicos | B14: LGH NAV | C14: Equity | D14: 30602658 | E14: =+registry!C23 -> 35723216 | F14: =+registry!D23 -> 38565928 | G14: =+registry!E23 -> 40379581 | H14: =+registry!F23 -> 40032701 | I14: =+registry!G23 -> 36265000 | J14: =+registry!H23 -> 38900747 | K14: =+registry!I23 -> 41760245 | L14: =+registry!J23 -> 50265874 | ... P14: =+registry!N23 -> 37231193
C15: Elbow | D15: 5000000 | E15: =SUM(E16) -> 17383391 | F15: =SUM(F16) -> 19070671 | G15: =SUM(G16) -> 20943032 | H15: =SUM(H16) -> 22999222 | I15: =SUM(I16) -> 28009536 | J15: =SUM(J16) -> 30460557 | K15: =SUM(K16) -> 33156609 | L15: =SUM(L16) -> 36091288 | ... P15: =SUM(P16) -> 104879625
A16: Bermuda: Elbow Beach | B16: LGH NAV | C16: Elbow Beach | D16: 5000000 | E16: =+registry!C33 -> 17383391 | F16: =+registry!D33 -> 19070671 | G16: =+registry!E33 -> 20943032 | H16: =+registry!F33 -> 22999222 | I16: =+registry!G33 -> 28009536 | J16: =+registry!H33 -> 30460557 | K16: =+registry!I33 -> 33156609 | L16: =+registry!J33 -> 36091288 | ... P16: =+registry!N33 -> 104879625
C17: Fritholme | D17: 0 | E17: =SUM(E18) -> 11353680 | F17: =SUM(F18) -> 13799240 | G17: =SUM(G18) -> 15549103 | H17: =SUM(H18) -> 15839974 | I17: =SUM(I18) -> 15929659 | J17: =SUM(J18) -> 15182357 | K17: =SUM(K18) -> 17072720 | L17: =SUM(L18) -> 0 | ... P17: =SUM(P18) -> 0
A18: Fritholme | B18: LGH NAV | C18: Fritholme | D18: 0 | E18: =+registry!C28 -> 11353680 | F18: =+registry!D28 -> 13799240 | G18: =+registry!E28 -> 15549103 | H18: =+registry!F28 -> 15839974 | I18: =+registry!G28 -> 15929659 | J18: =+registry!H28 -> 15182357 | K18: =+registry!I28 -> 17072720 | L18: =+registry!J28 -> 0 | ... P18: =+registry!N28 -> 0
C19: =+C20 -> [LSAT] | D19: 0 | E19: =SUM(E20) -> 0 | F19: =SUM(F20) -> 0 | G19: =SUM(G20) -> 0 | H19: =SUM(H20) -> 0 | I19: =SUM(I20) -> 0 | J19: =SUM(J20) -> 0 | K19: =SUM(K20) -> 0 | L19: =SUM(L20) -> 16000000 | ... P19: =SUM(P20) -> 21709416
A20: lgh_other_assets | B20: [SAT] Balance Sheet | C20: [LSAT] | D20: 0 | E20: =+registry!C78 -> 0 | F20: =+registry!D78 -> 0 | G20: =+registry!E78 -> 0 | H20: =+registry!F78 -> 0 | I20: =+registry!G78 -> 0 | J20: =+registry!H78 -> 0 | K20: =+registry!I78 -> 0 | L20: =+registry!J78 -> 16000000 | ... P20: =+registry!N78 -> 21709416
C21: =+C22 -> [L4] | D21: 0 | E21: =SUM(E22) -> 0 | F21: =SUM(F22) -> 0 | G21: =SUM(G22) -> 0 | H21: =SUM(H22) -> 0 | I21: =SUM(I22) -> 0 | J21: =SUM(J22) -> 0 | K21: =SUM(K22) -> 0 | L21: =SUM(L22) -> 0 | ... P21: =SUM(P22) -> 45000000
A22: lgh_other_assets | B22: [WC] Balance Sheet | C22: [L4] | D22: 0 | E22: =+registry!C79 -> 0 | F22: =+registry!D79 -> 0 | G22: =+registry!E79 -> 0 | H22: =+registry!F79 -> 0 | I22: =+registry!G79 -> 0 | J22: =+registry!H79 -> 0 | K22: =+registry!I79 -> 0 | L22: =+registry!J79 -> 0 | ... P22: =+registry!N79 -> 45000000
C23: =+C24 -> PV Loren fees (Key money) | D23: 20000000 | E23: =SUM(E24) -> 20000000 | F23: =SUM(F24) -> 20000000 | G23: =SUM(G24) -> 20000000 | H23: =SUM(H24) -> 20000000 | I23: =SUM(I24) -> 20600000 | J23: =SUM(J24) -> 21218000 | K23: =SUM(K24) -> 26854540 | L23: =SUM(L24) -> 27660176 | ... P23: =SUM(P24) -> 41436272
A24: c12_hm_oc | B24: PV Loren fees (Key money) | C24: PV Loren fees (Key money) | D24: 20000000 | E24: =+registry!C49 -> 20000000 | F24: =+registry!D49 -> 20000000 | G24: =+registry!E49 -> 20000000 | H24: =+registry!F49 -> 20000000 | I24: =+registry!G49 -> 20600000 | J24: =+registry!H49 -> 21218000 | K24: =+registry!I49 -> 26854540 | L24: =+registry!J49 -> 27660176 | ... P24: =+registry!N49 -> 41436272
C25: Other | D25: 3570254 | E25: =SUM(E26:E26) -> 4252788.9 | F25: =SUM(F26:F26) -> 5986171.9 | G25: =SUM(G26:G26) -> 4752346.8 | H25: =SUM(H26:H26) -> 4042423.2 | I25: =SUM(I26:I26) -> 3150709 | J25: =SUM(J26:J26) -> 3175738.3 | K25: =SUM(K26:K26) -> 3356358.1 | L25: =SUM(L26:L26) -> 3280322 | ... P25: =SUM(P26:P26) -> 5265898.3
A26: lgh_other_assets | B26: Balance | C26: Other Assets | D26: 3570254 | E26: =+registry!C77 -> 4252788.9 | F26: =+registry!D77 -> 5986171.9 | G26: =+registry!E77 -> 4752346.8 | H26: =+registry!F77 -> 4042423.2 | I26: =+registry!G77 -> 3150709 | J26: =+registry!H77 -> 3175738.3 | K26: =+registry!I77 -> 3356358.1 | L26: =+registry!J77 -> 3280322 | ... P26: =+registry!N77 -> 5265898.3
C27: Total assets incl. Cash | D27: 1.4597233e+08 | E27: =SUM(E5,E6,E8,E13,E15,E17,E19,E21,E23,E25) -> 1.6648123e+08 | F27: =SUM(F5,F6,F8,F13,F15,F17,F19,F21,F23,F25) -> 1.7226815e+08 | G27: =SUM(G5,G6,G8,G13,G15,G17,G19,G21,G23,G25) -> 1.7509039e+08 | H27: =SUM(H5,H6,H8,H13,H15,H17,H19,H21,H23,H25) -> 1.6869939e+08 | I27: =SUM(I5,I6,I8,I13,I15,I17,I19,I21,I23,I25) -> 1.741182e+08 | J27: =SUM(J5,J6,J8,J13,J15,J17,J19,J21,J23,J25) -> 1.8728828e+08 | K27: =SUM(K5,K6,K8,K13,K15,K17,K19,K21,K23,K25) -> 1.9643103e+08 | L27: =SUM(L5,L6,L8,L13,L15,L17,L19,L21,L23,L25) -> 2.1667755e+08 | ... P27: =SUM(P5,P6,P8,P13,P15,P17,P19,P21,P23,P25) -> 4.1559593e+08
C28: Liabilities
A29: lgh_debt | B29: Balance: Principal and interest | C29: LGH Debt | D29: 25387077 | E29: =+registry!C66 -> 29007182 | F29: =+registry!D66 -> 30149897 | G29: =+registry!E66 -> 9136912.2 | H29: =+registry!F66 -> 8575632.5 | I29: =+registry!G66 -> 7900128.8 | J29: =+registry!H66 -> 12239223 | K29: =+registry!I66 -> 12195992 | L29: =+registry!J66 -> 7400513.4 | ... P29: =+registry!N66 -> 0
A30: lgh_other_assets | B30: Total Capital Raised Other Projects | C30: Other Project Capital needs | D30: 0 | E30: =+registry!C91 -> 0 | F30: =+registry!D91 -> 0 | G30: =+registry!E91 -> 0 | H30: =+registry!F91 -> 0 | I30: =+registry!G91 -> 0 | J30: =+registry!H91 -> 0 | K30: =+registry!I91 -> 0 | L30: =+registry!J91 -> 0 | ... P30: =+registry!N91 -> 0
A31: lgh_other_liabs | B31: balance | C31: LGH other | D31: 812241.1 | E31: =+registry!C71 -> 3383115.8 | F31: =+registry!D71 -> 5020671.4 | G31: =+registry!E71 -> 5081889.2 | H31: =+registry!F71 -> 6989833.7 | I31: =+registry!G71 -> 8001344.4 | J31: =+registry!H71 -> 8575801.2 | K31: =+registry!I71 -> 8582691.7 | L31: =+registry!J71 -> 17286474 | ... P31: =+registry!N71 -> 27995423
C32: Total Liabilities | D32: 26199318 | E32: =SUM(E29:E31) -> 32390298 | F32: =SUM(F29:F31) -> 35170568 | G32: =SUM(G29:G31) -> 14218801 | H32: =SUM(H29:H31) -> 15565466 | I32: =SUM(I29:I31) -> 15901473 | J32: =SUM(J29:J31) -> 20815024 | K32: =SUM(K29:K31) -> 20778684 | L32: =SUM(L29:L31) -> 24686988 | ... P32: =SUM(P29:P31) -> 27995423
C33: Net Asset Value (NAV) | D33: 1.1977301e+08 | E33: =+E27-E32 -> 1.3409093e+08 | F33: =+F27-F32 -> 1.3709758e+08 | G33: =+G27-G32 -> 1.6087159e+08 | H33: =+H27-H32 -> 1.5313392e+08 | I33: =+I27-I32 -> 1.5821673e+08 | J33: =+J27-J32 -> 1.6647326e+08 | K33: =+K27-K32 -> 1.7565234e+08 | L33: =+L27-L32 -> 1.9199056e+08 | ... P33: =+P27-P32 -> 3.8760051e+08
C34: Shareholders' Equity
A35: lgh_ci | B35: total | C35: Carried Interest | D35: 0 | E35: =+registry!C86 -> 0 | F35: =+registry!D86 -> 0 | G35: =+registry!E86 -> 3805056.4 | H35: =+registry!F86 -> 1096872.2 | I35: =+registry!G86 -> 2875854.6 | J35: =+registry!H86 -> 5765639.9 | K35: =+registry!I86 -> 8978320.2 | L35: =+registry!J86 -> 14696697 | ... P35: =+registry!N86 -> 83160179
A36: lgh_pref | B36: balance | C36: Preferred Equity | D36: 51080209 | E36: =+registry!C62 -> 49890886 | F36: =+registry!D62 -> 50888704 | G36: =+registry!E62 -> 51906478 | H36: =+registry!F62 -> 54144869 | I36: =+registry!G62 -> 56742198 | J36: =+registry!H62 -> 58896376 | K36: =+registry!I62 -> 60074303 | L36: =+registry!J62 -> 64275789 | ... P36: =+registry!N62 -> 87446502
A37: cuda | B37: Distribution (cuda for pref) | C37: CUDA | D37: -6000000 | E37: =-registry!C94 -> 6050000 | F37: =-registry!D94 -> 0 | G37: =-registry!E94 -> 0 | H37: =-registry!F94 -> 0 | I37: =-registry!G94 -> 0 | J37: =-registry!H94 -> 0 | K37: =-registry!I94 -> 0 | L37: =-registry!J94 -> 0 | ... P37: =-registry!N94 -> 0
C38: Common Equity | D38: 74692801 | E38: =+E33-E35-E36-E37 -> 78150044 | F38: =+F33-F35-F36-F37 -> 86208873 | G38: =+G33-G35-G36-G37 -> 1.0516006e+08 | H38: =+H33-H35-H36-H37 -> 97892179 | I38: =+I33-I35-I36-I37 -> 98598675 | J38: =+J33-J35-J36-J37 -> 1.0181124e+08 | K38: =+K33-K35-K36-K37 -> 1.0659972e+08 | L38: =+L33-L35-L36-L37 -> 1.1301808e+08 | ... P38: =+P33-P35-P36-P37 -> 2.1699383e+08
C39: Total Shareholder's Equity | D39: 1.1977301e+08 | E39: =SUM(E35:E38) -> 1.3409093e+08 | F39: =SUM(F35:F38) -> 1.3709758e+08 | G39: =SUM(G35:G38) -> 1.6087159e+08 | H39: =SUM(H35:H38) -> 1.5313392e+08 | I39: =SUM(I35:I38) -> 1.5821673e+08 | J39: =SUM(J35:J38) -> 1.6647326e+08 | K39: =SUM(K35:K38) -> 1.7565234e+08 | L39: =SUM(L35:L38) -> 1.9199056e+08 | ... P39: =SUM(P35:P38) -> 3.8760051e+08
A40: Austin Lady Bird Lake | B40: Pref Liquidation adj. | C40: Austin Pref Liquidation adj. | D40: 0 | E40: =+registry!C16 -> 0 | F40: =+registry!D16 -> 0 | G40: =+registry!E16 -> 0 | H40: =+registry!F16 -> -4196895.7 | I40: =+registry!G16 -> -4334704.6 | J40: =+registry!H16 -> -4478646.1 | K40: =+registry!I16 -> -4629028.8 | L40: =+registry!J16 -> -4784461.1 | ... P40: =+registry!N16 -> 0
...

Sheet lgh_bs_errata

Sheet lgh_bs_qr

Sheet lgh_ci
A1: {=_xlfn.TEXTAFTER(CELL("filename",A1),"]")} -> lgh_ci
A2: Year | B2: 45657 | C2: =+lgh_bs!E2 -> 45747 | D2: =+lgh_bs!F2 -> 45838 | E2: =+lgh_bs!G2 -> 45930 | F2: =+lgh_bs!H2 -> 46022 | G2: =+lgh_bs!I2 -> 46112 | H2: =+lgh_bs!J2 -> 46203 | I2: =+lgh_bs!K2 -> 46295 | J2: =+lgh_bs!L2 -> 46387 | ... N2: =+lgh_bs!P2 -> 47848
A3: Period | B3: Q4 | C3: =+lgh_bs!E3 -> Q1 | D3: =+lgh_bs!F3 -> Q2 | E3: =+lgh_bs!G3 -> Q3 | F3: =+lgh_bs!H3 -> Q4 | G3: =+lgh_bs!I3 -> Q1 | H3: =+lgh_bs!J3 -> Q2 | I3: =+lgh_bs!K3 -> Q3 | J3: =+lgh_bs!L3 -> Q4 | ... N3: =+lgh_bs!P3 -> Q4
