Workbook
Name DepartmentNum: '.c12_inputs.hr'!$E$4

Sheet registry
A1: Year | B1: =+lgh_bs!D2 -> 45657 | C1: =+lgh_bs!E2 -> 45747 | D1: =+lgh_bs!F2 -> 45838 | E1: =+lgh_bs!G2 -> 45930 | F1: =+lgh_bs!H2 -> 46022 | G1: =+lgh_bs!I2 -> 46112 | H1: =+lgh_bs!J2 -> 46203 | I1: =+lgh_bs!K2 -> 46295 | ... N1: =+lgh_bs!P2 -> 47848
A2: subcategory | B2: =+lgh_bs!D3 -> Q4 | C2: =+lgh_bs!E3 -> Q1 | D2: =+lgh_bs!F3 -> Q2 | E2: =+lgh_bs!G3 -> Q3 | F2: =+lgh_bs!H3 -> Q4 | G2: =+lgh_bs!I3 -> Q1 | H2: =+lgh_bs!J3 -> Q2 | I2: =+lgh_bs!K3 -> Q3 | ... N2: =+lgh_bs!P3 -> Q4
A5: Cash Inflows | B5: =+pink_cs2!B17 -> 1562074 | C5: =+pink_cs2!C17 -> 3250000 | D5: =+pink_cs2!D17 -> 3388588 | E5: =+pink_cs2!E17 -> 1475962 | F5: =+pink_cs2!F17 -> 8336733 | G5: =+pink_cs2!G17 -> 0 | H5: =+pink_cs2!H17 -> 0 | I5: =+pink_cs2!I17 -> 0 | ... N5: =+pink_cs2!N17 -> 4123684
A6: Cash Outflows | B6: =+pink_cs2!B25 -> 0 | C6: =+pink_cs2!C25 -> -125000 | D6: =+pink_cs2!D25 -> -3717883 | E6: =+pink_cs2!E25 -> -3472013.3 | F6: =+pink_cs2!F25 -> 0 | G6: =+pink_cs2!G25 -> 0 | H6: =+pink_cs2!H25 -> 0 | I6: =+pink_cs2!I25 -> 0 | ... N6: =+pink_cs2!N25 -> 0
A7: Net Asset Value (NAV) | B7: =+pink_cs2!B60 -> 56391899 | C7: =+pink_cs2!C60 -> 48342875 | D7: =+pink_cs2!D60 -> 49230680 | E7: =+pink_cs2!E60 -> 51936303 | F7: =+pink_cs2!F60 -> 46803857 | G7: =+pink_cs2!G60 -> 46688396 | H7: =+pink_cs2!H60 -> 47318459 | I7: =+pink_cs2!I60 -> 47193849 | ... N7: =+pink_cs2!N60 -> 85421360
A10: Cash Inflows | B10: =+aus_cs2!E19 -> 814451.63 | C10: =+aus_cs2!F19 -> 5515000 | D10: =+aus_cs2!G19 -> 0 | E10: =+aus_cs2!H19 -> 525000 | F10: =+aus_cs2!I19 -> 0 | G10: =+aus_cs2!J19 -> 0 | H10: =+aus_cs2!K19 -> 0 | I10: =+aus_cs2!L19 -> 0 | ... N10: =+aus_cs2!Q19 -> 0
A11: Cash Outflows | B11: =+aus_cs2!E28 -> 0 | C11: =+aus_cs2!F28 -> -50000 | D11: =+aus_cs2!G28 -> -2025000 | E11: =+aus_cs2!H28 -> -230000 | F11: =+aus_cs2!I28 -> -289495 | G11: =+aus_cs2!J28 -> -1750000 | H11: =+aus_cs2!K28 -> -3420000 | I11: =+aus_cs2!L28 -> 0 | ... N11: =+aus_cs2!Q28 -> 0
A12: LGH NAV | B12: =+aus_cs2!E75 -> 15926855 | C12: =+aus_cs2!F75 -> 18088592 | D12: =+aus_cs2!G75 -> 17359150 | E12: =+aus_cs2!H75 -> 15109714 | F12: =+aus_cs2!I75 -> 7753407.4 | G12: =+aus_cs2!J75 -> 6038275.4 | H12: =+aus_cs2!K75 -> 4849926.1 | I12: =+aus_cs2!L75 -> 3974250.2 | ... N12: =+aus_cs2!Q75 -> 0
A13: Mezz Owned | B13: =+aus_cs2!E80 -> 8621252.7 | C13: =+aus_cs2!F80 -> 2691709.1 | D13: =+aus_cs2!G80 -> 2849465 | E13: =+aus_cs2!H80 -> 3017222.8 | F13: =+aus_cs2!I80 -> 4124556.9 | G13: =+aus_cs2!J80 -> 4237689.3 | H13: =+aus_cs2!K80 -> 6873678.2 | I13: =+aus_cs2!L80 -> 7084139.4 | ... N13: =+aus_cs2!Q80 -> 42318729
A14: Pref Owned | B14: =+aus_cs2!E83 -> 5608281.4 | C14: =+aus_cs2!F83 -> 5792434.5 | D14: =+aus_cs2!G83 -> 5984782.4 | E14: =+aus_cs2!H83 -> 6185737.8 | F14: =+aus_cs2!I83 -> 6393440.8 | G14: =+aus_cs2!J83 -> 6603375.3 | H14: =+aus_cs2!K83 -> 6822651.9 | I14: =+aus_cs2!L83 -> 7051741.1 | ... N14: =+aus_cs2!Q83 -> 4764456.8
A15: Net Asset Value (NAV) | B15: =+aus_cs2!E85 -> 30156389 | C15: =+aus_cs2!F85 -> 26572736 | D15: =+aus_cs2!G85 -> 26193398 | E15: =+aus_cs2!H85 -> 24312675 | F15: =+aus_cs2!I85 -> 6321102 | G15: =+aus_cs2!J85 -> 6506360 | H15: =+aus_cs2!K85 -> 9217684.1 | I15: =+aus_cs2!L85 -> 9506851.6 | ... N15: =+aus_cs2!Q85 -> 47083185
A16: Pref Liquidation adj. | B16: =+aus_cs2!E84-aus_cs2!E83 -> 0 | C16: =+aus_cs2!F84-aus_cs2!F83 -> 0 | D16: =+aus_cs2!G84-aus_cs2!G83 -> 0 | E16: =+aus_cs2!H84-aus_cs2!H83 -> 0 | F16: =+aus_cs2!I84-aus_cs2!I83 -> -4196895.7 | G16: =+aus_cs2!J84-aus_cs2!J83 -> -4334704.6 | H16: =+aus_cs2!K84-aus_cs2!K83 -> -4478646.1 | I16: =+aus_cs2!L84-aus_cs2!L83 -> -4629028.8 | ... N16: =+aus_cs2!Q84-aus_cs2!Q83 -> 0
A17: Equity Liquidation adj. | B17: =+aus_cs2!E76-aus_cs2!E75 -> 0 | C17: =+aus_cs2!F76-aus_cs2!F75 -> 0 | D17: =+aus_cs2!G76-aus_cs2!G75 -> 0 | E17: =+aus_cs2!H76-aus_cs2!H75 -> 0 | F17: =+aus_cs2!I76-aus_cs2!I75 -> -7753407.4 | G17: =+aus_cs2!J76-aus_cs2!J75 -> -6038275.4 | H17: =+aus_cs2!K76-aus_cs2!K75 -> -4849926.1 | I17: =+aus_cs2!L76-aus_cs2!L75 -> -3974250.2 | ... N17: =+aus_cs2!Q76-aus_cs2!Q75 -> 0
B18: =-aus_cs2!E64 -> 0 | C18: =-aus_cs2!F64 -> 215000 | D18: =-aus_cs2!G64 -> 289000 | E18: =-aus_cs2!H64 -> 0 | F18: =-aus_cs2!I64 -> 289495 | G18: =-aus_cs2!J64 -> 1289495 | H18: =-aus_cs2!K64 -> 1909495 | I18: =-aus_cs2!L64 -> 1909495 | ... N18: =-aus_cs2!Q64 -> 0
A21: Cash Inflows | B21: =+turks_cs2!B20 -> 0 | C21: =+turks_cs2!C20 -> 0 | D21: =+turks_cs2!D20 -> 0 | E21: =+turks_cs2!E20 -> 0 | F21: =+turks_cs2!F20 -> 350000 | G21: =+turks_cs2!G20 -> 0 | H21: =+turks_cs2!H20 -> 350000 | I21: =+turks_cs2!I20 -> 0 | ... N21: =+turks_cs2!N20 -> 1371287
A22: Cash Outflows | B22: =+turks_cs2!B27 -> 0 | C22: =+turks_cs2!C27 -> -382967 | D22: =+turks_cs2!D27 -> -2326328 | E22: =+turks_cs2!E27 -> -3292886 | F22: =+turks_cs2!F27 -> -5106622 | G22: =+turks_cs2!G27 -> -420000 | H22: =+turks_cs2!H27 -> -200000 | I22: =+turks_cs2!I27 -> -150000 | ... N22: =+turks_cs2!N27 -> 0
A23: LGH NAV | B23: =+turks_cs2!B70 -> 30602658 | C23: =+turks_cs2!C70 -> 35723216 | D23: =+turks_cs2!D70 -> 38565928 | E23: =+turks_cs2!E70 -> 40379581 | F23: =+turks_cs2!F70 -> 40032701 | G23: =+turks_cs2!G70 -> 36265000 | H23: =+turks_cs2!H70 -> 38900747 | I23: =+turks_cs2!I70 -> 41760245 | ... N23: =+turks_cs2!N70 -> 37231193
A26: Cash Inflows | B26: =+frith_cs2!B17 -> 0 | C26: =+frith_cs2!C17 -> 0 | D26: =+frith_cs2!D17 -> 0 | E26: =+frith_cs2!E17 -> 0 | F26: =+frith_cs2!F17 -> 0 | G26: =+frith_cs2!G17 -> 2400000 | H26: =+frith_cs2!H17 -> 3600000 | I26: =+frith_cs2!I17 -> 0 | ... N26: =+frith_cs2!N17 -> 0
A27: Cash Outflows | B27: =+frith_cs2!B24 -> 0 | C27: =+frith_cs2!C24 -> 0 | D27: =+frith_cs2!D24 -> 0 | E27: =+frith_cs2!E24 -> 0 | F27: =+frith_cs2!F24 -> -860000 | G27: =+frith_cs2!G24 -> 0 | H27: =+frith_cs2!H24 -> -1750000 | I27: =+frith_cs2!I24 -> 0 | ... N27: =+frith_cs2!N24 -> 0
A28: LGH NAV | B28: =+frith_cs2!B60 -> 0 | C28: =+frith_cs2!C60 -> 11353680 | D28: =+frith_cs2!D60 -> 13799240 | E28: =+frith_cs2!E60 -> 15549103 | F28: =+frith_cs2!F60 -> 15839974 | G28: =+frith_cs2!G60 -> 15929659 | H28: =+frith_cs2!H60 -> 15182357 | I28: =+frith_cs2!I60 -> 17072720 | ... N28: =+frith_cs2!N60 -> 0
A31: Cash Inflows | B31: =+elbow_cs2!B18 -> 0 | C31: =+elbow_cs2!C18 -> 0 | D31: =+elbow_cs2!D18 -> 2500000 | E31: =+elbow_cs2!E18 -> 2500000 | F31: =+elbow_cs2!F18 -> 6137500 | G31: =+elbow_cs2!G18 -> 5640000 | H31: =+elbow_cs2!H18 -> 7300000 | I31: =+elbow_cs2!I18 -> 0 | ... N31: =+elbow_cs2!N18 -> 0
A32: Cash Outflows | B32: =+elbow_cs2!B24 -> 0 | C32: =+elbow_cs2!C24 -> -2500000 | D32: =+elbow_cs2!D24 -> 0 | E32: =+elbow_cs2!E24 -> 0 | F32: =+elbow_cs2!F24 -> 0 | G32: =+elbow_cs2!G24 -> -1000000 | H32: =+elbow_cs2!H24 -> -2040000 | I32: =+elbow_cs2!I24 -> -2000000 | ... N32: =+elbow_cs2!N24 -> 0
A33: LGH NAV | B33: =+elbow_cs2!B53 -> 5000000 | C33: =+elbow_cs2!C53 -> 17383391 | D33: =+elbow_cs2!D53 -> 19070671 | E33: =+elbow_cs2!E53 -> 20943032 | F33: =+elbow_cs2!F53 -> 22999222 | G33: =+elbow_cs2!G53 -> 28009536 | H33: =+elbow_cs2!H53 -> 30460557 | I33: =+elbow_cs2!I53 -> 33156609 | ... N33: =+elbow_cs2!N53 -> 104879625
B36: =sat_cs2!B24 -> 0 | C36: =sat_cs2!C24 -> 0 | D36: =sat_cs2!D24 -> 0 | E36: =sat_cs2!E24 -> 0 | F36: =sat_cs2!F24 -> 0 | G36: =sat_cs2!G24 -> 0 | H36: =sat_cs2!H24 -> 0 | I36: =sat_cs2!I24 -> 0 | ... N36: =sat_cs2!N24 -> 1750000
B37: =sat_cs2!B17 -> 0 | C37: =sat_cs2!C17 -> 0 | D37: =sat_cs2!D17 -> 0 | E37: =sat_cs2!E17 -> 0 | F37: =sat_cs2!F17 -> 0 | G37: =sat_cs2!G17 -> 0 | H37: =sat_cs2!H17 -> 0 | I37: =sat_cs2!I17 -> 0 | ... N37: =sat_cs2!N17 -> 0
A42: Division Expenses
A43: Guarentee Fees | B43: =-(+pink_cs2!B$31+elbow_cs2!B$29+aus_cs2!E$33+turks_cs2!B$32+frith_cs2!B$29) -> 0 | C43: =-(+pink_cs2!C$31+elbow_cs2!C$29+aus_cs2!F$33+turks_cs2!C$32+frith_cs2!C$29) -> 0 | D43: =-(+pink_cs2!D$31+elbow_cs2!D$29+aus_cs2!G$33+turks_cs2!D$32+frith_cs2!D$29) -> 0 | E43: =-(+pink_cs2!E$31+elbow_cs2!E$29+aus_cs2!H$33+turks_cs2!E$32+frith_cs2!E$29) -> 0 | F43: =-(+pink_cs2!F$31+elbow_cs2!F$29+aus_cs2!I$33+turks_cs2!F$32+frith_cs2!F$29) -> 0 | G43: =-(+pink_cs2!G$31+elbow_cs2!G$29+aus_cs2!J$33+turks_cs2!G$32+frith_cs2!G$29) -> 0 | H43: =-(+pink_cs2!H$31+elbow_cs2!H$29+aus_cs2!K$33+turks_cs2!H$32+frith_cs2!H$29) -> 0 | I43: =-(+pink_cs2!I$31+elbow_cs2!I$29+aus_cs2!L$33+turks_cs2!I$32+frith_cs2!I$29) -> 0 | ... N43: =-(+pink_cs2!N$31+elbow_cs2!N$29+aus_cs2!Q$33+turks_cs2!N$32+frith_cs2!N$29) -> 0
A46: Total LGH HM Fees | B46: =+'c12_hm'!E60 -> 0 | C46: =+'c12_hm'!L60 -> 558947 | D46: =+'c12_hm'!M60 -> 558947 | E46: =+'c12_hm'!N60 -> 558947 | F46: =+'c12_hm'!O60 -> 447597 | G46: =+'c12_hm'!P60 -> 310715.79 | H46: =+'c12_hm'!Q60 -> 902637.29 | I46: =+'c12_hm'!R60 -> 948110.97 | J46: =+'c12_hm'!S60 -> 2385063.6 | ... N46: =+'c12_hm'!W60 -> 8232870
A47: c12 Participation | B47: =+'c12_hm'!E70 -> 0 | C47: =+'c12_hm'!L70 -> 558947 | D47: =+'c12_hm'!M70 -> 558947 | E47: =+'c12_hm'!N70 -> 558947 | F47: =+'c12_hm'!O70 -> 447597 | G47: =+'c12_hm'!P70 -> 63035.789 | H47: =+'c12_hm'!Q70 -> 398173.65 | I47: =+'c12_hm'!R70 -> 400447.34 | J47: =+'c12_hm'!S70 -> 662529.63 | ... N47: =+'c12_hm'!W70 -> 2432050.8
A49: PV Loren fees (Key money) | B49: =+lgh_manco!C8 -> 20000000 | C49: =+lgh_manco!D8 -> 20000000 | D49: =+lgh_manco!E8 -> 20000000 | E49: =+lgh_manco!F8 -> 20000000 | F49: =+lgh_manco!G8 -> 20000000 | G49: =+lgh_manco!H8 -> 20000000 | H49: =+lgh_manco!I8 -> 20000000 | I49: =+lgh_manco!J8 -> 25000000 | ... N49: =+lgh_manco!O8 -> 35000000
A50: Enterprise value | B50: =+lgh_manco!C10 -> 10000000 | C50: =+lgh_manco!D10 -> 10000000 | D50: =+lgh_manco!E10 -> 10000000 | E50: =+lgh_manco!F10 -> 10000000 | F50: =+lgh_manco!G10 -> 10000000 | G50: =+lgh_manco!H10 -> 10000000 | H50: =+lgh_manco!I10 -> 12000000 | I50: =+lgh_manco!J10 -> 17500000 | ... N50: =+lgh_manco!O10 -> 70000000
A51: Other EV | B51: =+lgh_manco!C11 -> 0 | C51: =+lgh_manco!D11 -> 0 | D51: =+lgh_manco!E11 -> 0 | E51: =+lgh_manco!F11 -> 0 | F51: =+lgh_manco!G11 -> 0 | G51: =+lgh_manco!H11 -> 0 | H51: =+lgh_manco!I11 -> 0 | I51: =+lgh_manco!J11 -> 0 | ... N51: =+lgh_manco!O11 -> 100000000
A55: Total LGH D&s Fees | B55: ='c12_d&s'!E60 -> 0 | C55: ='c12_d&s'!L60 -> 128735.5 | D55: ='c12_d&s'!M60 -> 128735.5 | E55: ='c12_d&s'!N60 -> 699135.5 | F55: ='c12_d&s'!O60 -> 911235.5 | G55: ='c12_d&s'!P60 -> 1735259.1 | H55: ='c12_d&s'!Q60 -> 2473819.8 | I55: ='c12_d&s'!R60 -> 2205638.8 | J55: ='c12_d&s'!S60 -> 5828630.3 | ... N55: ='c12_d&s'!W60 -> 4361744.7
A56: c12 D&s Participation | B56: ='c12_d&s'!E70 -> 0 | C56: ='c12_d&s'!L70 -> 64367.75 | D56: ='c12_d&s'!M70 -> 64367.75 | E56: ='c12_d&s'!N70 -> 349567.75 | F56: ='c12_d&s'!O70 -> 455617.75 | G56: ='c12_d&s'!P70 -> 806580.95 | H56: ='c12_d&s'!Q70 -> 1015405.1 | I56: ='c12_d&s'!R70 -> 935314.59 | J56: ='c12_d&s'!S70 -> 2208920.6 | ... N56: ='c12_d&s'!W70 -> 1408540.1
A58: total c12 participation | B58: ='c12_oc'!E10 -> 2452451 | C58: ='c12_oc'!L10 -> 623314.75 | D58: ='c12_oc'!M10 -> 623314.75 | E58: ='c12_oc'!N10 -> 908514.75 | F58: ='c12_oc'!O10 -> 903214.75 | G58: ='c12_oc'!P10 -> 886331.48 | H58: ='c12_oc'!Q10 -> 1430293.5 | I58: ='c12_oc'!R10 -> 1358160.9 | J58: ='c12_oc'!S10 -> 2898497.4 | ... N58: ='c12_oc'!W10 -> 3977928.6
A59: total lgh revenue | B59: ='c12_oc'!E87 -> 0 | C59: ='c12_oc'!L87 -> 687682.5 | D59: ='c12_oc'!M87 -> 687682.5 | E59: ='c12_oc'!N87 -> 1258082.5 | F59: ='c12_oc'!O87 -> 1358832.5 | G59: ='c12_oc'!P87 -> 2200269.7 | H59: ='c12_oc'!Q87 -> 3530751.8 | I59: ='c12_oc'!R87 -> 3421728.7 | J59: ='c12_oc'!S87 -> 8574636 | ... N59: ='c12_oc'!W87 -> 13901367
A60: art leases | B60: =lgh_oc!B8 -> 0 | C60: =lgh_oc!C8 -> 0 | D60: =lgh_oc!D8 -> 0 | E60: =lgh_oc!E8 -> 0 | F60: =lgh_oc!F8 -> 0 | G60: =lgh_oc!G8 -> 50000 | H60: =lgh_oc!H8 -> 50000 | I60: =lgh_oc!I8 -> 50000 | ... N60: =lgh_oc!N8 -> 250000
A62: balance | B62: =+lgh_pref_equity!L47 -> 51080209 | C62: =+lgh_pref_equity!M47 -> 49890886 | D62: =+lgh_pref_equity!N47 -> 50888704 | E62: =+lgh_pref_equity!O47 -> 51906478 | F62: =+lgh_pref_equity!P47 -> 54144869 | G62: =+lgh_pref_equity!Q47 -> 56742198 | H62: =+lgh_pref_equity!R47 -> 58896376 | I62: =+lgh_pref_equity!S47 -> 60074303 | ... N62: =+lgh_pref_equity!X47 -> 87446502
A63: Total Sources/In from Pref | B63: =+lgh_pref_equity!L55 -> 0 | C63: =+lgh_pref_equity!M55 -> 6050000 | D63: =+lgh_pref_equity!N55 -> 0 | E63: =+lgh_pref_equity!O55 -> 0 | F63: =+lgh_pref_equity!P55 -> 1200000 | G63: =+lgh_pref_equity!Q55 -> 1500000 | H63: =+lgh_pref_equity!R55 -> 1000000 | I63: =+lgh_pref_equity!S55 -> 0 | ... N63: =+lgh_pref_equity!X55 -> 0
A66: Balance: Principal and interest | B66: =+lgh_debt!G33 -> 25387077 | C66: =+lgh_debt!I33 -> 29007182 | D66: =+lgh_debt!K33 -> 30149897 | E66: =+lgh_debt!M33 -> 9136912.2 | F66: =+lgh_debt!O33 -> 8575632.5 | G66: =+lgh_debt!Q33 -> 7900128.8 | H66: =+lgh_debt!S33 -> 12239223 | I66: =+lgh_debt!U33 -> 12195992 | J66: =+lgh_debt!W33 -> 7400513.4 | K66: =+lgh_debt!Y33 -> 0 | L66: =+lgh_debt!AA33 -> 0 | M66: =+lgh_debt!AC33 -> 0 | N66: =+lgh_debt!AE33 -> 0
...

Sheet lgh_returns
D2: LEVERED RETURN ANCHORS | K2: UNLEVERED RETURN ANCHORS | R2: UNLEVERED RETURN ANCHORS
D3: Initial Adj. Common (Q1 2026) | E3: =(lgh_bs!I51*E4)/1000000 -> 107.16384 | K3: Initial Adj. Unlevered Equity (Q1 2026) | L3: =(lgh_bs!I53*$L$4)/1000000 -> 154.89325 | R3: Initial Adj. Unlevered Equity (Q1 2026) | S3: 154.45991
D4: Discount Factor (1.0 = no discount) | E4: =1-E5 -> 1 | K4: Discount Factor (1.0 = no discount) | L4: =1-L5 -> 1 | R4: Discount Factor (1.0 = no discount) | S4: 1
D5: Applied Discount | E5: 0 | K5: Applied Discount | L5: 0 | R5: Applied Discount | S5: 0
E8: Levered Return Metrics | L8: Unlevered Return Metrics | S8: Unlevered Return Metrics
C9: 2026 | D9: 2027 | E9: 2028 | F9: 2029 | G9: 2030 | J9: 2026 | K9: 2027 | L9: 2028 | M9: 2029 | N9: 2030 | Q9: 2026 | R9: 2027 | S9: 2028 | T9: 2029 | U9: 2030
C10: Common Equity | J10: Total Shareholder's Equity (SE) + Reserve - C/I | Q10: Total Shareholder's Equity (SE) + Reserve - C/I
C11: =(+lgh_bs!L38)/1000000 -> 111.47796 | D11: =(+lgh_bs!M38)/1000000 -> 127.65759 | E11: =(+lgh_bs!N38)/1000000 -> 153.26308 | F11: =(+lgh_bs!O38)/1000000 -> 183.68558 | G11: =(+lgh_bs!P38)/1000000 -> 213.02297 | J11: =(lgh_bs!L39-lgh_bs!L35+lgh_bs!L41+lgh_bs!L40)/1000000 -> 167.85243 | K11: =(lgh_bs!M39-lgh_bs!M35+lgh_bs!M41+lgh_bs!M40)/1000000 -> 193.12378 | L11: =(lgh_bs!N39-lgh_bs!N35+lgh_bs!N41+lgh_bs!N40)/1000000 -> 227.25903 | M11: =(lgh_bs!O39-lgh_bs!O35+lgh_bs!O41+lgh_bs!O40)/1000000 -> 263.8826 | N11: =(lgh_bs!P39-lgh_bs!P35+lgh_bs!P41+lgh_bs!P40)/1000000 -> 300.46947 | Q11: 168.53976 | R11: 194.24565 | S11: 228.88667 | T11: 266.12869 | U11: 303.35256
B12: Mult | C12: =+C11/$E3 -> 1.0402572 | D12: =+D11/$E3 -> 1.1912376 | E12: =+E11/$E3 -> 1.4301753 | F12: =+F11/$E3 -> 1.714063 | G12: =+G11/$E3 -> 1.9878251 | I12: Mult | J12: =+J11/$L$3 -> 1.0836653 | K12: =+K11/$L$3 -> 1.2468186 | L12: =+L11/$L$3 -> 1.4671978 | M12: =+M11/$L$3 -> 1.7036417 | N12: =+N11/$L$3 -> 1.9398488 | P12: Mult | Q12: 1.0911554 | R12: 1.2575797 | S12: 1.4818516 | T12: 1.7229628 | U12: 1.9639566
B13: YoY | C13: =+C11/E3-1 -> 0.040257215 | D13: =+D11/C11-1 -> 0.14513752 | E13: =+E11/D11-1 -> 0.20057941 | F13: =+F11/E11-1 -> 0.19849855 | G13: =+G11/F11-1 -> 0.15971528 | I13: YoY | J13: =+J11/L3-1 -> 0.083665283 | K13: =+K11/J11-1 -> 0.15055692 | L13: =+L11/K11-1 -> 0.17675321 | M13: =+M11/L11-1 -> 0.16115344 | N13: =+N11/M11-1 -> 0.13864829 | P13: YoY | Q13: 0.09115538 | R13: 0.15252121 | S13: 0.17833613 | T13: 0.16270942 | U13: 0.13987169
B14: Q1 2026 | C14: =(C11/$E3)^(1/((lgh_bs!L$2-lgh_bs!$I$2)/365))-1 -> 0.053781165 | D14: =(D11/$E3)^(1/((lgh_bs!M$2-lgh_bs!$I$2)/365))-1 -> 0.10495051 | E14: =($E$11/$E$3)^(1/((lgh_bs!$N$2-lgh_bs!$I$2)/365))-1 -> 0.13862001 | F14: =(F11/$E3)^(1/((lgh_bs!O$2-lgh_bs!$I$2)/365))-1 -> 0.15426286 | G14: =($G$11/$E$3)^(1/((lgh_bs!$P$2-lgh_bs!$I$2)/365))-1 -> 0.15540712 | I14: Q1 2026 | J14: =+(J11/$L$3)^(1/((lgh_bs!L$2-lgh_bs!$I$2)/365))-1 -> 0.11253939 | K14: =+(K11/$L$3)^(1/((lgh_bs!M$2-lgh_bs!$I$2)/365))-1 -> 0.13406462 | L14: =+(L11/$L$3)^(1/((lgh_bs!N$2-lgh_bs!$I$2)/365))-1 -> 0.14922728 | M14: =+(M11/$L$3)^(1/((lgh_bs!O$2-lgh_bs!$I$2)/365))-1 -> 0.15239035 | N14: =+(N11/$L$3)^(1/((lgh_bs!P$2-lgh_bs!$I$2)/365))-1 -> 0.14948733 | P14: Q1 2026 | Q14: 0.1227572 | R14: 0.13963651 | S14: 0.15337861 | T14: 0.1558554 | U14: 0.15247627
C16: Common + Pref MTM + Austin Adj. + Loren EV | J16: Total SE + Reserve - C/I + Loren EV | Q16: Total SE + Reserve - C/I + Loren EV
C17: =C11+(SUM(lgh_bs!L40:L42)/1000000)*(1-lgh_inputs!$D$4)+(lgh_bs!L46/1000000) -> 128.0496 | D17: =D11+(SUM(lgh_bs!M40:M42)/1000000)*(1-lgh_inputs!$D$4)+(lgh_bs!M46/1000000) -> 150.14537 | E17: =E11+(SUM(lgh_bs!N40:N42)/1000000)*(1-lgh_inputs!$D$4)+(lgh_bs!N46/1000000) -> 185.18858 | F17: =F11+(SUM(lgh_bs!O40:O42)/1000000)*(1-lgh_inputs!$D$4)+(lgh_bs!O46/1000000) -> 219.22555 | G17: =G11+(SUM(lgh_bs!P40:P42)/1000000)*(1-lgh_inputs!$D$4)+(lgh_bs!P46/1000000) -> 258.52297 | J17: =J11+(lgh_bs!L42/1000000)*(1-lgh_inputs!$D$4) -> 180.85243 | K17: =K11+(lgh_bs!M42/1000000)*(1-lgh_inputs!$D$4) -> 210.99878 | L17: =L11+(lgh_bs!N42/1000000)*(1-lgh_inputs!$D$4) -> 254.55903 | M17: =M11+(lgh_bs!O42/1000000)*(1-lgh_inputs!$D$4) -> 297.0326 | N17: =N11+(lgh_bs!P42/1000000)*(1-lgh_inputs!$D$4) -> 345.96947 | Q17: 182.92306 | R17: 214.61599 | S17: 260.14033 | T17: 305.21809 | U17: 357.21971
B18: Mult | C18: =+C17/$E$3 -> 1.1948956 | D18: =+D17/$E$3 -> 1.4010824 | E18: =+E17/$E$3 -> 1.7280883 | F18: =+F17/$E$3 -> 2.0457045 | G18: =+G17/$E$3 -> 2.4124086 | I18: Mult | J18: =+J17/$L$3 -> 1.1675941 | K18: =+K17/$L$3 -> 1.3622207 | L18: =+L17/$L$3 -> 1.6434482 | M18: =+M17/$L$3 -> 1.9176601 | N18: =+N17/$L$3 -> 2.2335995 | P18: Mult | Q18: 1.1842753 | R18: 1.3894608 | S18: 1.6841932 | T18: 1.9760343 | U18: 2.3127018
B19: YoY | C19: =+C17/E3-1 -> 0.19489556 | D19: =+D17/C17-1 -> 0.17255637 | E19: =+E17/D17-1 -> 0.23339518 | F19: =+F17/E17-1 -> 0.1837963 | G19: =+G17/F17-1 -> 0.17925564 | I19: YoY | J19: =+J17/L3-1 -> 0.16759406 | K19: =+K17/J17-1 -> 0.1666903 | L19: =+L17/K17-1 -> 0.20644786 | M19: =+M17/L17-1 -> 0.16685157 | N19: =+N17/M17-1 -> 0.16475253 | P19: YoY | Q19: 0.18427528 | R19: 0.17325828 | S19: 0.21211999 | T19: 0.17328246 | U19: 0.1703753
B20: Q1 2026 | C20: =(C17/$E$3)^(1/((lgh_bs!L$2-lgh_bs!$I$2)/365))-1 -> 0.26659547 | D20: =(D17/$E$3)^(1/((lgh_bs!M$2-lgh_bs!$I$2)/365))-1 -> 0.21207659 | E20: =(E17/$E$3)^(1/((lgh_bs!N$2-lgh_bs!$I$2)/365))-1 -> 0.21953535 | F20: =(F17/$E$3)^(1/((lgh_bs!O$2-lgh_bs!$I$2)/365))-1 -> 0.20991651 | G20: =(G17/$E$3)^(1/((lgh_bs!P$2-lgh_bs!$I$2)/365))-1 -> 0.20340446 | I20: Q1 2026 | J20: =(J17/$L3)^(1/((lgh_bs!L$2-lgh_bs!$I$2)/365))-1 -> 0.2283289 | K20: =(K17/$L3)^(1/((lgh_bs!M$2-lgh_bs!$I$2)/365))-1 -> 0.1927873 | L20: =(L17/$L3)^(1/((lgh_bs!N$2-lgh_bs!$I$2)/365))-1 -> 0.19751582 | M20: =(M17/$L3)^(1/((lgh_bs!O$2-lgh_bs!$I$2)/365))-1 -> 0.18927426 | N20: =(N17/$L3)^(1/((lgh_bs!P$2-lgh_bs!$I$2)/365))-1 -> 0.18407598 | P20: Q1 2026 | Q20: 0.2516754 | R20: 0.20633249 | S20: 0.20820382 | T20: 0.19880647 | U20: 0.19277193
C22: Common + Pref MTM + Austin Adj. + Loren EV + Other EV | J22: Total SE + Reserve - C/I + Loren EV + Other EV | Q22: Total SE + Reserve - C/I + Loren EV + Other EV
C23: =(+lgh_bs!L51)/1000000 -> 128.0496 | D23: =(+lgh_bs!M51)/1000000 -> 150.14537 | E23: =(+lgh_bs!N51)/1000000 -> 201.43858 | F23: =(+lgh_bs!O51)/1000000 -> 251.72555 | G23: =(+lgh_bs!P51)/1000000 -> 323.52297 | J23: =+lgh_bs!L53/1000000 -> 183.61789 | K23: =+lgh_bs!M53/1000000 -> 212.38186 | L23: =+lgh_bs!N53/1000000 -> 271.15039 | M23: =+lgh_bs!O53/1000000 -> 329.80279 | N23: =+lgh_bs!P53/1000000 -> 410.96947 | Q23: 185.68852 | R23: 215.99907 | S23: 276.7317 | T23: 337.98827 | U23: 422.21971
B24: Mult | C24: =+C23/$E3 -> 1.1948956 | D24: =+D23/$E3 -> 1.4010824 | E24: =+E23/$E3 -> 1.8797252 | F24: =+F23/$E3 -> 2.3489784 | G24: =+G23/$E3 -> 3.0189565 | I24: Mult | J24: =+J23/$L3 -> 1.185448 | K24: =+K23/$L3 -> 1.3711499 | L24: =+L23/$L3 -> 1.750563 | M24: =+M23/$L3 -> 2.1292264 | N24: =+N23/$L3 -> 2.6532433 | P24: Mult | Q24: 1.2021793 | R24: 1.3984151 | S24: 1.7916085 | T24: 2.1881941 | U24: 2.7335229
B25: YoY | C25: =+C23/E3-1 -> 0.19489556 | D25: =+D23/C23-1 -> 0.17255637 | E25: =+E23/D23-1 -> 0.34162362 | F25: =+F23/E23-1 -> 0.24963925 | G25: =+G23/F23-1 -> 0.28522102 | I25: YoY | J25: =+J23/L3-1 -> 0.18544803 | K25: =+K23/J23-1 -> 0.15665123 | L25: =+L23/K23-1 -> 0.27671163 | M25: =+M23/L23-1 -> 0.21630945 | N25: =+N23/M23-1 -> 0.24610673 | P25: YoY | Q25: 0.20217934 | R25: 0.16323334 | S25: 0.28117076 | T25: 0.22135728 | U25: 0.24921408
B26: Q1 2026 | C26: =(C23/$E3)^(1/((lgh_bs!L$2-lgh_bs!$I$2)/365))-1 -> 0.26659547 | D26: =(D23/$E3)^(1/((lgh_bs!M$2-lgh_bs!$I$2)/365))-1 -> 0.21207659 | E26: =(E23/$E3)^(1/((lgh_bs!N$2-lgh_bs!$I$2)/365))-1 -> 0.2573256 | F26: =(F23/$E3)^(1/((lgh_bs!O$2-lgh_bs!$I$2)/365))-1 -> 0.25527467 | G26: =(G23/$E3)^(1/((lgh_bs!P$2-lgh_bs!$I$2)/365))-1 -> 0.26151251 | I26: Q1 2026 | J26: =(J23/$L3)^(1/((lgh_bs!L$2-lgh_bs!$I$2)/365))-1 -> 0.25332082 | K26: =(K23/$L3)^(1/((lgh_bs!M$2-lgh_bs!$I$2)/365))-1 -> 0.19724011 | L26: =(L23/$L3)^(1/((lgh_bs!N$2-lgh_bs!$I$2)/365))-1 -> 0.22526633 | M26: =(M23/$L3)^(1/((lgh_bs!O$2-lgh_bs!$I$2)/365))-1 -> 0.22287532 | N26: =(N23/$L3)^(1/((lgh_bs!P$2-lgh_bs!$I$2)/365))-1 -> 0.22772358 | P26: Q1 2026 | Q26: 0.27685335 | R26: 0.21076007 | S26: 0.23561293 | T26: 0.23180149 | U26: 0.23544228
J27: * Unlevered Equity is the sum of Common and Preferred Equity | Q27: * Unlevered Equity is the sum of Common and Preferred Equity

Sheet lgh_inputs
C3: ASSUMPTION INPUTS from lgh_returns page
C4: CI % | D4: 0.35
C6: Pref MTM Discount Rate | D6: 0.12
C8: return on cash balances (lgh_oc) | D8: 0.03
C10: pref unit size in dollars | D10: 25
C11: from pref page
C13: Valuation Assumptions
C14: Inflation | D14: 0
C15: from lgh_manco

Sheet lgh_bs
A1: Entity | B1: Subcategory | C1: {=_xlfn.TEXTAFTER(CELL("filename",C1),"]")} -> lgh_bs
C2: Year | D2: 45657 | E2: 45747 | F2: 45838 | G2: 45930 | H2: 46022 | I2: 46112 | J2: 46203 | K2: 46295 | L2: 46387 | M2: 46752 | N2: 47118 | O2: 47483 | P2: 47848
C3: Period | D3: Q4 | E3: Q1 | F3: Q2 | G3: Q3 | H3: Q4 | I3: Q1 | J3: Q2 | K3: Q3 | L3: Q4 | M3: Q4 | N3: Q4 | O3: Q4 | P3: Q4
C4: Assets
A5: lgh_oc | B5: Cumm cash balance | C5: Cash | D5: 251128 | E5: =+registry!C82 -> 1854835.2 | F5: =+registry!D82 -> -2432356 | G5: =+registry!E82 -> -5195946.3 | H5: =+registry!F82 -> 421256.07 | I5: =+registry!G82 -> 5590388.1 | J5: =+registry!H82 -> 10863126 | K5: =+registry!I82 -> 7305682.2 | L5: =+registry!J82 -> 3057475.4 | ... P5: =+registry!N82 -> 27896240
C6: Bermuda | D6: 56391899 | E6: =SUM(E7:E7) -> 48342875 | F6: =SUM(F7:F7) -> 49230680 | G6: =SUM(G7:G7) -> 51936303 | H6: =SUM(H7:H7) -> 46803857 | I6: =SUM(I7:I7) -> 46688396 | J6: =SUM(J7:J7) -> 47318459 | K6: =SUM(K7:K7) -> 47193849 | L6: =SUM(L7:L7) -> 60232309 | ... P6: =SUM(P7:P7) -> 85421360
A7: Bermuda Pink Beach | B7: Level 1 | C7: Equity | D7: 56391899 | E7: =+registry!C7 -> 48342875 | F7: =+registry!D7 -> 49230680 | G7: =+registry!E7 -> 51936303 | H7: =+registry!F7 -> 46803857 | I7: =+registry!G7 -> 46688396 | J7: =+registry!H7 -> 47318459 | K7: =+registry!I7 -> 47193849 | L7: =+registry!J7 -> 60232309 | ... P7: =+registry!N7 -> 85421360
C8: Austin | D8: 30156389 | E8: =SUM(E9:E12) -> 26787736 | F8: =SUM(F9:F12) -> 26482398 | G8: =SUM(G9:G12) -> 24312675 | H8: =SUM(H9:H12) -> 18560900 | I8: =SUM(I9:I12) -> 18168835 | J8: =SUM(J9:J12) -> 20455751 | K8: =SUM(K9:K12) -> 20019626 | L8: =SUM(L9:L12) -> 20380869 | ... P8: =SUM(P9:P12) -> 47083185
A9: Austin Lady Bird Lake | B9: LGH NAV | C9: Equity | D9: 15926855 | E9: =+registry!C12 -> 18088592 | F9: =+registry!D12 -> 17359150 | G9: =+registry!E12 -> 15109714 | H9: =+registry!F12 -> 7753407.4 | I9: =+registry!G12 -> 6038275.4 | J9: =+registry!H12 -> 4849926.1 | K9: =+registry!I12 -> 3974250.2 | L9: =+registry!J12 -> 3116853.8 | ... P9: =+registry!N12 -> 0
A10: Austin Lady Bird Lake | B10: Pref Owned | C10: Preferred Equity | D10: 5608281.4 | E10: =+registry!C14 -> 5792434.5 | F10: =+registry!D14 -> 5984782.4 | G10: =+registry!E14 -> 6185737.8 | H10: =+registry!F14 -> 6393440.8 | I10: =+registry!G14 -> 6603375.3 | J10: =+registry!H14 -> 6822651.9 | K10: =+registry!I14 -> 7051741.1 | L10: =+registry!J14 -> 7288522.5 | ... P10: =+registry!N14 -> 4764456.8
A11: Austin Lady Bird Lake | B11: Mezz Owned | C11: Mezz Loan | D11: 8621252.7 | E11: =+registry!C13 -> 2691709.1 | F11: =+registry!D13 -> 2849465 | G11: =+registry!E13 -> 3017222.8 | H11: =+registry!F13 -> 4124556.9 | I11: =+registry!G13 -> 4237689.3 | J11: =+registry!H13 -> 6873678.2 | K11: =+registry!I13 -> 7084139.4 | L11: =+registry!J13 -> 7315998.2 | ... P11: =+registry!N13 -> 42318729
C12: STL | D12: =registry!B18 -> 0 | E12: =registry!C18 -> 215000 | F12: =registry!D18 -> 289000 | G12: =registry!E18 -> 0 | H12: =registry!F18 -> 289495 | I12: =registry!G18 -> 1289495 | J12: =registry!H18 -> 1909495 | K12: =registry!I18 -> 1909495 | ... P12: =registry!N18 -> 0
C13: Turks | D13: 30602658 | E13: =SUM(E14) -> 35723216 | F13: =SUM(F14) -> 38565928 | G13: =SUM(G14) -> 40379581 | H13: =SUM(H14) -> 40032701 | I13: =SUM(I14) -> 36265000 | J13: =SUM(J14) -> 38900747 | K13: =SUM(K14) -> 41760245 | L13: =SUM(L14) -> 50265874 | ... P13: =SUM(P14) -> 37231193
A14: Turks & Caicos | B14: LGH NAV | C14: Equity | D14: 30602658 | E14: =+registry!C23 -> 35723216 | F14: =+registry!D23 -> 38565928 | G14: =+registry!E23 -> 40379581 | H14: =+registry!F23 -> 40032701 | I14: =+registry!G23 -> 36265000 | J14: =+registry!H23 -> 38900747 | K14: =+registry!I23 -> 41760245 | L14: =+registry!J23 -> 50265874 | ... P14: =+registry!N23 -> 37231193
C15: Elbow | D15: 5000000 | E15: =SUM(E16) -> 17383391 | F15: =SUM(F16) -> 19070671 | G15: =SUM(G16) -> 20943032 | H15: =SUM(H16) -> 22999222 | I15: =SUM(I16) -> 28009536 | J15: =SUM(J16) -> 30460557 | K15: =SUM(K16) -> 33156609 | L15: =SUM(L16) -> 36091288 | ... P15: =SUM(P16) -> 104879625
A16: Bermuda: Elbow Beach | B16: LGH NAV | C16: Elbow Beach | D16: 5000000 | E16: =+registry!C33 -> 17383391 | F16: =+registry!D33 -> 19070671 | G16: =+registry!E33 -> 20943032 | H16: =+registry!F33 -> 22999222 | I16: =+registry!G33 -> 28009536 | J16: =+registry!H33 -> 30460557 | K16: =+registry!I33 -> 33156609 | L16: =+registry!J33 -> 36091288 | ... P16: =+registry!N33 -> 104879625
C17: Fritholme | D17: 0 | E17: =SUM(E18) -> 11353680 | F17: =SUM(F18) -> 13799240 | G17: =SUM(G18) -> 15549103 | H17: =SUM(H18) -> 15839974 | I17: =SUM(I18) -> 15929659 | J17: =SUM(J18) -> 15182357 | K17: =SUM(K18) -> 17072720 | L17: =SUM(L18) -> 0 | ... P17: =SUM(P18) -> 0
A18: Fritholme | B18: LGH NAV | C18: Fritholme | D18: 0 | E18: =+registry!C28 -> 11353680 | F18: =+registry!D28 -> 13799240 | G18: =+registry!E28 -> 15549103 | H18: =+registry!F28 -> 15839974 | I18: =+registry!G28 -> 15929659 | J18: =+registry!H28 -> 15182357 | K18: =+registry!I28 -> 17072720 | L18: =+registry!J28 -> 0 | ... P18: =+registry!N28 -> 0
C19: =+C20 -> [LSAT] | D19: 0 | E19: =SUM(E20) -> 0 | F19: =SUM(F20) -> 0 | G19: =SUM(G20) -> 0 | H19: =SUM(H20) -> 0 | I19: =SUM(I20) -> 0 | J19: =SUM(J20) -> 0 | K19: =SUM(K20) -> 0 | L19: =SUM(L20) -> 16000000 | ... P19: =SUM(P20) -> 21709416
A20: lgh_other_assets | B20: [SAT] Balance Sheet | C20: [LSAT] | D20: 0 | E20: =+registry!C78 -> 0 | F20: =+registry!D78 -> 0 | G20: =+registry!E78 -> 0 | H20: =+registry!F78 -> 0 | I20: =+registry!G78 -> 0 | J20: =+registry!H78 -> 0 | K20: =+registry!I78 -> 0 | L20: =+registry!J78 -> 16000000 | ... P20: =+registry!N78 -> 21709416
C21: =+C22 -> [L4] | D21: 0 | E21: =SUM(E22) -> 0 | F21: =SUM(F22) -> 0 | G21: =SUM(G22) -> 0 | H21: =SUM(H22) -> 0 | I21: =SUM(I22) -> 0 | J21: =SUM(J22) -> 0 | K21: =SUM(K22) -> 0 | L21: =SUM(L22) -> 0 | ... P21: =SUM(P22) -> 45000000
A22: lgh_other_assets | B22: [WC] Balance Sheet | C22: [L4] | D22: 0 | E22: =+registry!C79 -> 0 | F22: =+registry!D79 -> 0 | G22: =+registry!E79 -> 0 | H22: =+registry!F79 -> 0 | I22: =+registry!G79 -> 0 | J22: =+registry!H79 -> 0 | K22: =+registry!I79 -> 0 | L22: =+registry!J79 -> 0 | ... P22: =+registry!N79 -> 45000000
C23: =+C24 -> PV Loren fees (Key money) | D23: 20000000 | E23: =SUM(E24) -> 20000000 | F23: =SUM(F24) -> 20000000 | G23: =SUM(G24) -> 20000000 | H23: =SUM(H24) -> 20000000 | I23: =SUM(I24) -> 20000000 | J23: =SUM(J24) -> 20000000 | K23: =SUM(K24) -> 25000000 | L23: =SUM(L24) -> 25000000 | ... P23: =SUM(P24) -> 35000000
A24: c12_hm_oc | B24: PV Loren fees (Key money) | C24: PV Loren fees (Key money) | D24: 20000000 | E24: =+registry!C49 -> 20000000 | F24: =+registry!D49 -> 20000000 | G24: =+registry!E49 -> 20000000 | H24: =+registry!F49 -> 20000000 | I24: =+registry!G49 -> 20000000 | J24: =+registry!H49 -> 20000000 | K24: =+registry!I49 -> 25000000 | L24: =+registry!J49 -> 25000000 | ... P24: =+registry!N49 -> 35000000
C25: Other | D25: 3570254 | E25: =SUM(E26:E26) -> 4318174.2 | F25: =SUM(F26:F26) -> 6116942.4 | G25: =SUM(G26:G26) -> 4951761.6 | H25: =SUM(H26:H26) -> 4325793.8 | I25: =SUM(I26:I26) -> 3150709 | J25: =SUM(J26:J26) -> 3175738.3 | K25: =SUM(K26:K26) -> 3356358.1 | L25: =SUM(L26:L26) -> 3280322 | ... P25: =SUM(P26:P26) -> 5265898.3
A26: lgh_other_assets | B26: Balance | C26: Other Assets | D26: 3570254 | E26: =+registry!C77 -> 4318174.2 | F26: =+registry!D77 -> 6116942.4 | G26: =+registry!E77 -> 4951761.6 | H26: =+registry!F77 -> 4325793.8 | I26: =+registry!G77 -> 3150709 | J26: =+registry!H77 -> 3175738.3 | K26: =+registry!I77 -> 3356358.1 | L26: =+registry!J77 -> 3280322 | ... P26: =+registry!N77 -> 5265898.3
C27: Total assets incl. Cash | D27: 1.4597233e+08 | E27: =SUM(E5,E6,E8,E13,E15,E17,E19,E21,E23,E25) -> 1.6576391e+08 | F27: =SUM(F5,F6,F8,F13,F15,F17,F19,F21,F23,F25) -> 1.708335e+08 | G27: =SUM(G5,G6,G8,G13,G15,G17,G19,G21,G23,G25) -> 1.7287651e+08 | H27: =SUM(H5,H6,H8,H13,H15,H17,H19,H21,H23,H25) -> 1.689837e+08 | I27: =SUM(I5,I6,I8,I13,I15,I17,I19,I21,I23,I25) -> 1.7380252e+08 | J27: =SUM(J5,J6,J8,J13,J15,J17,J19,J21,J23,J25) -> 1.8635674e+08 | K27: =SUM(K5,K6,K8,K13,K15,K17,K19,K21,K23,K25) -> 1.9486509e+08 | L27: =SUM(L5,L6,L8,L13,L15,L17,L19,L21,L23,L25) -> 2.1430814e+08 | ... P27: =SUM(P5,P6,P8,P13,P15,P17,P19,P21,P23,P25) -> 4.0948692e+08
C28: Liabilities
A29: lgh_debt | B29: Balance: Principal and interest | C29: LGH Debt | D29: 25387077 | E29: =+registry!C66 -> 29007182 | F29: =+registry!D66 -> 30149897 | G29: =+registry!E66 -> 9136912.2 | H29: =+registry!F66 -> 8575632.5 | I29: =+registry!G66 -> 7900128.8 | J29: =+registry!H66 -> 12239223 | K29: =+registry!I66 -> 12195992 | L29: =+registry!J66 -> 7400513.4 | ... P29: =+registry!N66 -> 0
A30: lgh_other_assets | B30: Total Capital Raised Other Projects | C30: Other Project Capital needs | D30: 0 | E30: =+registry!C91 -> 0 | F30: =+registry!D91 -> 0 | G30: =+registry!E91 -> 0 | H30: =+registry!F91 -> 0 | I30: =+registry!G91 -> 0 | J30: =+registry!H91 -> 0 | K30: =+registry!I91 -> 0 | L30: =+registry!J91 -> 0 | ... P30: =+registry!N91 -> 0
A31: lgh_other_liabs | B31: balance | C31: LGH other | D31: 812241.1 | E31: =+registry!C71 -> 3383115.8 | F31: =+registry!D71 -> 5020671.4 | G31: =+registry!E71 -> 5081889.2 | H31: =+registry!F71 -> 6989833.7 | I31: =+registry!G71 -> 8001344.4 | J31: =+registry!H71 -> 8575801.2 | K31: =+registry!I71 -> 8582691.7 | L31: =+registry!J71 -> 17286474 | ... P31: =+registry!N71 -> 27995423
C32: Total Liabilities | D32: 26199318 | E32: =SUM(E29:E31) -> 32390298 | F32: =SUM(F29:F31) -> 35170568 | G32: =SUM(G29:G31) -> 14218801 | H32: =SUM(H29:H31) -> 15565466 | I32: =SUM(I29:I31) -> 15901473 | J32: =SUM(J29:J31) -> 20815024 | K32: =SUM(K29:K31) -> 20778684 | L32: =SUM(L29:L31) -> 24686988 | ... P32: =SUM(P29:P31) -> 27995423
C33: Net Asset Value (NAV) | D33: 1.1977301e+08 | E33: =+E27-E32 -> 1.3337361e+08 | F33: =+F27-F32 -> 1.3566293e+08 | G33: =+G27-G32 -> 1.5865771e+08 | H33: =+H27-H32 -> 1.5341824e+08 | I33: =+I27-I32 -> 1.5790105e+08 | J33: =+J27-J32 -> 1.6554171e+08 | K33: =+K27-K32 -> 1.7408641e+08 | L33: =+L27-L32 -> 1.8962115e+08 | ... P33: =+P27-P32 -> 3.8149149e+08
C34: Shareholders' Equity
A35: lgh_ci | B35: total | C35: Carried Interest | D35: 0 | E35: =+registry!C86 -> 0 | F35: =+registry!D86 -> 0 | G35: =+registry!E86 -> 3030197.3 | H35: =+registry!F86 -> 1196383.1 | I35: =+registry!G86 -> 2765367.7 | J35: =+registry!H86 -> 5439599 | K35: =+registry!I86 -> 8430241.9 | L35: =+registry!J86 -> 13867403 | ... P35: =+registry!N86 -> 81022023
A36: lgh_pref | B36: balance | C36: Preferred Equity | D36: 51080209 | E36: =+registry!C62 -> 49890886 | F36: =+registry!D62 -> 50888704 | G36: =+registry!E62 -> 51906478 | H36: =+registry!F62 -> 54144869 | I36: =+registry!G62 -> 56742198 | J36: =+registry!H62 -> 58896376 | K36: =+registry!I62 -> 60074303 | L36: =+registry!J62 -> 64275789 | ... P36: =+registry!N62 -> 87446502
A37: cuda | B37: Distribution (cuda for pref) | C37: CUDA | D37: -6000000 | E37: =-registry!C94 -> 6050000 | F37: =-registry!D94 -> 0 | G37: =-registry!E94 -> 0 | H37: =-registry!F94 -> 0 | I37: =-registry!G94 -> 0 | J37: =-registry!H94 -> 0 | K37: =-registry!I94 -> 0 | L37: =-registry!J94 -> 0 | ... P37: =-registry!N94 -> 0
C38: Common Equity | D38: 74692801 | E38: =+E33-E35-E36-E37 -> 77432723 | F38: =+F33-F35-F36-F37 -> 84774231 | G38: =+G33-G35-G36-G37 -> 1.0372103e+08 | H38: =+H33-H35-H36-H37 -> 98076985 | I38: =+I33-I35-I36-I37 -> 98393485 | J38: =+J33-J35-J36-J37 -> 1.0120574e+08 | K38: =+K33-K35-K36-K37 -> 1.0558186e+08 | L38: =+L33-L35-L36-L37 -> 1.1147796e+08 | ... P38: =+P33-P35-P36-P37 -> 2.1302297e+08
C39: Total Shareholder's Equity | D39: 1.1977301e+08 | E39: =SUM(E35:E38) -> 1.3337361e+08 | F39: =SUM(F35:F38) -> 1.3566293e+08 | G39: =SUM(G35:G38) -> 1.5865771e+08 | H39: =SUM(H35:H38) -> 1.5341824e+08 | I39: =SUM(I35:I38) -> 1.5790105e+08 | J39: =SUM(J35:J38) -> 1.6554171e+08 | K39: =SUM(K35:K38) -> 1.7408641e+08 | L39: =SUM(L35:L38) -> 1.8962115e+08 | ... P39: =SUM(P35:P38) -> 3.8149149e+08
A40: Austin Lady Bird Lake | B40: Pref Liquidation adj. | C40: Austin Pref Liquidation adj. | D40: 0 | E40: =+registry!C16 -> 0 | F40: =+registry!D16 -> 0 | G40: =+registry!E16 -> 0 | H40: =+registry!F16 -> -4196895.7 | I40: =+registry!G16 -> -4334704.6 | J40: =+registry!H16 -> -4478646.1 | K40: =+registry!I16 -> -4629028.8 | L40: =+registry!J16 -> -4784461.1 | ... P40: =+registry!N16 -> 0
...

Sheet lgh_bs_errata
A1: LGH Balance Sheet
B2: 2024 | F2: 2025 | J2: 2026
A3: Assets | B3: Reported Audited Financials | C3: Signed Audited Financials | D3: ∆ | E3: COMMENTS 2024 | F3: Reported Q4 | G3: Restated Q4 | H3: ∆ | I3: COMMENTS 2025 | J3: Reported Q1 | K3: Restated Q1 | L3: ∆ | M3: Comments
A4: Cash
A5: Pink Beach | I5: valuation increased +.7M, added 3.3M of debt (net between adj. to acrrued unpaid fees, GM note)
A6: Equity
A7: Austin | I7: reduced unpaid accrued fees as liability
A8: Equity
A9: Mezz & Preferred & STL | E9: rounding
A10: Turks | I10: loan closed in Jan. PV impact to liabs
A11: Equity
A12: Elbow | I12: adjustment to appraised stabalized hotel valuation
A13: Elbow Beach
A14: Ocean Hills | I14: difference in accrued unpaid fees
A15: Fritholme
A16: Other
A17: Other Assets
A18: Net Accrued Unpaid Fees | I18: $1.8M,+$0.7M, +$0.4M adj to fee liabilities held at properties
A19: PV Loren fees (Key Money) | E19: reduction to audited key money | I19: carried through from 2024 reduction. Plus removal of 2.5M previously stated
A20: Total assets incl. Cash
A21: Liabilities
A22: LGH Debt | I22: adj of pre equity moved to lgh debt, and lgh debt moved to property(Bermuda), Kraus note
A23: LGH other | I23: additional year end debt and intercompany balances not previously disclosed. 1.4M roots loan
A24: Total Liabilities
A25: Net Asset Value
A26: Shareholder's Equity | I26: 3.7 key money reduction in 2024 + another 2.5M reduction for YE 2025, 5M in debt moved from pref equity. 2.1 roots adjustment from 700k receivable to 1.4 payable. 3.1M in accured fees removed. Additional YE debt now carried on BS.
A27: Carried Interest | I27: reduced from 37.5% to 30%
A28: Preferred Equity | I28: only moved $4M or $8M of La pointe + previously forecasted conversions not closed and accrued principal
A29: CUDA
A30: Common Equity | E30: adj. to key money per audit | I30: adj. to key money per audit
A31: Total Shareholder's Equity
A32: Enterprise value | E32: 0.5x multiple from key money calc and audit adjustment | I32: 1x multiple of key money
A33: Reserve
A34: Prefer Equity Audit adj.
A35: NAV after EV and LIQ adj.
A36: Add. Carried Interest Val. | I36: reduced CI from 37.5% to 30%
A37: LGH Pref MTM | E37: 5.25 instead of 6 years discount applied | I37: MTM reduced 16% to 12%
A38: CUDA | E38: =E29 -> 0
A39: Adj. Pref
A40: Adj. Carried Interest | E40: =E27+E36 -> 0
...

Sheet lgh_bs_qr
A1: Entity | B1: Subcategory | C1: {=_xlfn.TEXTAFTER(CELL("filename",C1),"]")} -> lgh_bs_qr
C2: Year | D2: 45657 | E2: 45747 | F2: 45838 | G2: 45930 | H2: 46022 | I2: 46112 | J2: 46203 | K2: 46295 | L2: 46387 | M2: 46752 | N2: 47118 | O2: 47483 | P2: 47848
C3: Period | D3: Q4 | E3: Q1 | F3: Q2 | G3: Q3 | H3: Q4 | I3: Q1 | J3: Q2 | K3: Q3 | L3: Q4 | M3: Q4 | N3: Q4 | O3: Q4 | P3: Q4
C4: Assets
A5: lgh_oc | B5: Cumm cash balance | C5: Cash
C6: Bermuda
A7: Bermuda Pink Beach | B7: Level 1 | C7: Equity
C8: Austin
A9: Austin Lady Bird Lake | B9: LGH NAV | C9: Equity
A10: Austin Lady Bird Lake | B10: Pref Owned | C10: Preferred Equity
A11: Austin Lady Bird Lake | B11: Mezz Owned | C11: Mezz Loan
C12: STL
C13: Turks
A14: Turks & Caicos | B14: LGH NAV | C14: Equity
C15: Elbow
A16: Bermuda: Elbow Beach | B16: LGH NAV | C16: Elbow Beach
C17: Fritholme
A18: Fritholme | B18: LGH NAV | C18: Fritholme
C19: =+C20 -> [LSAT]
A20: lgh_other_assets | B20: [SAT] Balance Sheet | C20: [LSAT]
C21: =+C22 -> [L4]
A22: lgh_other_assets | B22: [WC] Balance Sheet | C22: [L4]
C23: =+C24 -> PV Loren fees (Key money)
A24: c12_hm_oc | B24: PV Loren fees (Key money) | C24: PV Loren fees (Key money)
C25: Other
A26: lgh_other_assets | B26: Balance | C26: Other Assets
C27: Total assets incl. Cash
C28: Liabilities
A29: lgh_debt | B29: Balance: Principal and interest | C29: LGH Debt
A30: lgh_other_assets | B30: Total Capital Raised Other Projects | C30: Other Project Capital needs
A31: lgh_other_liabs | B31: balance | C31: LGH other
C32: Total Liabilities
C33: Net Asset Value (NAV)
C34: Shareholders' Equity
A35: lgh_ci | B35: total | C35: Carried Interest
A36: lgh_pref | B36: balance | C36: Preferred Equity
A37: cuda | B37: Distribution (cuda for pref) | C37: CUDA
C38: Common Equity
C39: Total Shareholder's Equity
A40: Austin Lady Bird Lake | B40: Pref Liquidation adj. | C40: Austin Pref Liquidation adj.
...

Sheet lgh_oc
A1: {=_xlfn.TEXTAFTER(CELL("filename",A1),"]")} -> lgh_oc
A2: Year | B2: 45657 | C2: =+lgh_bs!E2 -> 45747 | D2: =+lgh_bs!F2 -> 45838 | E2: =+lgh_bs!G2 -> 45930 | F2: =+lgh_bs!H2 -> 46022 | G2: =+lgh_bs!I2 -> 46112 | H2: =+lgh_bs!J2 -> 46203 | I2: =+lgh_bs!K2 -> 46295 | J2: =+lgh_bs!L2 -> 46387 | ... N2: =+lgh_bs!P2 -> 47848
A3: Period | B3: Q4 | C3: =+lgh_bs!E3 -> Q1 | D3: =+lgh_bs!F3 -> Q2 | E3: =+lgh_bs!G3 -> Q3 | F3: =+lgh_bs!H3 -> Q4 | G3: =+lgh_bs!I3 -> Q1 | H3: =+lgh_bs!J3 -> Q2 | I3: =+lgh_bs!K3 -> Q3 | J3: =+lgh_bs!L3 -> Q4 | ... N3: =+lgh_bs!P3 -> Q4
A4: fee, service, and charge backs
A5: Total Revenue | B5: =registry!B59 -> 0 | C5: =registry!C59 -> 687682.5 | D5: =registry!D59 -> 687682.5 | E5: =registry!E59 -> 1258082.5 | F5: =registry!F59 -> 1358832.5 | G5: =registry!G59 -> 2200269.7 | H5: =registry!H59 -> 3530751.8 | I5: =registry!I59 -> 3421728.7 | ... N5: =registry!N59 -> 13901367
A7: Other Income
A8: Art Leases | B8: 0 | C8: 0 | D8: 0 | E8: 0 | F8: 0 | G8: 50000 | H8: 50000 | I8: 50000 | J8: 50000 | K8: 250000 | L8: 250000 | M8: 250000 | N8: 250000
A9: Total Other Income | B9: 0 | C9: =SUM(C8:C8) -> 0 | D9: =SUM(D8:D8) -> 0 | E9: =SUM(E8:E8) -> 0 | F9: =SUM(F8:F8) -> 0 | G9: =SUM(G8:G8) -> 50000 | H9: =SUM(H8:H8) -> 50000 | I9: =SUM(I8:I8) -> 50000 | J9: =SUM(J8:J8) -> 50000 | ... N9: =SUM(N8:N8) -> 250000
A11: total lgh operating revenue | B11: =B9+B5 -> 0 | C11: =C9+C5 -> 687682.5 | D11: =D9+D5 -> 687682.5 | E11: =E9+E5 -> 1258082.5 | F11: =F9+F5 -> 1358832.5 | G11: =G9+G5 -> 2250269.7 | H11: =H9+H5 -> 3580751.8 | I11: =I9+I5 -> 3471728.7 | ... N11: =N9+N5 -> 14151367
A13: C12 Participation Expense
A14: Total C12 Participation (inc 5% for c/bs) | B14: =-registry!B58 -> -2452451 | C14: =-registry!C58 -> -623314.75 | D14: =-registry!D58 -> -623314.75 | E14: =-registry!E58 -> -908514.75 | F14: =-registry!F58 -> -903214.75 | G14: =-registry!G58 -> -886331.48 | H14: =-registry!H58 -> -1430293.5 | I14: =-registry!I58 -> -1358160.9 | ... N14: =-registry!N58 -> -3977928.6
A16: Total c12 Operating Expenses | B16: =+registry!B95 -> -5450569 | C16: =+registry!C95 -> -1637186 | D16: =+registry!D95 -> -1733477 | E16: =+registry!E95 -> -1694124 | F16: =+registry!F95 -> -2917273 | G16: =+registry!G95 -> -4057849.9 | H16: =+registry!H95 -> -4457407 | I16: =+registry!I95 -> -2834607 | ... N16: =+registry!N95 -> -12445131
A18: Total LGH Expenses | B18: -8570520 | C18: =+C14+C16 -> -2260500.8 | D18: =+D14+D16 -> -2356791.8 | E18: =+E14+E16 -> -2602638.8 | F18: =+F14+F16 -> -3820487.8 | G18: =+G14+G16 -> -4944181.3 | H18: =+H14+H16 -> -5887700.5 | I18: =+I14+I16 -> -4192767.9 | J18: =+J14+J16 -> -7829290.6 | ... N18: =+N14+N16 -> -16423060
A20: Total LGH Operating Profit | B20: =+B11+B18+B23 -> -8570520 | C20: =+C11+C18+C23 -> -1572818.2 | D20: =+D11+D18+D23 -> -1669109.2 | E20: =+E11+E18+E23 -> -1344556.2 | F20: =+F11+F18+F23 -> -2461655.2 | G20: =+G11+G18+G23 -> -2693911.7 | H20: =+H11+H18+H23 -> -2306948.6 | I20: =+I11+I18+I23 -> -721039.15 | ... N20: =+N11+N18+N23 -> -2271692.6
A21: LGH opprofit / bs-1 | F21: =-SUM(C20:F20)/lgh_bs!H44 -> 0.046532218 | J21: =-SUM(G20:J20)/lgh_bs!L44 -> 0.019465384 | K21: =-K20/lgh_bs!M44 -> -0.0088979783 | L21: =-L20/lgh_bs!N44 -> 0.0029838314 | M21: =-M20/lgh_bs!O44 -> -0.0049303061 | N21: =-N20/lgh_bs!P44 -> 0.0041191797
A23: Guarantee Fees Received | B23: 0 | C23: =+registry!C43 -> 0 | D23: =+registry!D43 -> 0 | E23: =+registry!E43 -> 0 | F23: =+registry!F43 -> 0 | G23: =+registry!G43 -> 0 | H23: =+registry!H43 -> 0 | I23: =+registry!I43 -> 0 | J23: =+registry!J43 -> 1000000 | ... N23: =+registry!N43 -> 0 | O23: need to be reflected in cs2s
A24: Guarentee Fees accrued cumm (PIK) | B24: =+registry!B96 -> 0 | C24: =+registry!C96 -> 350000 | D24: =+registry!D96 -> 700000 | E24: =+registry!E96 -> 1050000 | F24: =+registry!F96 -> 1600000 | G24: =+registry!G96 -> 2150000 | H24: =+registry!H96 -> 2700000 | I24: =+registry!I96 -> 3250000 | ... N24: =+registry!N96 -> 1900000
A25: Guarentee Fees Expense | B25: 0 | C25: -250000 | D25: -250000 | E25: -250000 | F25: -250000 | G25: -250000 | H25: -250000 | I25: -250000 | J25: -250000 | K25: -1000000 | L25: -1000000 | M25: -1000000 | N25: -1000000
A26: net guarantee fees | B26: =B23+B25 -> 0 | C26: =C23+C25 -> -250000 | D26: =D23+D25 -> -250000 | E26: =E23+E25 -> -250000 | F26: =F23+F25 -> -250000 | G26: =G23+G25 -> -250000 | H26: =H23+H25 -> -250000 | I26: =I23+I25 -> -250000 | ... N26: =N23+N25 -> -1000000
A28: Cash Flow from Properties
A29: Sources/In
A30: Bermuda PB | B30: 1562074 | C30: =+registry!C5 -> 3250000 | D30: =+registry!D5 -> 3388588 | E30: =+registry!E5 -> 1475962 | F30: =+registry!F5 -> 8336733 | G30: =+registry!G5 -> 0 | H30: =+registry!H5 -> 0 | I30: =+registry!I5 -> 0 | J30: =+registry!J5 -> 0 | ... N30: =+registry!N5 -> 4123684
A31: Austin | B31: 814451.63 | C31: =+registry!C10 -> 5515000 | D31: =+registry!D10 -> 0 | E31: =+registry!E10 -> 525000 | F31: =+registry!F10 -> 0 | G31: =+registry!G10 -> 0 | H31: =+registry!H10 -> 0 | I31: =+registry!I10 -> 0 | J31: =+registry!J10 -> 0 | ... N31: =+registry!N10 -> 0
A32: Turks | B32: 0 | C32: =+registry!C21 -> 0 | D32: =+registry!D21 -> 0 | E32: =+registry!E21 -> 0 | F32: =+registry!F21 -> 350000 | G32: =+registry!G21 -> 0 | H32: =+registry!H21 -> 350000 | I32: =+registry!I21 -> 0 | J32: =+registry!J21 -> 0 | ... N32: =+registry!N21 -> 1371287
A33: Frithholme | B33: 0 | C33: =+registry!C26 -> 0 | D33: =+registry!D26 -> 0 | E33: =+registry!E26 -> 0 | F33: =+registry!F26 -> 0 | G33: =+registry!G26 -> 2400000 | H33: =+registry!H26 -> 3600000 | I33: =+registry!I26 -> 0 | J33: =+registry!J26 -> 16900000 | ... N33: =+registry!N26 -> 0
A34: SAT | B34: =registry!B36 -> 0 | C34: =registry!C36 -> 0 | D34: =registry!D36 -> 0 | E34: =registry!E36 -> 0 | F34: =registry!F36 -> 0 | G34: =registry!G36 -> 0 | H34: =registry!H36 -> 0 | I34: =registry!I36 -> 0 | ... N34: =registry!N36 -> 1750000
A35: Bermuda Elbow | B35: 0 | C35: =+registry!C31 -> 0 | D35: =+registry!D31 -> 2500000 | E35: =+registry!E31 -> 2500000 | F35: =+registry!F31 -> 6137500 | G35: =+registry!G31 -> 5640000 | H35: =+registry!H31 -> 7300000 | I35: =+registry!I31 -> 0 | J35: =+registry!J31 -> 0 | ... N35: =+registry!N31 -> 0
A36: Total Sources | B36: 2376525.6 | C36: =SUM(C30:C35) -> 8765000 | D36: =SUM(D30:D35) -> 5888588 | E36: =SUM(E30:E35) -> 4500962 | F36: =SUM(F30:F35) -> 14824233 | G36: =SUM(G30:G35) -> 8040000 | H36: =SUM(H30:H35) -> 11250000 | I36: =SUM(I30:I35) -> 0 | J36: =SUM(J30:J35) -> 16900000 | ... N36: =SUM(N30:N35) -> 7244971
A37: Uses/out
A38: Bermuda PB | B38: 0 | C38: =+registry!C6 -> -125000 | D38: =+registry!D6 -> -3717883 | E38: =+registry!E6 -> -3472013.3 | F38: =+registry!F6 -> 0 | G38: =+registry!G6 -> 0 | H38: =+registry!H6 -> 0 | I38: =+registry!I6 -> 0 | J38: =+registry!J6 -> -4604401.2 | ... N38: =+registry!N6 -> 0
A39: Austin | B39: 0 | C39: =+registry!C11 -> -50000 | D39: =+registry!D11 -> -2025000 | E39: =+registry!E11 -> -230000 | F39: =+registry!F11 -> -289495 | G39: =+registry!G11 -> -1750000 | H39: =+registry!H11 -> -3420000 | I39: =+registry!I11 -> 0 | J39: =+registry!J11 -> -750000 | ... N39: =+registry!N11 -> 0
A40: Turks | B40: 0 | C40: =+registry!C22 -> -382967 | D40: =+registry!D22 -> -2326328 | E40: =+registry!E22 -> -3292886 | F40: =+registry!F22 -> -5106622 | G40: =+registry!G22 -> -420000 | H40: =+registry!H22 -> -200000 | I40: =+registry!I22 -> -150000 | J40: =+registry!J22 -> -550000 | ... N40: =+registry!N22 -> 0
A41: Frithholme | B41: 0 | C41: =+registry!C27 -> 0 | D41: =+registry!D27 -> 0 | E41: =+registry!E27 -> 0 | F41: =+registry!F27 -> -860000 | G41: =+registry!G27 -> 0 | H41: =+registry!H27 -> -1750000 | I41: =+registry!I27 -> 0 | J41: =+registry!J27 -> 0 | ... N41: =+registry!N27 -> 0
A42: SAT | B42: =registry!B37 -> 0 | C42: =registry!C37 -> 0 | D42: =registry!D37 -> 0 | E42: =registry!E37 -> 0 | F42: =registry!F37 -> 0 | G42: =registry!G37 -> 0 | H42: =registry!H37 -> 0 | I42: =registry!I37 -> 0 | ... N42: =registry!N37 -> 0
A43: Bermuda Elbow | B43: 0 | C43: =+registry!C32 -> -2500000 | D43: =+registry!D32 -> 0 | E43: =+registry!E32 -> 0 | F43: =+registry!F32 -> 0 | G43: =+registry!G32 -> -1000000 | H43: =+registry!H32 -> -2040000 | I43: =+registry!I32 -> -2000000 | J43: =+registry!J32 -> -8250000 | ... N43: =+registry!N32 -> 0
A44: Total Uses | B44: 0 | C44: =SUM(C38:C43) -> -3057967 | D44: =SUM(D38:D43) -> -8069211 | E44: =SUM(E38:E43) -> -6994899.3 | F44: =SUM(F38:F43) -> -6256117 | G44: =SUM(G38:G43) -> -3170000 | H44: =SUM(H38:H43) -> -7410000 | I44: =SUM(I38:I43) -> -2150000 | J44: =SUM(J38:J43) -> -30154401 | ... N44: =SUM(N38:N43) -> 0
A46: Total CF from Property Distributions | B46: 2376525.6 | C46: =+C36+C44 -> 5707033 | D46: =+D36+D44 -> -2180623 | E46: =+E36+E44 -> -2493937.3 | F46: =+F36+F44 -> 8568116 | G46: =+G36+G44 -> 4870000 | H46: =+H36+H44 -> 3840000 | I46: =+I36+I44 -> -2150000 | J46: =+J36+J44 -> -13254401 | ... N46: =+N36+N44 -> 7244971
A48: LGH DEPO Cash Flow
A50: Sources/In
A51: lgh equity | B51: 0 | C51: =+registry!C97 -> 0 | D51: =+registry!D97 -> 23600000 | E51: =+registry!E97 -> 200000 | F51: =+registry!F97 -> 0 | G51: =+registry!G97 -> 0 | H51: =+registry!H97 -> 0 | I51: =+registry!I97 -> 0 | J51: =+registry!J97 -> 0 | ... N51: =+registry!N97 -> 0
...

Sheet lgh_ci
A1: {=_xlfn.TEXTAFTER(CELL("filename",A1),"]")} -> lgh_ci
A2: Year | B2: 45657 | C2: =+lgh_bs!E2 -> 45747 | D2: =+lgh_bs!F2 -> 45838 | E2: =+lgh_bs!G2 -> 45930 | F2: =+lgh_bs!H2 -> 46022 | G2: =+lgh_bs!I2 -> 46112 | H2: =+lgh_bs!J2 -> 46203 | I2: =+lgh_bs!K2 -> 46295 | J2: =+lgh_bs!L2 -> 46387 | ... N2: =+lgh_bs!P2 -> 47848
A3: Period | B3: Q4 | C3: =+lgh_bs!E3 -> Q1 | D3: =+lgh_bs!F3 -> Q2 | E3: =+lgh_bs!G3 -> Q3 | F3: =+lgh_bs!H3 -> Q4 | G3: =+lgh_bs!I3 -> Q1 | H3: =+lgh_bs!J3 -> Q2 | I3: =+lgh_bs!K3 -> Q3 | J3: =+lgh_bs!L3 -> Q4 | ... N3: =+lgh_bs!P3 -> Q4
A4: NAV | B4: 1.1977301e+08 | C4: =+lgh_bs!E33 -> 1.3337361e+08 | D4: =+lgh_bs!F33 -> 1.3566293e+08 | E4: =+lgh_bs!G33 -> 1.5865771e+08 | F4: =+lgh_bs!H33 -> 1.5341824e+08 | G4: =+lgh_bs!I33 -> 1.5790105e+08 | H4: =+lgh_bs!J33 -> 1.6554171e+08 | I4: =+lgh_bs!K33 -> 1.7408641e+08 | J4: =+lgh_bs!L33 -> 1.8962115e+08 | ... N4: =+lgh_bs!P33 -> 3.8149149e+08
A5: adjusted NAV | B5: 1.2977301e+08 | C5: =lgh_bs!E44 -> 1.4337361e+08 | D5: =lgh_bs!F44 -> 1.4566293e+08 | E5: =lgh_bs!G44 -> 1.6865771e+08 | F5: =lgh_bs!H44 -> 1.5146793e+08 | G5: =lgh_bs!I44 -> 1.5752807e+08 | H5: =lgh_bs!J44 -> 1.6821314e+08 | I5: =lgh_bs!K44 -> 1.8298313e+08 | J5: =lgh_bs!L44 -> 2.0171984e+08 | ... N5: =lgh_bs!P44 -> 5.5149149e+08
A7: Common carried interest
B8: 0 | C8: =+lgh_inputs!$D$4 -> 0.35 | D8: =+lgh_inputs!$D$4 -> 0.35 | E8: =+lgh_inputs!$D$4 -> 0.35 | F8: =+lgh_inputs!$D$4 -> 0.35 | G8: =+lgh_inputs!$D$4 -> 0.35 | H8: =+lgh_inputs!$D$4 -> 0.35 | I8: =+lgh_inputs!$D$4 -> 0.35 | J8: =+lgh_inputs!$D$4 -> 0.35 | ... N8: =+lgh_inputs!$D$4 -> 0.35
A9: 150000000 | B9: 150000000 | C9: =$A9 -> 150000000 | D9: =$A9 -> 150000000 | E9: =$A9 -> 150000000 | F9: =$A9 -> 150000000 | G9: =$A9 -> 150000000 | H9: =$A9 -> 150000000 | I9: =$A9 -> 150000000 | J9: =$A9 -> 150000000 | ... N9: =$A9 -> 150000000
B10: 0 | C10: =MAX((C$4-C9)*C8,0) -> 0 | D10: =MAX((D$4-D9)*D8,0) -> 0 | E10: =MAX((E$4-E9)*E8,0) -> 3030197.3 | F10: =MAX((F$4-F9)*F8,0) -> 1196383.1 | G10: =MAX((G$4-G9)*G8,0) -> 2765367.7 | H10: =MAX((H$4-H9)*H8,0) -> 5439599 | I10: =MAX((I$4-I9)*I8,0) -> 8430241.9 | J10: =MAX((J$4-J9)*J8,0) -> 13867403 | ... N10: =MAX((N$4-N9)*N8,0) -> 81022023
A11: total | B11: 0 | C11: =+C10 -> 0 | D11: =+D10 -> 0 | E11: =+E10 -> 3030197.3 | F11: =+F10 -> 1196383.1 | G11: =+G10 -> 2765367.7 | H11: =+H10 -> 5439599 | I11: =+I10 -> 8430241.9 | J11: =+J10 -> 13867403 | ... N11: =+N10 -> 81022023
A12: Additional CI Val.
B13: 0 | C13: =+lgh_inputs!$D$4 -> 0.35 | D13: =+lgh_inputs!$D$4 -> 0.35 | E13: =+lgh_inputs!$D$4 -> 0.35 | F13: =+lgh_inputs!$D$4 -> 0.35 | G13: =+lgh_inputs!$D$4 -> 0.35 | H13: =+lgh_inputs!$D$4 -> 0.35 | I13: =+lgh_inputs!$D$4 -> 0.35 | J13: =+lgh_inputs!$D$4 -> 0.35 | ... N13: =+lgh_inputs!$D$4 -> 0.35
A14: 150000000 | B14: 150000000 | C14: =$A14 -> 150000000 | D14: =$A14 -> 150000000 | E14: =$A14 -> 150000000 | F14: =$A14 -> 150000000 | G14: =$A14 -> 150000000 | H14: =$A14 -> 150000000 | I14: =$A14 -> 150000000 | J14: =$A14 -> 150000000 | ... N14: =$A14 -> 150000000
B15: 0 | C15: =MAX((C$5-C14)*C13,0)-C10 -> 0 | D15: =MAX((D$5-D14)*D13,0)-D10 -> 0 | E15: =MAX((E$5-E14)*E13,0)-E10 -> 3500000 | F15: =MAX((F$5-F14)*F13,0)-F10 -> -682606.09 | G15: =MAX((G$5-G14)*G13,0)-G10 -> -130543 | H15: =MAX((H$5-H14)*H13,0)-H10 -> 934999.71 | I15: =MAX((I$5-I14)*I13,0)-I10 -> 3113852.3 | J15: =MAX((J$5-J14)*J13,0)-J10 -> 4234539.8 | ... N15: =MAX((N$5-N14)*N13,0)-N10 -> 59500000

Sheet lgh_cuda
A1: CUDA (liability)
A2: Year | B2: 45657 | C2: =+lgh_bs!E2 -> 45747 | D2: =+lgh_bs!F2 -> 45838 | E2: =+lgh_bs!G2 -> 45930 | F2: =+lgh_bs!H2 -> 46022 | G2: =+lgh_bs!I2 -> 46112 | H2: =+lgh_bs!J2 -> 46203 | I2: =+lgh_bs!K2 -> 46295 | J2: =+lgh_bs!L2 -> 46387 | ... N2: =+lgh_bs!P2 -> 47848
A3: Period | B3: Q4 | C3: =+lgh_bs!E3 -> Q1 | D3: =+lgh_bs!F3 -> Q2 | E3: =+lgh_bs!G3 -> Q3 | F3: =+lgh_bs!H3 -> Q4 | G3: =+lgh_bs!I3 -> Q1 | H3: =+lgh_bs!J3 -> Q2 | I3: =+lgh_bs!K3 -> Q3 | J3: =+lgh_bs!L3 -> Q4 | ... N3: =+lgh_bs!P3 -> Q4
A4: Common Unit Distribution Amount (partner participation)
A5: Increase per LLC agreement | B5: 3000000 | C5: =3000000/4 -> 750000
A6: Distribution (cuda for pref) | B6: 6000000 | C6: =-6050000 -> -6050000
A7: Distribution (cash payout to Managing Member) | D7: -1200000
A8: cuda writeoff for discount | D8: -350000
A9: Distribution (kind within other against art) | C9: =-2150000 -> -2150000
A10: total | B10: 9000000 | C10: =SUM(C5:C9) -> -7450000 | D10: =SUM(D5:D9) -> -1550000 | E10: =SUM(E5:E9) -> 0 | F10: =SUM(F5:F9) -> 0 | G10: =SUM(G5:G9) -> 0 | H10: =SUM(H5:H9) -> 0 | I10: =SUM(I5:I9) -> 0 | J10: =SUM(J5:J9) -> 0 | ... N10: =SUM(N5:N9) -> 0
A11: Balance | B11: 9000000 | C11: =+B11+C10 -> 1550000 | D11: =+C11+D10 -> 0 | E11: =+D11+E10 -> 0 | F11: =+E11+F10 -> 0 | G11: =+F11+G10 -> 0 | H11: =+G11+H10 -> 0 | I11: =+H11+I10 -> 0 | J11: =+I11+J10 -> 0 | ... N11: =+M11+N10 -> 0
A13: Cashflows sources and uses
A15: Sources (cash)
A16: Total LGH Other Liabs in(source) after (assets and cuda) | B16: 6000000
A18: Uses (cash)
A19: Total LGH Other Liabs Cashflow out (flow) (assets and cuda) | B19: 0 | C19: =SUM(C6:C7) -> -6050000 | D19: =SUM(D6:D7) -> -1200000 | E19: =SUM(E6:E7) -> 0 | F19: =SUM(F6:F7) -> 0 | G19: =SUM(G6:G7) -> 0 | H19: =SUM(H6:H7) -> 0 | I19: =SUM(I6:I7) -> 0 | J19: =SUM(J6:J7) -> 0 | ... N19: =SUM(N6:N7) -> 0

Sheet lgh_equity
A1: LGH Equity
A2: Year | B2: 45657 | C2: =+lgh_bs!E2 -> 45747 | D2: =+lgh_bs!F2 -> 45838 | E2: =+lgh_bs!G2 -> 45930 | F2: =+lgh_bs!H2 -> 46022 | G2: =+lgh_bs!I2 -> 46112 | H2: =+lgh_bs!J2 -> 46203 | I2: =+lgh_bs!K2 -> 46295 | J2: =+lgh_bs!L2 -> 46387 | ... N2: =+lgh_bs!P2 -> 47848
A3: Period | B3: Q4 | C3: =+lgh_bs!E3 -> Q1 | D3: =+lgh_bs!F3 -> Q2 | E3: =+lgh_bs!G3 -> Q3 | F3: =+lgh_bs!H3 -> Q4 | G3: =+lgh_bs!I3 -> Q1 | H3: =+lgh_bs!J3 -> Q2 | I3: =+lgh_bs!K3 -> Q3 | J3: =+lgh_bs!L3 -> Q4 | ... N3: =+lgh_bs!P3 -> Q4
A5: EQUITY OWNERSHIP (and percent)
A6: Phil Potter
A7: Cambrian | B7: 0 | D7: 23600000 | E7: 0 | F7: =3000000*0 -> 0 | G7: 0 | H7: 0 | I7: 0 | J7: 0 | K7: 0 | L7: 0 | M7: 0 | N7: 0
A8: Arik
A9: Scott | E9: 200000
A10: Balance | B10: 0 | C10: =SUM(C6:C9) -> 0 | D10: =SUM(D6:D9) -> 23600000 | E10: =SUM(E6:E9) -> 200000 | F10: =SUM(F6:F9) -> 0 | G10: =SUM(G6:G9) -> 0 | H10: =SUM(H6:H9) -> 0 | I10: =SUM(I6:I9) -> 0 | J10: =SUM(J6:J9) -> 0 | ... N10: =SUM(N6:N9) -> 0
A12: Sources/In
B13: 0 | C13: =+C10 -> 0 | D13: =+D10 -> 23600000 | E13: =+E10 -> 200000 | F13: =+F10 -> 0 | G13: =+G10 -> 0 | H13: =+H10 -> 0 | I13: =+I10 -> 0 | J13: =+J10 -> 0 | ... N13: =+N10 -> 0
A14: Total sources in | B14: 0 | C14: =SUM(C13) -> 0 | D14: =SUM(D13) -> 23600000 | E14: =SUM(E13) -> 200000 | F14: =SUM(F13) -> 0 | G14: =SUM(G13) -> 0 | H14: =SUM(H13) -> 0 | I14: =SUM(I13) -> 0 | J14: =SUM(J13) -> 0 | ... N14: =SUM(N13) -> 0
A16: Uses/Out
B17: 0 | C17: 0 | D17: -23600000 | E17: 0 | F17: 0 | G17: 0 | H17: 0 | I17: 0 | J17: 0 | K17: 0 | L17: 0 | M17: 0 | N17: 0
A18: Total Uses/Out | B18: 0 | C18: =SUM(C17) -> 0 | D18: =SUM(D17) -> -23600000 | E18: =SUM(E17) -> 0 | F18: =SUM(F17) -> 0 | G18: =SUM(G17) -> 0 | H18: =SUM(H17) -> 0 | I18: =SUM(I17) -> 0 | J18: =SUM(J17) -> 0 | ... N18: =SUM(N17) -> 0
A20: LGH Cash Flow Total | B20: 0 | C20: =+C10+C18 -> 0 | D20: =+D10+D18 -> 0 | E20: =+E10+E18 -> 200000 | F20: =+F10+F18 -> 0 | G20: =+G10+G18 -> 0 | H20: =+H10+H18 -> 0 | I20: =+I10+I18 -> 0 | J20: =+J10+J18 -> 0 | ... N20: =+N10+N18 -> 0
A22: EQUITY PERCENTAGE
A23: Dilution Calculation
A24: new equity raised | B24: 0 | C24: =SUM(C32:C37)-C36 -> 0 | D24: =SUM(D32:D37)-D36 -> 0.236 | E24: =SUM(E32:E37)-E36 -> 0.0032 | F24: =SUM(F32:F37)-F36 -> 0 | G24: =SUM(G32:G37)-G36 -> 0 | H24: =SUM(H32:H37)-H36 -> 0 | I24: =SUM(I32:I37)-I36 -> 0 | J24: =SUM(J32:J37)-J36 -> 0 | ... N24: =SUM(N32:N37)-N36 -> 0
A25: Issued Share % | B25: 0.0099009901 | C25: =(B25+C24)/(1+C24) -> 0.0099009901 | D25: =(C25+D24)/(1+D24) -> 0.19894902 | E25: =(D25+E24)/(1+E24) -> 0.20150421 | F25: =(E25+F24)/(1+F24) -> 0.20150421 | G25: =(F25+G24)/(1+G24) -> 0.20150421 | H25: =(G25+H24)/(1+H24) -> 0.20150421 | I25: =(H25+I24)/(1+I24) -> 0.20150421 | J25: =(I25+J24)/(1+J24) -> 0.20150421 | ... N25: =(M25+N24)/(1+N24) -> 0.20150421
A26: Unissued Share % | B26: 0.98544554 | C26: =B26/(1+C24) -> 0.98544554 | D26: =C26/(1+D24) -> 0.79728604 | E26: =D26/(1+E24) -> 0.79474286 | F26: =E26/(1+F24) -> 0.79474286 | G26: =F26/(1+G24) -> 0.79474286 | H26: =G26/(1+H24) -> 0.79474286 | I26: =H26/(1+I24) -> 0.79474286 | J26: =I26/(1+J24) -> 0.79474286 | ... N26: =M26/(1+N24) -> 0.79474286
A27: pref raised | B27: 0.2706625 | C27: =+C50 -> 0.007685 | D27: =+D50 -> 0 | E27: =+E50 -> 0 | F27: =+F50 -> 0 | G27: =+G50 -> 0.00265 | H27: =+H50 -> 0 | I27: =+I50 -> 0 | J27: =+J50 -> 0 | ... N27: =+N50 -> 0
A28: Pref Share % | B28: 0.36316834 | C28: =B28/(1+C24)+C27 -> 0.37085334 | D28: =C28/(1+D24)+D27 -> 0.30004316 | E28: =D28/(1+E24)+E27 -> 0.29908608 | F28: =E28/(1+F24)+F27 -> 0.29908608 | G28: =F28/(1+G24)+G27 -> 0.30173608 | H28: =G28/(1+H24)+H27 -> 0.30173608 | I28: =H28/(1+I24)+I27 -> 0.30173608 | J28: =I28/(1+J24)+J27 -> 0.30173608 | ... N28: =M28/(1+N24)+N27 -> 0.30173608
A29: Unissued Share % | B29: 0.6222772 | C29: =C26-C28 -> 0.6145922 | D29: =D26-D28 -> 0.49724288 | E29: =E26-E28 -> 0.49565678 | F29: =F26-F28 -> 0.49565678 | G29: =G26-G28 -> 0.49300678 | H29: =H26-H28 -> 0.49300678 | I29: =I26-I28 -> 0.49300678 | J29: =J26-J28 -> 0.49300678 | ... N29: =N26-N28 -> 0.49300678
A31: New Equity Issued
A32: Sk
A33: Huston
A34: potter
A35: Cambrian | D35: 0.236
A36: PFNGT LLC Pref Transfer | D36: 0.25
A37: Scott Bruner | E37: 0.0032
A38: Total | B38: 0 | C38: =SUM(C32:C37) -> 0 | D38: =SUM(D32:D37) -> 0.486 | E38: =SUM(E32:E37) -> 0.0032 | F38: =SUM(F32:F37) -> 0 | G38: =SUM(G32:G37) -> 0 | H38: =SUM(H32:H37) -> 0 | I38: =SUM(I32:I37) -> 0 | J38: =SUM(J32:J37) -> 0 | ... N38: =SUM(N32:N37) -> 0
A39: Common Equity Position
A40: =A32 -> Sk | B40: 0.6222772 | C40: =+C29 -> 0.6145922 | D40: =+D29 -> 0.49724288 | E40: =+E29 -> 0.49565678 | F40: =+F29 -> 0.49565678 | G40: =+G29 -> 0.49300678 | H40: =+H29 -> 0.49300678 | I40: =+I29 -> 0.49300678 | J40: =+J29 -> 0.49300678 | ... N40: =+N29 -> 0.49300678
A41: =A33 -> Huston | B41: 0.0046534653 | C41: {=IF(B41>0,B41/(1+C$24),(SUMPRODUCT(($A41=$A$33:$A$37)*C$33:C$37))/(1+C$24))} -> 0.0046534653 | D41: {=IF(C41>0,C41/(1+D$24),(SUMPRODUCT(($A41=$A$33:$A$37)*D$33:D$37))/(1+D$24))} -> 0.0037649396 | E41: {=IF(D41>0,D41/(1+E$24),(SUMPRODUCT(($A41=$A$33:$A$37)*E$33:E$37))/(1+E$24))} -> 0.0037529302 | F41: {=IF(E41>0,E41/(1+F$24),(SUMPRODUCT(($A41=$A$33:$A$37)*F$33:F$37))/(1+F$24))} -> 0.0037529302 | G41: {=IF(F41>0,F41/(1+G$24),(SUMPRODUCT(($A41=$A$33:$A$37)*G$33:G$37))/(1+G$24))} -> 0.0037529302 | H41: {=IF(G41>0,G41/(1+H$24),(SUMPRODUCT(($A41=$A$33:$A$37)*H$33:H$37))/(1+H$24))} -> 0.0037529302 | I41: {=IF(H41>0,H41/(1+I$24),(SUMPRODUCT(($A41=$A$33:$A$37)*I$33:I$37))/(1+I$24))} -> 0.0037529302 | J41: {=IF(I41>0,I41/(1+J$24),(SUMPRODUCT(($A41=$A$33:$A$37)*J$33:J$37))/(1+J$24))} -> 0.0037529302 | ... N41: {=IF(M41>0,M41/(1+N$24),(SUMPRODUCT(($A41=$A$33:$A$37)*N$33:N$37))/(1+N$24))} -> 0.0037529302
